<?xml version="1.0" encoding="UTF-8"?>
<!DOCTYPE html PUBLIC "-//W3C//DTD XHTML 1.0 Strict//EN" "http://www.w3.org/TR/xhtml1/DTD/xhtml1-strict.dtd">
<html xmlns="http://www.w3.org/1999/xhtml">
<head>
    <title>kuaidiinteface</title>
    <meta name="generator" content="HTMLTestRunner 0.8.2"/>
    <meta http-equiv="Content-Type" content="text/html; charset=UTF-8"/>
    
<style type="text/css" media="screen">
body        { font-family: verdana, arial, helvetica, sans-serif; font-size: 80%; }
table       { font-size: 100%; }
pre         { }

/* -- heading ---------------------------------------------------------------------- */
h1 {
	font-size: 16pt;
	color: gray;
}
.heading {
    margin-top: 0ex;
    margin-bottom: 1ex;
}

.heading .attribute {
    margin-top: 1ex;
    margin-bottom: 0;
}

.heading .description {
    margin-top: 4ex;
    margin-bottom: 6ex;
}

/* -- css div popup ------------------------------------------------------------------------ */
a.popup_link {
}

a.popup_link:hover {
    color: red;
}

.popup_window {
    display: none;
    position: relative;
    left: 0px;
    top: 0px;
    /*border: solid #627173 1px; */
    padding: 10px;
    background-color: #E6E6D6;
    font-family: "Lucida Console", "Courier New", Courier, monospace;
    text-align: left;
    font-size: 8pt;
    width: 500px;
}

}
/* -- report ------------------------------------------------------------------------ */
#show_detail_line {
    margin-top: 3ex;
    margin-bottom: 1ex;
}
#result_table {
    width: 80%;
    border-collapse: collapse;
    border: 1px solid #777;
}
#header_row {
    font-weight: bold;
    color: white;
    background-color: #777;
}
#result_table td {
    border: 1px solid #777;
    padding: 2px;
}
#total_row  { font-weight: bold; }
.passClass  { background-color: #6c6; }
.failClass  { background-color: #c60; }
.errorClass { background-color: #c00; }
.passCase   { color: #6c6; }
.failCase   { color: #c60; font-weight: bold; }
.errorCase  { color: #c00; font-weight: bold; }
.hiddenRow  { display: none; }
.testcase   { margin-left: 2em; }


/* -- ending ---------------------------------------------------------------------- */
#ending {
}

</style>

</head>
<body>
<script language="javascript" type="text/javascript"><!--
output_list = Array();

/* level - 0:Summary; 1:Failed; 2:All */
function showCase(level) {
    trs = document.getElementsByTagName("tr");
    for (var i = 0; i < trs.length; i++) {
        tr = trs[i];
        id = tr.id;
        if (id.substr(0,2) == 'ft') {
            if (level < 1) {
                tr.className = 'hiddenRow';
            }
            else {
                tr.className = '';
            }
        }
        if (id.substr(0,2) == 'pt') {
            if (level > 1) {
                tr.className = '';
            }
            else {
                tr.className = 'hiddenRow';
            }
        }
    }
}


function showClassDetail(cid, count) {
    var id_list = Array(count);
    var toHide = 1;
    for (var i = 0; i < count; i++) {
        tid0 = 't' + cid.substr(1) + '.' + (i+1);
        tid = 'f' + tid0;
        tr = document.getElementById(tid);
        if (!tr) {
            tid = 'p' + tid0;
            tr = document.getElementById(tid);
        }
        id_list[i] = tid;
        if (tr.className) {
            toHide = 0;
        }
    }
    for (var i = 0; i < count; i++) {
        tid = id_list[i];
        if (toHide) {
            document.getElementById('div_'+tid).style.display = 'none'
            document.getElementById(tid).className = 'hiddenRow';
        }
        else {
            document.getElementById(tid).className = '';
        }
    }
}


function showTestDetail(div_id){
    var details_div = document.getElementById(div_id)
    var displayState = details_div.style.display
    // alert(displayState)
    if (displayState != 'block' ) {
        displayState = 'block'
        details_div.style.display = 'block'
    }
    else {
        details_div.style.display = 'none'
    }
}


function html_escape(s) {
    s = s.replace(/&/g,'&amp;');
    s = s.replace(/</g,'&lt;');
    s = s.replace(/>/g,'&gt;');
    return s;
}

/* obsoleted by detail in <div>
function showOutput(id, name) {
    var w = window.open("", //url
                    name,
                    "resizable,scrollbars,status,width=800,height=450");
    d = w.document;
    d.write("<pre>");
    d.write(html_escape(output_list[id]));
    d.write("\n");
    d.write("<a href='javascript:window.close()'>close</a>\n");
    d.write("</pre>\n");
    d.close();
}
*/
--></script>

<div class='heading'>
<h1>kuaidiinteface</h1>
<p class='attribute'><strong>Start Time:</strong> 2019-06-14 16:49:23</p>
<p class='attribute'><strong>Duration:</strong> 0:00:09.925514</p>
<p class='attribute'><strong>Status:</strong> Pass 3 Failure 2 Error 18</p>

<p class='description'>kuaidkuaidi</p>
</div>



<p id='show_detail_line'>Show
<a href='javascript:showCase(0)'>Summary</a>
<a href='javascript:showCase(1)'>Failed</a>
<a href='javascript:showCase(2)'>All</a>
</p>
<table id='result_table'>
<colgroup>
<col align='left' />
<col align='right' />
<col align='right' />
<col align='right' />
<col align='right' />
<col align='right' />
</colgroup>
<tr id='header_row'>
    <td>Test Group/Test case</td>
    <td>Count</td>
    <td>Pass</td>
    <td>Fail</td>
    <td>Error</td>
    <td>View</td>
</tr>

<tr class='errorClass'>
    <td>get_event_list_test.GetEventListTest:  获得发布会列表 </td>
    <td>8</td>
    <td>0</td>
    <td>0</td>
    <td>8</td>
    <td><a href="javascript:showClassDetail('c1',8)">Detail</a></td>
</tr>

<tr id='ft1.1' class='none'>
    <td class='errorCase'><div class='testcase'>test_get_event_list_eid_error: eid=901 查询结果为空</div></td>
    <td colspan='5' align='center'>

    <!--css div popup start-->
    <a class="popup_link" onfocus='this.blur();' href="javascript:showTestDetail('div_ft1.1')" >
        error</a>

    <div id='div_ft1.1' class="popup_window">
        <div style='text-align: right; color:red;cursor:pointer'>
        <a onfocus='this.blur();' onclick="document.getElementById('div_ft1.1').style.display = 'none' " >
           [x]</a>
        </div>
        <pre>
        
ft1.1: Traceback (most recent call last):
  File "C:\Users\JHMK-ZSS\PycharmProjects\pyrequests\venv\lib\site-packages\urllib3\connection.py", line 160, in _new_conn
    (self._dns_host, self.port), self.timeout, **extra_kw)
  File "C:\Users\JHMK-ZSS\PycharmProjects\pyrequests\venv\lib\site-packages\urllib3\util\connection.py", line 80, in create_connection
    raise err
  File "C:\Users\JHMK-ZSS\PycharmProjects\pyrequests\venv\lib\site-packages\urllib3\util\connection.py", line 70, in create_connection
    sock.connect(sa)
ConnectionRefusedError: [WinError 10061] 由于目标计算机积极拒绝，无法连接。

During handling of the above exception, another exception occurred:

Traceback (most recent call last):
  File "C:\Users\JHMK-ZSS\PycharmProjects\pyrequests\venv\lib\site-packages\urllib3\connectionpool.py", line 603, in urlopen
    chunked=chunked)
  File "C:\Users\JHMK-ZSS\PycharmProjects\pyrequests\venv\lib\site-packages\urllib3\connectionpool.py", line 355, in _make_request
    conn.request(method, url, **httplib_request_kw)
  File "C:\Users\JHMK-ZSS\AppData\Local\Programs\Python\Python37\lib\http\client.py", line 1229, in request
    self._send_request(method, url, body, headers, encode_chunked)
  File "C:\Users\JHMK-ZSS\AppData\Local\Programs\Python\Python37\lib\http\client.py", line 1275, in _send_request
    self.endheaders(body, encode_chunked=encode_chunked)
  File "C:\Users\JHMK-ZSS\AppData\Local\Programs\Python\Python37\lib\http\client.py", line 1224, in endheaders
    self._send_output(message_body, encode_chunked=encode_chunked)
  File "C:\Users\JHMK-ZSS\AppData\Local\Programs\Python\Python37\lib\http\client.py", line 1016, in _send_output
    self.send(msg)
  File "C:\Users\JHMK-ZSS\AppData\Local\Programs\Python\Python37\lib\http\client.py", line 956, in send
    self.connect()
  File "C:\Users\JHMK-ZSS\PycharmProjects\pyrequests\venv\lib\site-packages\urllib3\connection.py", line 183, in connect
    conn = self._new_conn()
  File "C:\Users\JHMK-ZSS\PycharmProjects\pyrequests\venv\lib\site-packages\urllib3\connection.py", line 169, in _new_conn
    self, "Failed to establish a new connection: %s" % e)
urllib3.exceptions.NewConnectionError: &lt;urllib3.connection.HTTPConnection object at 0x000001EA7DFFF588&gt;: Failed to establish a new connection: [WinError 10061] 由于目标计算机积极拒绝，无法连接。

During handling of the above exception, another exception occurred:

Traceback (most recent call last):
  File "C:\Users\JHMK-ZSS\PycharmProjects\pyrequests\venv\lib\site-packages\requests\adapters.py", line 449, in send
    timeout=timeout
  File "C:\Users\JHMK-ZSS\PycharmProjects\pyrequests\venv\lib\site-packages\urllib3\connectionpool.py", line 641, in urlopen
    _stacktrace=sys.exc_info()[2])
  File "C:\Users\JHMK-ZSS\PycharmProjects\pyrequests\venv\lib\site-packages\urllib3\util\retry.py", line 399, in increment
    raise MaxRetryError(_pool, url, error or ResponseError(cause))
urllib3.exceptions.MaxRetryError: HTTPConnectionPool(host='127.0.0.1', port=8000): Max retries exceeded with url: /api/get_event_list/?eid=901 (Caused by NewConnectionError('&lt;urllib3.connection.HTTPConnection object at 0x000001EA7DFFF588&gt;: Failed to establish a new connection: [WinError 10061] 由于目标计算机积极拒绝，无法连接。'))

During handling of the above exception, another exception occurred:

Traceback (most recent call last):
  File "C:\Users\JHMK-ZSS\PycharmProjects\pyrequests\interface\get_event_list_test.py", line 21, in test_get_event_list_eid_error
    r = requests.get(self.base_url, params={'eid':901})
  File "C:\Users\JHMK-ZSS\PycharmProjects\pyrequests\venv\lib\site-packages\requests\api.py", line 75, in get
    return request('get', url, params=params, **kwargs)
  File "C:\Users\JHMK-ZSS\PycharmProjects\pyrequests\venv\lib\site-packages\requests\api.py", line 60, in request
    return session.request(method=method, url=url, **kwargs)
  File "C:\Users\JHMK-ZSS\PycharmProjects\pyrequests\venv\lib\site-packages\requests\sessions.py", line 533, in request
    resp = self.send(prep, **send_kwargs)
  File "C:\Users\JHMK-ZSS\PycharmProjects\pyrequests\venv\lib\site-packages\requests\sessions.py", line 646, in send
    r = adapter.send(request, **kwargs)
  File "C:\Users\JHMK-ZSS\PycharmProjects\pyrequests\venv\lib\site-packages\requests\adapters.py", line 516, in send
    raise ConnectionError(e, request=request)
requests.exceptions.ConnectionError: HTTPConnectionPool(host='127.0.0.1', port=8000): Max retries exceeded with url: /api/get_event_list/?eid=901 (Caused by NewConnectionError('&lt;urllib3.connection.HTTPConnection object at 0x000001EA7DFFF588&gt;: Failed to establish a new connection: [WinError 10061] 由于目标计算机积极拒绝，无法连接。'))


        </pre>
    </div>
    <!--css div popup end-->

    </td>
</tr>

<tr id='ft1.2' class='none'>
    <td class='errorCase'><div class='testcase'>test_get_event_list_eid_error: eid=901 查询结果为空</div></td>
    <td colspan='5' align='center'>

    <!--css div popup start-->
    <a class="popup_link" onfocus='this.blur();' href="javascript:showTestDetail('div_ft1.2')" >
        error</a>

    <div id='div_ft1.2' class="popup_window">
        <div style='text-align: right; color:red;cursor:pointer'>
        <a onfocus='this.blur();' onclick="document.getElementById('div_ft1.2').style.display = 'none' " >
           [x]</a>
        </div>
        <pre>
        
ft1.2: Traceback (most recent call last):
  File "C:\Users\JHMK-ZSS\PycharmProjects\pyrequests\interface\get_event_list_test.py", line 17, in tearDown
    print(self.result)
AttributeError: 'GetEventListTest' object has no attribute 'result'


        </pre>
    </div>
    <!--css div popup end-->

    </td>
</tr>

<tr id='ft1.3' class='none'>
    <td class='errorCase'><div class='testcase'>test_get_event_list_eid_success: 根据 eid 查询结果成功</div></td>
    <td colspan='5' align='center'>

    <!--css div popup start-->
    <a class="popup_link" onfocus='this.blur();' href="javascript:showTestDetail('div_ft1.3')" >
        error</a>

    <div id='div_ft1.3' class="popup_window">
        <div style='text-align: right; color:red;cursor:pointer'>
        <a onfocus='this.blur();' onclick="document.getElementById('div_ft1.3').style.display = 'none' " >
           [x]</a>
        </div>
        <pre>
        
ft1.3: Traceback (most recent call last):
  File "C:\Users\JHMK-ZSS\PycharmProjects\pyrequests\venv\lib\site-packages\urllib3\connection.py", line 160, in _new_conn
    (self._dns_host, self.port), self.timeout, **extra_kw)
  File "C:\Users\JHMK-ZSS\PycharmProjects\pyrequests\venv\lib\site-packages\urllib3\util\connection.py", line 80, in create_connection
    raise err
  File "C:\Users\JHMK-ZSS\PycharmProjects\pyrequests\venv\lib\site-packages\urllib3\util\connection.py", line 70, in create_connection
    sock.connect(sa)
ConnectionRefusedError: [WinError 10061] 由于目标计算机积极拒绝，无法连接。

During handling of the above exception, another exception occurred:

Traceback (most recent call last):
  File "C:\Users\JHMK-ZSS\PycharmProjects\pyrequests\venv\lib\site-packages\urllib3\connectionpool.py", line 603, in urlopen
    chunked=chunked)
  File "C:\Users\JHMK-ZSS\PycharmProjects\pyrequests\venv\lib\site-packages\urllib3\connectionpool.py", line 355, in _make_request
    conn.request(method, url, **httplib_request_kw)
  File "C:\Users\JHMK-ZSS\AppData\Local\Programs\Python\Python37\lib\http\client.py", line 1229, in request
    self._send_request(method, url, body, headers, encode_chunked)
  File "C:\Users\JHMK-ZSS\AppData\Local\Programs\Python\Python37\lib\http\client.py", line 1275, in _send_request
    self.endheaders(body, encode_chunked=encode_chunked)
  File "C:\Users\JHMK-ZSS\AppData\Local\Programs\Python\Python37\lib\http\client.py", line 1224, in endheaders
    self._send_output(message_body, encode_chunked=encode_chunked)
  File "C:\Users\JHMK-ZSS\AppData\Local\Programs\Python\Python37\lib\http\client.py", line 1016, in _send_output
    self.send(msg)
  File "C:\Users\JHMK-ZSS\AppData\Local\Programs\Python\Python37\lib\http\client.py", line 956, in send
    self.connect()
  File "C:\Users\JHMK-ZSS\PycharmProjects\pyrequests\venv\lib\site-packages\urllib3\connection.py", line 183, in connect
    conn = self._new_conn()
  File "C:\Users\JHMK-ZSS\PycharmProjects\pyrequests\venv\lib\site-packages\urllib3\connection.py", line 169, in _new_conn
    self, "Failed to establish a new connection: %s" % e)
urllib3.exceptions.NewConnectionError: &lt;urllib3.connection.HTTPConnection object at 0x000001EA7E0A75C0&gt;: Failed to establish a new connection: [WinError 10061] 由于目标计算机积极拒绝，无法连接。

During handling of the above exception, another exception occurred:

Traceback (most recent call last):
  File "C:\Users\JHMK-ZSS\PycharmProjects\pyrequests\venv\lib\site-packages\requests\adapters.py", line 449, in send
    timeout=timeout
  File "C:\Users\JHMK-ZSS\PycharmProjects\pyrequests\venv\lib\site-packages\urllib3\connectionpool.py", line 641, in urlopen
    _stacktrace=sys.exc_info()[2])
  File "C:\Users\JHMK-ZSS\PycharmProjects\pyrequests\venv\lib\site-packages\urllib3\util\retry.py", line 399, in increment
    raise MaxRetryError(_pool, url, error or ResponseError(cause))
urllib3.exceptions.MaxRetryError: HTTPConnectionPool(host='127.0.0.1', port=8000): Max retries exceeded with url: /api/get_event_list/?eid=1 (Caused by NewConnectionError('&lt;urllib3.connection.HTTPConnection object at 0x000001EA7E0A75C0&gt;: Failed to establish a new connection: [WinError 10061] 由于目标计算机积极拒绝，无法连接。'))

During handling of the above exception, another exception occurred:

Traceback (most recent call last):
  File "C:\Users\JHMK-ZSS\PycharmProjects\pyrequests\interface\get_event_list_test.py", line 28, in test_get_event_list_eid_success
    r = requests.get(self.base_url, params={'eid':1})
  File "C:\Users\JHMK-ZSS\PycharmProjects\pyrequests\venv\lib\site-packages\requests\api.py", line 75, in get
    return request('get', url, params=params, **kwargs)
  File "C:\Users\JHMK-ZSS\PycharmProjects\pyrequests\venv\lib\site-packages\requests\api.py", line 60, in request
    return session.request(method=method, url=url, **kwargs)
  File "C:\Users\JHMK-ZSS\PycharmProjects\pyrequests\venv\lib\site-packages\requests\sessions.py", line 533, in request
    resp = self.send(prep, **send_kwargs)
  File "C:\Users\JHMK-ZSS\PycharmProjects\pyrequests\venv\lib\site-packages\requests\sessions.py", line 646, in send
    r = adapter.send(request, **kwargs)
  File "C:\Users\JHMK-ZSS\PycharmProjects\pyrequests\venv\lib\site-packages\requests\adapters.py", line 516, in send
    raise ConnectionError(e, request=request)
requests.exceptions.ConnectionError: HTTPConnectionPool(host='127.0.0.1', port=8000): Max retries exceeded with url: /api/get_event_list/?eid=1 (Caused by NewConnectionError('&lt;urllib3.connection.HTTPConnection object at 0x000001EA7E0A75C0&gt;: Failed to establish a new connection: [WinError 10061] 由于目标计算机积极拒绝，无法连接。'))


        </pre>
    </div>
    <!--css div popup end-->

    </td>
</tr>

<tr id='ft1.4' class='none'>
    <td class='errorCase'><div class='testcase'>test_get_event_list_eid_success: 根据 eid 查询结果成功</div></td>
    <td colspan='5' align='center'>

    <!--css div popup start-->
    <a class="popup_link" onfocus='this.blur();' href="javascript:showTestDetail('div_ft1.4')" >
        error</a>

    <div id='div_ft1.4' class="popup_window">
        <div style='text-align: right; color:red;cursor:pointer'>
        <a onfocus='this.blur();' onclick="document.getElementById('div_ft1.4').style.display = 'none' " >
           [x]</a>
        </div>
        <pre>
        
ft1.4: Traceback (most recent call last):
  File "C:\Users\JHMK-ZSS\PycharmProjects\pyrequests\interface\get_event_list_test.py", line 17, in tearDown
    print(self.result)
AttributeError: 'GetEventListTest' object has no attribute 'result'


        </pre>
    </div>
    <!--css div popup end-->

    </td>
</tr>

<tr id='ft1.5' class='none'>
    <td class='errorCase'><div class='testcase'>test_get_event_list_nam_result_null: 关键字‘abc’查询</div></td>
    <td colspan='5' align='center'>

    <!--css div popup start-->
    <a class="popup_link" onfocus='this.blur();' href="javascript:showTestDetail('div_ft1.5')" >
        error</a>

    <div id='div_ft1.5' class="popup_window">
        <div style='text-align: right; color:red;cursor:pointer'>
        <a onfocus='this.blur();' onclick="document.getElementById('div_ft1.5').style.display = 'none' " >
           [x]</a>
        </div>
        <pre>
        
ft1.5: Traceback (most recent call last):
  File "C:\Users\JHMK-ZSS\PycharmProjects\pyrequests\venv\lib\site-packages\urllib3\connection.py", line 160, in _new_conn
    (self._dns_host, self.port), self.timeout, **extra_kw)
  File "C:\Users\JHMK-ZSS\PycharmProjects\pyrequests\venv\lib\site-packages\urllib3\util\connection.py", line 80, in create_connection
    raise err
  File "C:\Users\JHMK-ZSS\PycharmProjects\pyrequests\venv\lib\site-packages\urllib3\util\connection.py", line 70, in create_connection
    sock.connect(sa)
ConnectionRefusedError: [WinError 10061] 由于目标计算机积极拒绝，无法连接。

During handling of the above exception, another exception occurred:

Traceback (most recent call last):
  File "C:\Users\JHMK-ZSS\PycharmProjects\pyrequests\venv\lib\site-packages\urllib3\connectionpool.py", line 603, in urlopen
    chunked=chunked)
  File "C:\Users\JHMK-ZSS\PycharmProjects\pyrequests\venv\lib\site-packages\urllib3\connectionpool.py", line 355, in _make_request
    conn.request(method, url, **httplib_request_kw)
  File "C:\Users\JHMK-ZSS\AppData\Local\Programs\Python\Python37\lib\http\client.py", line 1229, in request
    self._send_request(method, url, body, headers, encode_chunked)
  File "C:\Users\JHMK-ZSS\AppData\Local\Programs\Python\Python37\lib\http\client.py", line 1275, in _send_request
    self.endheaders(body, encode_chunked=encode_chunked)
  File "C:\Users\JHMK-ZSS\AppData\Local\Programs\Python\Python37\lib\http\client.py", line 1224, in endheaders
    self._send_output(message_body, encode_chunked=encode_chunked)
  File "C:\Users\JHMK-ZSS\AppData\Local\Programs\Python\Python37\lib\http\client.py", line 1016, in _send_output
    self.send(msg)
  File "C:\Users\JHMK-ZSS\AppData\Local\Programs\Python\Python37\lib\http\client.py", line 956, in send
    self.connect()
  File "C:\Users\JHMK-ZSS\PycharmProjects\pyrequests\venv\lib\site-packages\urllib3\connection.py", line 183, in connect
    conn = self._new_conn()
  File "C:\Users\JHMK-ZSS\PycharmProjects\pyrequests\venv\lib\site-packages\urllib3\connection.py", line 169, in _new_conn
    self, "Failed to establish a new connection: %s" % e)
urllib3.exceptions.NewConnectionError: &lt;urllib3.connection.HTTPConnection object at 0x000001EA7E0A7BA8&gt;: Failed to establish a new connection: [WinError 10061] 由于目标计算机积极拒绝，无法连接。

During handling of the above exception, another exception occurred:

Traceback (most recent call last):
  File "C:\Users\JHMK-ZSS\PycharmProjects\pyrequests\venv\lib\site-packages\requests\adapters.py", line 449, in send
    timeout=timeout
  File "C:\Users\JHMK-ZSS\PycharmProjects\pyrequests\venv\lib\site-packages\urllib3\connectionpool.py", line 641, in urlopen
    _stacktrace=sys.exc_info()[2])
  File "C:\Users\JHMK-ZSS\PycharmProjects\pyrequests\venv\lib\site-packages\urllib3\util\retry.py", line 399, in increment
    raise MaxRetryError(_pool, url, error or ResponseError(cause))
urllib3.exceptions.MaxRetryError: HTTPConnectionPool(host='127.0.0.1', port=8000): Max retries exceeded with url: /api/get_event_list/?name=abc (Caused by NewConnectionError('&lt;urllib3.connection.HTTPConnection object at 0x000001EA7E0A7BA8&gt;: Failed to establish a new connection: [WinError 10061] 由于目标计算机积极拒绝，无法连接。'))

During handling of the above exception, another exception occurred:

Traceback (most recent call last):
  File "C:\Users\JHMK-ZSS\PycharmProjects\pyrequests\interface\get_event_list_test.py", line 37, in test_get_event_list_nam_result_null
    r = requests.get(self.base_url, params={'name':'abc'})
  File "C:\Users\JHMK-ZSS\PycharmProjects\pyrequests\venv\lib\site-packages\requests\api.py", line 75, in get
    return request('get', url, params=params, **kwargs)
  File "C:\Users\JHMK-ZSS\PycharmProjects\pyrequests\venv\lib\site-packages\requests\api.py", line 60, in request
    return session.request(method=method, url=url, **kwargs)
  File "C:\Users\JHMK-ZSS\PycharmProjects\pyrequests\venv\lib\site-packages\requests\sessions.py", line 533, in request
    resp = self.send(prep, **send_kwargs)
  File "C:\Users\JHMK-ZSS\PycharmProjects\pyrequests\venv\lib\site-packages\requests\sessions.py", line 646, in send
    r = adapter.send(request, **kwargs)
  File "C:\Users\JHMK-ZSS\PycharmProjects\pyrequests\venv\lib\site-packages\requests\adapters.py", line 516, in send
    raise ConnectionError(e, request=request)
requests.exceptions.ConnectionError: HTTPConnectionPool(host='127.0.0.1', port=8000): Max retries exceeded with url: /api/get_event_list/?name=abc (Caused by NewConnectionError('&lt;urllib3.connection.HTTPConnection object at 0x000001EA7E0A7BA8&gt;: Failed to establish a new connection: [WinError 10061] 由于目标计算机积极拒绝，无法连接。'))


        </pre>
    </div>
    <!--css div popup end-->

    </td>
</tr>

<tr id='ft1.6' class='none'>
    <td class='errorCase'><div class='testcase'>test_get_event_list_nam_result_null: 关键字‘abc’查询</div></td>
    <td colspan='5' align='center'>

    <!--css div popup start-->
    <a class="popup_link" onfocus='this.blur();' href="javascript:showTestDetail('div_ft1.6')" >
        error</a>

    <div id='div_ft1.6' class="popup_window">
        <div style='text-align: right; color:red;cursor:pointer'>
        <a onfocus='this.blur();' onclick="document.getElementById('div_ft1.6').style.display = 'none' " >
           [x]</a>
        </div>
        <pre>
        
ft1.6: Traceback (most recent call last):
  File "C:\Users\JHMK-ZSS\PycharmProjects\pyrequests\interface\get_event_list_test.py", line 17, in tearDown
    print(self.result)
AttributeError: 'GetEventListTest' object has no attribute 'result'


        </pre>
    </div>
    <!--css div popup end-->

    </td>
</tr>

<tr id='ft1.7' class='none'>
    <td class='errorCase'><div class='testcase'>test_get_event_list_name_find: 关键字‘发布会’模糊查询</div></td>
    <td colspan='5' align='center'>

    <!--css div popup start-->
    <a class="popup_link" onfocus='this.blur();' href="javascript:showTestDetail('div_ft1.7')" >
        error</a>

    <div id='div_ft1.7' class="popup_window">
        <div style='text-align: right; color:red;cursor:pointer'>
        <a onfocus='this.blur();' onclick="document.getElementById('div_ft1.7').style.display = 'none' " >
           [x]</a>
        </div>
        <pre>
        
ft1.7: Traceback (most recent call last):
  File "C:\Users\JHMK-ZSS\PycharmProjects\pyrequests\venv\lib\site-packages\urllib3\connection.py", line 160, in _new_conn
    (self._dns_host, self.port), self.timeout, **extra_kw)
  File "C:\Users\JHMK-ZSS\PycharmProjects\pyrequests\venv\lib\site-packages\urllib3\util\connection.py", line 80, in create_connection
    raise err
  File "C:\Users\JHMK-ZSS\PycharmProjects\pyrequests\venv\lib\site-packages\urllib3\util\connection.py", line 70, in create_connection
    sock.connect(sa)
ConnectionRefusedError: [WinError 10061] 由于目标计算机积极拒绝，无法连接。

During handling of the above exception, another exception occurred:

Traceback (most recent call last):
  File "C:\Users\JHMK-ZSS\PycharmProjects\pyrequests\venv\lib\site-packages\urllib3\connectionpool.py", line 603, in urlopen
    chunked=chunked)
  File "C:\Users\JHMK-ZSS\PycharmProjects\pyrequests\venv\lib\site-packages\urllib3\connectionpool.py", line 355, in _make_request
    conn.request(method, url, **httplib_request_kw)
  File "C:\Users\JHMK-ZSS\AppData\Local\Programs\Python\Python37\lib\http\client.py", line 1229, in request
    self._send_request(method, url, body, headers, encode_chunked)
  File "C:\Users\JHMK-ZSS\AppData\Local\Programs\Python\Python37\lib\http\client.py", line 1275, in _send_request
    self.endheaders(body, encode_chunked=encode_chunked)
  File "C:\Users\JHMK-ZSS\AppData\Local\Programs\Python\Python37\lib\http\client.py", line 1224, in endheaders
    self._send_output(message_body, encode_chunked=encode_chunked)
  File "C:\Users\JHMK-ZSS\AppData\Local\Programs\Python\Python37\lib\http\client.py", line 1016, in _send_output
    self.send(msg)
  File "C:\Users\JHMK-ZSS\AppData\Local\Programs\Python\Python37\lib\http\client.py", line 956, in send
    self.connect()
  File "C:\Users\JHMK-ZSS\PycharmProjects\pyrequests\venv\lib\site-packages\urllib3\connection.py", line 183, in connect
    conn = self._new_conn()
  File "C:\Users\JHMK-ZSS\PycharmProjects\pyrequests\venv\lib\site-packages\urllib3\connection.py", line 169, in _new_conn
    self, "Failed to establish a new connection: %s" % e)
urllib3.exceptions.NewConnectionError: &lt;urllib3.connection.HTTPConnection object at 0x000001EA7E0B32B0&gt;: Failed to establish a new connection: [WinError 10061] 由于目标计算机积极拒绝，无法连接。

During handling of the above exception, another exception occurred:

Traceback (most recent call last):
  File "C:\Users\JHMK-ZSS\PycharmProjects\pyrequests\venv\lib\site-packages\requests\adapters.py", line 449, in send
    timeout=timeout
  File "C:\Users\JHMK-ZSS\PycharmProjects\pyrequests\venv\lib\site-packages\urllib3\connectionpool.py", line 641, in urlopen
    _stacktrace=sys.exc_info()[2])
  File "C:\Users\JHMK-ZSS\PycharmProjects\pyrequests\venv\lib\site-packages\urllib3\util\retry.py", line 399, in increment
    raise MaxRetryError(_pool, url, error or ResponseError(cause))
urllib3.exceptions.MaxRetryError: HTTPConnectionPool(host='127.0.0.1', port=8000): Max retries exceeded with url: /api/get_event_list/?name=xiao (Caused by NewConnectionError('&lt;urllib3.connection.HTTPConnection object at 0x000001EA7E0B32B0&gt;: Failed to establish a new connection: [WinError 10061] 由于目标计算机积极拒绝，无法连接。'))

During handling of the above exception, another exception occurred:

Traceback (most recent call last):
  File "C:\Users\JHMK-ZSS\PycharmProjects\pyrequests\interface\get_event_list_test.py", line 44, in test_get_event_list_name_find
    r = requests.get(self.base_url, params={'name':'xiao'})
  File "C:\Users\JHMK-ZSS\PycharmProjects\pyrequests\venv\lib\site-packages\requests\api.py", line 75, in get
    return request('get', url, params=params, **kwargs)
  File "C:\Users\JHMK-ZSS\PycharmProjects\pyrequests\venv\lib\site-packages\requests\api.py", line 60, in request
    return session.request(method=method, url=url, **kwargs)
  File "C:\Users\JHMK-ZSS\PycharmProjects\pyrequests\venv\lib\site-packages\requests\sessions.py", line 533, in request
    resp = self.send(prep, **send_kwargs)
  File "C:\Users\JHMK-ZSS\PycharmProjects\pyrequests\venv\lib\site-packages\requests\sessions.py", line 646, in send
    r = adapter.send(request, **kwargs)
  File "C:\Users\JHMK-ZSS\PycharmProjects\pyrequests\venv\lib\site-packages\requests\adapters.py", line 516, in send
    raise ConnectionError(e, request=request)
requests.exceptions.ConnectionError: HTTPConnectionPool(host='127.0.0.1', port=8000): Max retries exceeded with url: /api/get_event_list/?name=xiao (Caused by NewConnectionError('&lt;urllib3.connection.HTTPConnection object at 0x000001EA7E0B32B0&gt;: Failed to establish a new connection: [WinError 10061] 由于目标计算机积极拒绝，无法连接。'))


        </pre>
    </div>
    <!--css div popup end-->

    </td>
</tr>

<tr id='ft1.8' class='none'>
    <td class='errorCase'><div class='testcase'>test_get_event_list_name_find: 关键字‘发布会’模糊查询</div></td>
    <td colspan='5' align='center'>

    <!--css div popup start-->
    <a class="popup_link" onfocus='this.blur();' href="javascript:showTestDetail('div_ft1.8')" >
        error</a>

    <div id='div_ft1.8' class="popup_window">
        <div style='text-align: right; color:red;cursor:pointer'>
        <a onfocus='this.blur();' onclick="document.getElementById('div_ft1.8').style.display = 'none' " >
           [x]</a>
        </div>
        <pre>
        
ft1.8: Traceback (most recent call last):
  File "C:\Users\JHMK-ZSS\PycharmProjects\pyrequests\interface\get_event_list_test.py", line 17, in tearDown
    print(self.result)
AttributeError: 'GetEventListTest' object has no attribute 'result'


        </pre>
    </div>
    <!--css div popup end-->

    </td>
</tr>

<tr class='errorClass'>
    <td>get_guest_list_test.GetGuestListTest:  获得嘉宾列表 </td>
    <td>10</td>
    <td>0</td>
    <td>0</td>
    <td>10</td>
    <td><a href="javascript:showClassDetail('c2',10)">Detail</a></td>
</tr>

<tr id='ft2.1' class='none'>
    <td class='errorCase'><div class='testcase'>test_get_event_list_eid_error: 根据 eid 查询结果为空</div></td>
    <td colspan='5' align='center'>

    <!--css div popup start-->
    <a class="popup_link" onfocus='this.blur();' href="javascript:showTestDetail('div_ft2.1')" >
        error</a>

    <div id='div_ft2.1' class="popup_window">
        <div style='text-align: right; color:red;cursor:pointer'>
        <a onfocus='this.blur();' onclick="document.getElementById('div_ft2.1').style.display = 'none' " >
           [x]</a>
        </div>
        <pre>
        
ft2.1: Traceback (most recent call last):
  File "C:\Users\JHMK-ZSS\PycharmProjects\pyrequests\venv\lib\site-packages\urllib3\connection.py", line 160, in _new_conn
    (self._dns_host, self.port), self.timeout, **extra_kw)
  File "C:\Users\JHMK-ZSS\PycharmProjects\pyrequests\venv\lib\site-packages\urllib3\util\connection.py", line 80, in create_connection
    raise err
  File "C:\Users\JHMK-ZSS\PycharmProjects\pyrequests\venv\lib\site-packages\urllib3\util\connection.py", line 70, in create_connection
    sock.connect(sa)
ConnectionRefusedError: [WinError 10061] 由于目标计算机积极拒绝，无法连接。

During handling of the above exception, another exception occurred:

Traceback (most recent call last):
  File "C:\Users\JHMK-ZSS\PycharmProjects\pyrequests\venv\lib\site-packages\urllib3\connectionpool.py", line 603, in urlopen
    chunked=chunked)
  File "C:\Users\JHMK-ZSS\PycharmProjects\pyrequests\venv\lib\site-packages\urllib3\connectionpool.py", line 355, in _make_request
    conn.request(method, url, **httplib_request_kw)
  File "C:\Users\JHMK-ZSS\AppData\Local\Programs\Python\Python37\lib\http\client.py", line 1229, in request
    self._send_request(method, url, body, headers, encode_chunked)
  File "C:\Users\JHMK-ZSS\AppData\Local\Programs\Python\Python37\lib\http\client.py", line 1275, in _send_request
    self.endheaders(body, encode_chunked=encode_chunked)
  File "C:\Users\JHMK-ZSS\AppData\Local\Programs\Python\Python37\lib\http\client.py", line 1224, in endheaders
    self._send_output(message_body, encode_chunked=encode_chunked)
  File "C:\Users\JHMK-ZSS\AppData\Local\Programs\Python\Python37\lib\http\client.py", line 1016, in _send_output
    self.send(msg)
  File "C:\Users\JHMK-ZSS\AppData\Local\Programs\Python\Python37\lib\http\client.py", line 956, in send
    self.connect()
  File "C:\Users\JHMK-ZSS\PycharmProjects\pyrequests\venv\lib\site-packages\urllib3\connection.py", line 183, in connect
    conn = self._new_conn()
  File "C:\Users\JHMK-ZSS\PycharmProjects\pyrequests\venv\lib\site-packages\urllib3\connection.py", line 169, in _new_conn
    self, "Failed to establish a new connection: %s" % e)
urllib3.exceptions.NewConnectionError: &lt;urllib3.connection.HTTPConnection object at 0x000001EA7E0A7E10&gt;: Failed to establish a new connection: [WinError 10061] 由于目标计算机积极拒绝，无法连接。

During handling of the above exception, another exception occurred:

Traceback (most recent call last):
  File "C:\Users\JHMK-ZSS\PycharmProjects\pyrequests\venv\lib\site-packages\requests\adapters.py", line 449, in send
    timeout=timeout
  File "C:\Users\JHMK-ZSS\PycharmProjects\pyrequests\venv\lib\site-packages\urllib3\connectionpool.py", line 641, in urlopen
    _stacktrace=sys.exc_info()[2])
  File "C:\Users\JHMK-ZSS\PycharmProjects\pyrequests\venv\lib\site-packages\urllib3\util\retry.py", line 399, in increment
    raise MaxRetryError(_pool, url, error or ResponseError(cause))
urllib3.exceptions.MaxRetryError: HTTPConnectionPool(host='127.0.0.1', port=8000): Max retries exceeded with url: /api/get_guest_list/?eid=901 (Caused by NewConnectionError('&lt;urllib3.connection.HTTPConnection object at 0x000001EA7E0A7E10&gt;: Failed to establish a new connection: [WinError 10061] 由于目标计算机积极拒绝，无法连接。'))

During handling of the above exception, another exception occurred:

Traceback (most recent call last):
  File "C:\Users\JHMK-ZSS\PycharmProjects\pyrequests\interface\get_guest_list_test.py", line 27, in test_get_event_list_eid_error
    r = requests.get(self.base_url, params={'eid':901})
  File "C:\Users\JHMK-ZSS\PycharmProjects\pyrequests\venv\lib\site-packages\requests\api.py", line 75, in get
    return request('get', url, params=params, **kwargs)
  File "C:\Users\JHMK-ZSS\PycharmProjects\pyrequests\venv\lib\site-packages\requests\api.py", line 60, in request
    return session.request(method=method, url=url, **kwargs)
  File "C:\Users\JHMK-ZSS\PycharmProjects\pyrequests\venv\lib\site-packages\requests\sessions.py", line 533, in request
    resp = self.send(prep, **send_kwargs)
  File "C:\Users\JHMK-ZSS\PycharmProjects\pyrequests\venv\lib\site-packages\requests\sessions.py", line 646, in send
    r = adapter.send(request, **kwargs)
  File "C:\Users\JHMK-ZSS\PycharmProjects\pyrequests\venv\lib\site-packages\requests\adapters.py", line 516, in send
    raise ConnectionError(e, request=request)
requests.exceptions.ConnectionError: HTTPConnectionPool(host='127.0.0.1', port=8000): Max retries exceeded with url: /api/get_guest_list/?eid=901 (Caused by NewConnectionError('&lt;urllib3.connection.HTTPConnection object at 0x000001EA7E0A7E10&gt;: Failed to establish a new connection: [WinError 10061] 由于目标计算机积极拒绝，无法连接。'))


        </pre>
    </div>
    <!--css div popup end-->

    </td>
</tr>

<tr id='ft2.2' class='none'>
    <td class='errorCase'><div class='testcase'>test_get_event_list_eid_error: 根据 eid 查询结果为空</div></td>
    <td colspan='5' align='center'>

    <!--css div popup start-->
    <a class="popup_link" onfocus='this.blur();' href="javascript:showTestDetail('div_ft2.2')" >
        error</a>

    <div id='div_ft2.2' class="popup_window">
        <div style='text-align: right; color:red;cursor:pointer'>
        <a onfocus='this.blur();' onclick="document.getElementById('div_ft2.2').style.display = 'none' " >
           [x]</a>
        </div>
        <pre>
        
ft2.2: Traceback (most recent call last):
  File "C:\Users\JHMK-ZSS\PycharmProjects\pyrequests\interface\get_guest_list_test.py", line 16, in tearDown
    print(self.result)
AttributeError: 'GetGuestListTest' object has no attribute 'result'


        </pre>
    </div>
    <!--css div popup end-->

    </td>
</tr>

<tr id='ft2.3' class='none'>
    <td class='errorCase'><div class='testcase'>test_get_event_list_eid_phone_null: 根据 eid 和phone 查询结果为空</div></td>
    <td colspan='5' align='center'>

    <!--css div popup start-->
    <a class="popup_link" onfocus='this.blur();' href="javascript:showTestDetail('div_ft2.3')" >
        error</a>

    <div id='div_ft2.3' class="popup_window">
        <div style='text-align: right; color:red;cursor:pointer'>
        <a onfocus='this.blur();' onclick="document.getElementById('div_ft2.3').style.display = 'none' " >
           [x]</a>
        </div>
        <pre>
        
ft2.3: Traceback (most recent call last):
  File "C:\Users\JHMK-ZSS\PycharmProjects\pyrequests\venv\lib\site-packages\urllib3\connection.py", line 160, in _new_conn
    (self._dns_host, self.port), self.timeout, **extra_kw)
  File "C:\Users\JHMK-ZSS\PycharmProjects\pyrequests\venv\lib\site-packages\urllib3\util\connection.py", line 80, in create_connection
    raise err
  File "C:\Users\JHMK-ZSS\PycharmProjects\pyrequests\venv\lib\site-packages\urllib3\util\connection.py", line 70, in create_connection
    sock.connect(sa)
ConnectionRefusedError: [WinError 10061] 由于目标计算机积极拒绝，无法连接。

During handling of the above exception, another exception occurred:

Traceback (most recent call last):
  File "C:\Users\JHMK-ZSS\PycharmProjects\pyrequests\venv\lib\site-packages\urllib3\connectionpool.py", line 603, in urlopen
    chunked=chunked)
  File "C:\Users\JHMK-ZSS\PycharmProjects\pyrequests\venv\lib\site-packages\urllib3\connectionpool.py", line 355, in _make_request
    conn.request(method, url, **httplib_request_kw)
  File "C:\Users\JHMK-ZSS\AppData\Local\Programs\Python\Python37\lib\http\client.py", line 1229, in request
    self._send_request(method, url, body, headers, encode_chunked)
  File "C:\Users\JHMK-ZSS\AppData\Local\Programs\Python\Python37\lib\http\client.py", line 1275, in _send_request
    self.endheaders(body, encode_chunked=encode_chunked)
  File "C:\Users\JHMK-ZSS\AppData\Local\Programs\Python\Python37\lib\http\client.py", line 1224, in endheaders
    self._send_output(message_body, encode_chunked=encode_chunked)
  File "C:\Users\JHMK-ZSS\AppData\Local\Programs\Python\Python37\lib\http\client.py", line 1016, in _send_output
    self.send(msg)
  File "C:\Users\JHMK-ZSS\AppData\Local\Programs\Python\Python37\lib\http\client.py", line 956, in send
    self.connect()
  File "C:\Users\JHMK-ZSS\PycharmProjects\pyrequests\venv\lib\site-packages\urllib3\connection.py", line 183, in connect
    conn = self._new_conn()
  File "C:\Users\JHMK-ZSS\PycharmProjects\pyrequests\venv\lib\site-packages\urllib3\connection.py", line 169, in _new_conn
    self, "Failed to establish a new connection: %s" % e)
urllib3.exceptions.NewConnectionError: &lt;urllib3.connection.HTTPConnection object at 0x000001EA7E0A7828&gt;: Failed to establish a new connection: [WinError 10061] 由于目标计算机积极拒绝，无法连接。

During handling of the above exception, another exception occurred:

Traceback (most recent call last):
  File "C:\Users\JHMK-ZSS\PycharmProjects\pyrequests\venv\lib\site-packages\requests\adapters.py", line 449, in send
    timeout=timeout
  File "C:\Users\JHMK-ZSS\PycharmProjects\pyrequests\venv\lib\site-packages\urllib3\connectionpool.py", line 641, in urlopen
    _stacktrace=sys.exc_info()[2])
  File "C:\Users\JHMK-ZSS\PycharmProjects\pyrequests\venv\lib\site-packages\urllib3\util\retry.py", line 399, in increment
    raise MaxRetryError(_pool, url, error or ResponseError(cause))
urllib3.exceptions.MaxRetryError: HTTPConnectionPool(host='127.0.0.1', port=8000): Max retries exceeded with url: /api/get_guest_list/?eid=901&amp;phone=10000000000 (Caused by NewConnectionError('&lt;urllib3.connection.HTTPConnection object at 0x000001EA7E0A7828&gt;: Failed to establish a new connection: [WinError 10061] 由于目标计算机积极拒绝，无法连接。'))

During handling of the above exception, another exception occurred:

Traceback (most recent call last):
  File "C:\Users\JHMK-ZSS\PycharmProjects\pyrequests\interface\get_guest_list_test.py", line 43, in test_get_event_list_eid_phone_null
    r = requests.get(self.base_url, params={'eid':901,'phone':'10000000000'})
  File "C:\Users\JHMK-ZSS\PycharmProjects\pyrequests\venv\lib\site-packages\requests\api.py", line 75, in get
    return request('get', url, params=params, **kwargs)
  File "C:\Users\JHMK-ZSS\PycharmProjects\pyrequests\venv\lib\site-packages\requests\api.py", line 60, in request
    return session.request(method=method, url=url, **kwargs)
  File "C:\Users\JHMK-ZSS\PycharmProjects\pyrequests\venv\lib\site-packages\requests\sessions.py", line 533, in request
    resp = self.send(prep, **send_kwargs)
  File "C:\Users\JHMK-ZSS\PycharmProjects\pyrequests\venv\lib\site-packages\requests\sessions.py", line 646, in send
    r = adapter.send(request, **kwargs)
  File "C:\Users\JHMK-ZSS\PycharmProjects\pyrequests\venv\lib\site-packages\requests\adapters.py", line 516, in send
    raise ConnectionError(e, request=request)
requests.exceptions.ConnectionError: HTTPConnectionPool(host='127.0.0.1', port=8000): Max retries exceeded with url: /api/get_guest_list/?eid=901&amp;phone=10000000000 (Caused by NewConnectionError('&lt;urllib3.connection.HTTPConnection object at 0x000001EA7E0A7828&gt;: Failed to establish a new connection: [WinError 10061] 由于目标计算机积极拒绝，无法连接。'))


        </pre>
    </div>
    <!--css div popup end-->

    </td>
</tr>

<tr id='ft2.4' class='none'>
    <td class='errorCase'><div class='testcase'>test_get_event_list_eid_phone_null: 根据 eid 和phone 查询结果为空</div></td>
    <td colspan='5' align='center'>

    <!--css div popup start-->
    <a class="popup_link" onfocus='this.blur();' href="javascript:showTestDetail('div_ft2.4')" >
        error</a>

    <div id='div_ft2.4' class="popup_window">
        <div style='text-align: right; color:red;cursor:pointer'>
        <a onfocus='this.blur();' onclick="document.getElementById('div_ft2.4').style.display = 'none' " >
           [x]</a>
        </div>
        <pre>
        
ft2.4: Traceback (most recent call last):
  File "C:\Users\JHMK-ZSS\PycharmProjects\pyrequests\interface\get_guest_list_test.py", line 16, in tearDown
    print(self.result)
AttributeError: 'GetGuestListTest' object has no attribute 'result'


        </pre>
    </div>
    <!--css div popup end-->

    </td>
</tr>

<tr id='ft2.5' class='none'>
    <td class='errorCase'><div class='testcase'>test_get_event_list_eid_phone_success: 根据 eid 和phone 查询结果成功</div></td>
    <td colspan='5' align='center'>

    <!--css div popup start-->
    <a class="popup_link" onfocus='this.blur();' href="javascript:showTestDetail('div_ft2.5')" >
        error</a>

    <div id='div_ft2.5' class="popup_window">
        <div style='text-align: right; color:red;cursor:pointer'>
        <a onfocus='this.blur();' onclick="document.getElementById('div_ft2.5').style.display = 'none' " >
           [x]</a>
        </div>
        <pre>
        
ft2.5: Traceback (most recent call last):
  File "C:\Users\JHMK-ZSS\PycharmProjects\pyrequests\venv\lib\site-packages\urllib3\connection.py", line 160, in _new_conn
    (self._dns_host, self.port), self.timeout, **extra_kw)
  File "C:\Users\JHMK-ZSS\PycharmProjects\pyrequests\venv\lib\site-packages\urllib3\util\connection.py", line 80, in create_connection
    raise err
  File "C:\Users\JHMK-ZSS\PycharmProjects\pyrequests\venv\lib\site-packages\urllib3\util\connection.py", line 70, in create_connection
    sock.connect(sa)
ConnectionRefusedError: [WinError 10061] 由于目标计算机积极拒绝，无法连接。

During handling of the above exception, another exception occurred:

Traceback (most recent call last):
  File "C:\Users\JHMK-ZSS\PycharmProjects\pyrequests\venv\lib\site-packages\urllib3\connectionpool.py", line 603, in urlopen
    chunked=chunked)
  File "C:\Users\JHMK-ZSS\PycharmProjects\pyrequests\venv\lib\site-packages\urllib3\connectionpool.py", line 355, in _make_request
    conn.request(method, url, **httplib_request_kw)
  File "C:\Users\JHMK-ZSS\AppData\Local\Programs\Python\Python37\lib\http\client.py", line 1229, in request
    self._send_request(method, url, body, headers, encode_chunked)
  File "C:\Users\JHMK-ZSS\AppData\Local\Programs\Python\Python37\lib\http\client.py", line 1275, in _send_request
    self.endheaders(body, encode_chunked=encode_chunked)
  File "C:\Users\JHMK-ZSS\AppData\Local\Programs\Python\Python37\lib\http\client.py", line 1224, in endheaders
    self._send_output(message_body, encode_chunked=encode_chunked)
  File "C:\Users\JHMK-ZSS\AppData\Local\Programs\Python\Python37\lib\http\client.py", line 1016, in _send_output
    self.send(msg)
  File "C:\Users\JHMK-ZSS\AppData\Local\Programs\Python\Python37\lib\http\client.py", line 956, in send
    self.connect()
  File "C:\Users\JHMK-ZSS\PycharmProjects\pyrequests\venv\lib\site-packages\urllib3\connection.py", line 183, in connect
    conn = self._new_conn()
  File "C:\Users\JHMK-ZSS\PycharmProjects\pyrequests\venv\lib\site-packages\urllib3\connection.py", line 169, in _new_conn
    self, "Failed to establish a new connection: %s" % e)
urllib3.exceptions.NewConnectionError: &lt;urllib3.connection.HTTPConnection object at 0x000001EA7E00A588&gt;: Failed to establish a new connection: [WinError 10061] 由于目标计算机积极拒绝，无法连接。

During handling of the above exception, another exception occurred:

Traceback (most recent call last):
  File "C:\Users\JHMK-ZSS\PycharmProjects\pyrequests\venv\lib\site-packages\requests\adapters.py", line 449, in send
    timeout=timeout
  File "C:\Users\JHMK-ZSS\PycharmProjects\pyrequests\venv\lib\site-packages\urllib3\connectionpool.py", line 641, in urlopen
    _stacktrace=sys.exc_info()[2])
  File "C:\Users\JHMK-ZSS\PycharmProjects\pyrequests\venv\lib\site-packages\urllib3\util\retry.py", line 399, in increment
    raise MaxRetryError(_pool, url, error or ResponseError(cause))
urllib3.exceptions.MaxRetryError: HTTPConnectionPool(host='127.0.0.1', port=8000): Max retries exceeded with url: /api/get_guest_list/?eid=1&amp;phone=15945393949 (Caused by NewConnectionError('&lt;urllib3.connection.HTTPConnection object at 0x000001EA7E00A588&gt;: Failed to establish a new connection: [WinError 10061] 由于目标计算机积极拒绝，无法连接。'))

During handling of the above exception, another exception occurred:

Traceback (most recent call last):
  File "C:\Users\JHMK-ZSS\PycharmProjects\pyrequests\interface\get_guest_list_test.py", line 50, in test_get_event_list_eid_phone_success
    r = requests.get(self.base_url, params={'eid':1,'phone':'15945393949'})
  File "C:\Users\JHMK-ZSS\PycharmProjects\pyrequests\venv\lib\site-packages\requests\api.py", line 75, in get
    return request('get', url, params=params, **kwargs)
  File "C:\Users\JHMK-ZSS\PycharmProjects\pyrequests\venv\lib\site-packages\requests\api.py", line 60, in request
    return session.request(method=method, url=url, **kwargs)
  File "C:\Users\JHMK-ZSS\PycharmProjects\pyrequests\venv\lib\site-packages\requests\sessions.py", line 533, in request
    resp = self.send(prep, **send_kwargs)
  File "C:\Users\JHMK-ZSS\PycharmProjects\pyrequests\venv\lib\site-packages\requests\sessions.py", line 646, in send
    r = adapter.send(request, **kwargs)
  File "C:\Users\JHMK-ZSS\PycharmProjects\pyrequests\venv\lib\site-packages\requests\adapters.py", line 516, in send
    raise ConnectionError(e, request=request)
requests.exceptions.ConnectionError: HTTPConnectionPool(host='127.0.0.1', port=8000): Max retries exceeded with url: /api/get_guest_list/?eid=1&amp;phone=15945393949 (Caused by NewConnectionError('&lt;urllib3.connection.HTTPConnection object at 0x000001EA7E00A588&gt;: Failed to establish a new connection: [WinError 10061] 由于目标计算机积极拒绝，无法连接。'))


        </pre>
    </div>
    <!--css div popup end-->

    </td>
</tr>

<tr id='ft2.6' class='none'>
    <td class='errorCase'><div class='testcase'>test_get_event_list_eid_phone_success: 根据 eid 和phone 查询结果成功</div></td>
    <td colspan='5' align='center'>

    <!--css div popup start-->
    <a class="popup_link" onfocus='this.blur();' href="javascript:showTestDetail('div_ft2.6')" >
        error</a>

    <div id='div_ft2.6' class="popup_window">
        <div style='text-align: right; color:red;cursor:pointer'>
        <a onfocus='this.blur();' onclick="document.getElementById('div_ft2.6').style.display = 'none' " >
           [x]</a>
        </div>
        <pre>
        
ft2.6: Traceback (most recent call last):
  File "C:\Users\JHMK-ZSS\PycharmProjects\pyrequests\interface\get_guest_list_test.py", line 16, in tearDown
    print(self.result)
AttributeError: 'GetGuestListTest' object has no attribute 'result'


        </pre>
    </div>
    <!--css div popup end-->

    </td>
</tr>

<tr id='ft2.7' class='none'>
    <td class='errorCase'><div class='testcase'>test_get_event_list_eid_success: 根据 eid 查询结果成功</div></td>
    <td colspan='5' align='center'>

    <!--css div popup start-->
    <a class="popup_link" onfocus='this.blur();' href="javascript:showTestDetail('div_ft2.7')" >
        error</a>

    <div id='div_ft2.7' class="popup_window">
        <div style='text-align: right; color:red;cursor:pointer'>
        <a onfocus='this.blur();' onclick="document.getElementById('div_ft2.7').style.display = 'none' " >
           [x]</a>
        </div>
        <pre>
        
ft2.7: Traceback (most recent call last):
  File "C:\Users\JHMK-ZSS\PycharmProjects\pyrequests\venv\lib\site-packages\urllib3\connection.py", line 160, in _new_conn
    (self._dns_host, self.port), self.timeout, **extra_kw)
  File "C:\Users\JHMK-ZSS\PycharmProjects\pyrequests\venv\lib\site-packages\urllib3\util\connection.py", line 80, in create_connection
    raise err
  File "C:\Users\JHMK-ZSS\PycharmProjects\pyrequests\venv\lib\site-packages\urllib3\util\connection.py", line 70, in create_connection
    sock.connect(sa)
ConnectionRefusedError: [WinError 10061] 由于目标计算机积极拒绝，无法连接。

During handling of the above exception, another exception occurred:

Traceback (most recent call last):
  File "C:\Users\JHMK-ZSS\PycharmProjects\pyrequests\venv\lib\site-packages\urllib3\connectionpool.py", line 603, in urlopen
    chunked=chunked)
  File "C:\Users\JHMK-ZSS\PycharmProjects\pyrequests\venv\lib\site-packages\urllib3\connectionpool.py", line 355, in _make_request
    conn.request(method, url, **httplib_request_kw)
  File "C:\Users\JHMK-ZSS\AppData\Local\Programs\Python\Python37\lib\http\client.py", line 1229, in request
    self._send_request(method, url, body, headers, encode_chunked)
  File "C:\Users\JHMK-ZSS\AppData\Local\Programs\Python\Python37\lib\http\client.py", line 1275, in _send_request
    self.endheaders(body, encode_chunked=encode_chunked)
  File "C:\Users\JHMK-ZSS\AppData\Local\Programs\Python\Python37\lib\http\client.py", line 1224, in endheaders
    self._send_output(message_body, encode_chunked=encode_chunked)
  File "C:\Users\JHMK-ZSS\AppData\Local\Programs\Python\Python37\lib\http\client.py", line 1016, in _send_output
    self.send(msg)
  File "C:\Users\JHMK-ZSS\AppData\Local\Programs\Python\Python37\lib\http\client.py", line 956, in send
    self.connect()
  File "C:\Users\JHMK-ZSS\PycharmProjects\pyrequests\venv\lib\site-packages\urllib3\connection.py", line 183, in connect
    conn = self._new_conn()
  File "C:\Users\JHMK-ZSS\PycharmProjects\pyrequests\venv\lib\site-packages\urllib3\connection.py", line 169, in _new_conn
    self, "Failed to establish a new connection: %s" % e)
urllib3.exceptions.NewConnectionError: &lt;urllib3.connection.HTTPConnection object at 0x000001EA7DFFF518&gt;: Failed to establish a new connection: [WinError 10061] 由于目标计算机积极拒绝，无法连接。

During handling of the above exception, another exception occurred:

Traceback (most recent call last):
  File "C:\Users\JHMK-ZSS\PycharmProjects\pyrequests\venv\lib\site-packages\requests\adapters.py", line 449, in send
    timeout=timeout
  File "C:\Users\JHMK-ZSS\PycharmProjects\pyrequests\venv\lib\site-packages\urllib3\connectionpool.py", line 641, in urlopen
    _stacktrace=sys.exc_info()[2])
  File "C:\Users\JHMK-ZSS\PycharmProjects\pyrequests\venv\lib\site-packages\urllib3\util\retry.py", line 399, in increment
    raise MaxRetryError(_pool, url, error or ResponseError(cause))
urllib3.exceptions.MaxRetryError: HTTPConnectionPool(host='127.0.0.1', port=8000): Max retries exceeded with url: /api/get_guest_list/?eid=1 (Caused by NewConnectionError('&lt;urllib3.connection.HTTPConnection object at 0x000001EA7DFFF518&gt;: Failed to establish a new connection: [WinError 10061] 由于目标计算机积极拒绝，无法连接。'))

During handling of the above exception, another exception occurred:

Traceback (most recent call last):
  File "C:\Users\JHMK-ZSS\PycharmProjects\pyrequests\interface\get_guest_list_test.py", line 34, in test_get_event_list_eid_success
    r = requests.get(self.base_url, params={'eid':1})
  File "C:\Users\JHMK-ZSS\PycharmProjects\pyrequests\venv\lib\site-packages\requests\api.py", line 75, in get
    return request('get', url, params=params, **kwargs)
  File "C:\Users\JHMK-ZSS\PycharmProjects\pyrequests\venv\lib\site-packages\requests\api.py", line 60, in request
    return session.request(method=method, url=url, **kwargs)
  File "C:\Users\JHMK-ZSS\PycharmProjects\pyrequests\venv\lib\site-packages\requests\sessions.py", line 533, in request
    resp = self.send(prep, **send_kwargs)
  File "C:\Users\JHMK-ZSS\PycharmProjects\pyrequests\venv\lib\site-packages\requests\sessions.py", line 646, in send
    r = adapter.send(request, **kwargs)
  File "C:\Users\JHMK-ZSS\PycharmProjects\pyrequests\venv\lib\site-packages\requests\adapters.py", line 516, in send
    raise ConnectionError(e, request=request)
requests.exceptions.ConnectionError: HTTPConnectionPool(host='127.0.0.1', port=8000): Max retries exceeded with url: /api/get_guest_list/?eid=1 (Caused by NewConnectionError('&lt;urllib3.connection.HTTPConnection object at 0x000001EA7DFFF518&gt;: Failed to establish a new connection: [WinError 10061] 由于目标计算机积极拒绝，无法连接。'))


        </pre>
    </div>
    <!--css div popup end-->

    </td>
</tr>

<tr id='ft2.8' class='none'>
    <td class='errorCase'><div class='testcase'>test_get_event_list_eid_success: 根据 eid 查询结果成功</div></td>
    <td colspan='5' align='center'>

    <!--css div popup start-->
    <a class="popup_link" onfocus='this.blur();' href="javascript:showTestDetail('div_ft2.8')" >
        error</a>

    <div id='div_ft2.8' class="popup_window">
        <div style='text-align: right; color:red;cursor:pointer'>
        <a onfocus='this.blur();' onclick="document.getElementById('div_ft2.8').style.display = 'none' " >
           [x]</a>
        </div>
        <pre>
        
ft2.8: Traceback (most recent call last):
  File "C:\Users\JHMK-ZSS\PycharmProjects\pyrequests\interface\get_guest_list_test.py", line 16, in tearDown
    print(self.result)
AttributeError: 'GetGuestListTest' object has no attribute 'result'


        </pre>
    </div>
    <!--css div popup end-->

    </td>
</tr>

<tr id='ft2.9' class='none'>
    <td class='errorCase'><div class='testcase'>test_get_guest_list_eid_null: eid 参数为空</div></td>
    <td colspan='5' align='center'>

    <!--css div popup start-->
    <a class="popup_link" onfocus='this.blur();' href="javascript:showTestDetail('div_ft2.9')" >
        error</a>

    <div id='div_ft2.9' class="popup_window">
        <div style='text-align: right; color:red;cursor:pointer'>
        <a onfocus='this.blur();' onclick="document.getElementById('div_ft2.9').style.display = 'none' " >
           [x]</a>
        </div>
        <pre>
        
ft2.9: Traceback (most recent call last):
  File "C:\Users\JHMK-ZSS\PycharmProjects\pyrequests\venv\lib\site-packages\urllib3\connection.py", line 160, in _new_conn
    (self._dns_host, self.port), self.timeout, **extra_kw)
  File "C:\Users\JHMK-ZSS\PycharmProjects\pyrequests\venv\lib\site-packages\urllib3\util\connection.py", line 80, in create_connection
    raise err
  File "C:\Users\JHMK-ZSS\PycharmProjects\pyrequests\venv\lib\site-packages\urllib3\util\connection.py", line 70, in create_connection
    sock.connect(sa)
ConnectionRefusedError: [WinError 10061] 由于目标计算机积极拒绝，无法连接。

During handling of the above exception, another exception occurred:

Traceback (most recent call last):
  File "C:\Users\JHMK-ZSS\PycharmProjects\pyrequests\venv\lib\site-packages\urllib3\connectionpool.py", line 603, in urlopen
    chunked=chunked)
  File "C:\Users\JHMK-ZSS\PycharmProjects\pyrequests\venv\lib\site-packages\urllib3\connectionpool.py", line 355, in _make_request
    conn.request(method, url, **httplib_request_kw)
  File "C:\Users\JHMK-ZSS\AppData\Local\Programs\Python\Python37\lib\http\client.py", line 1229, in request
    self._send_request(method, url, body, headers, encode_chunked)
  File "C:\Users\JHMK-ZSS\AppData\Local\Programs\Python\Python37\lib\http\client.py", line 1275, in _send_request
    self.endheaders(body, encode_chunked=encode_chunked)
  File "C:\Users\JHMK-ZSS\AppData\Local\Programs\Python\Python37\lib\http\client.py", line 1224, in endheaders
    self._send_output(message_body, encode_chunked=encode_chunked)
  File "C:\Users\JHMK-ZSS\AppData\Local\Programs\Python\Python37\lib\http\client.py", line 1016, in _send_output
    self.send(msg)
  File "C:\Users\JHMK-ZSS\AppData\Local\Programs\Python\Python37\lib\http\client.py", line 956, in send
    self.connect()
  File "C:\Users\JHMK-ZSS\PycharmProjects\pyrequests\venv\lib\site-packages\urllib3\connection.py", line 183, in connect
    conn = self._new_conn()
  File "C:\Users\JHMK-ZSS\PycharmProjects\pyrequests\venv\lib\site-packages\urllib3\connection.py", line 169, in _new_conn
    self, "Failed to establish a new connection: %s" % e)
urllib3.exceptions.NewConnectionError: &lt;urllib3.connection.HTTPConnection object at 0x000001EA7E0B3A90&gt;: Failed to establish a new connection: [WinError 10061] 由于目标计算机积极拒绝，无法连接。

During handling of the above exception, another exception occurred:

Traceback (most recent call last):
  File "C:\Users\JHMK-ZSS\PycharmProjects\pyrequests\venv\lib\site-packages\requests\adapters.py", line 449, in send
    timeout=timeout
  File "C:\Users\JHMK-ZSS\PycharmProjects\pyrequests\venv\lib\site-packages\urllib3\connectionpool.py", line 641, in urlopen
    _stacktrace=sys.exc_info()[2])
  File "C:\Users\JHMK-ZSS\PycharmProjects\pyrequests\venv\lib\site-packages\urllib3\util\retry.py", line 399, in increment
    raise MaxRetryError(_pool, url, error or ResponseError(cause))
urllib3.exceptions.MaxRetryError: HTTPConnectionPool(host='127.0.0.1', port=8000): Max retries exceeded with url: /api/get_guest_list/?eid= (Caused by NewConnectionError('&lt;urllib3.connection.HTTPConnection object at 0x000001EA7E0B3A90&gt;: Failed to establish a new connection: [WinError 10061] 由于目标计算机积极拒绝，无法连接。'))

During handling of the above exception, another exception occurred:

Traceback (most recent call last):
  File "C:\Users\JHMK-ZSS\PycharmProjects\pyrequests\interface\get_guest_list_test.py", line 20, in test_get_guest_list_eid_null
    r = requests.get(self.base_url, params={'eid':''})
  File "C:\Users\JHMK-ZSS\PycharmProjects\pyrequests\venv\lib\site-packages\requests\api.py", line 75, in get
    return request('get', url, params=params, **kwargs)
  File "C:\Users\JHMK-ZSS\PycharmProjects\pyrequests\venv\lib\site-packages\requests\api.py", line 60, in request
    return session.request(method=method, url=url, **kwargs)
  File "C:\Users\JHMK-ZSS\PycharmProjects\pyrequests\venv\lib\site-packages\requests\sessions.py", line 533, in request
    resp = self.send(prep, **send_kwargs)
  File "C:\Users\JHMK-ZSS\PycharmProjects\pyrequests\venv\lib\site-packages\requests\sessions.py", line 646, in send
    r = adapter.send(request, **kwargs)
  File "C:\Users\JHMK-ZSS\PycharmProjects\pyrequests\venv\lib\site-packages\requests\adapters.py", line 516, in send
    raise ConnectionError(e, request=request)
requests.exceptions.ConnectionError: HTTPConnectionPool(host='127.0.0.1', port=8000): Max retries exceeded with url: /api/get_guest_list/?eid= (Caused by NewConnectionError('&lt;urllib3.connection.HTTPConnection object at 0x000001EA7E0B3A90&gt;: Failed to establish a new connection: [WinError 10061] 由于目标计算机积极拒绝，无法连接。'))


        </pre>
    </div>
    <!--css div popup end-->

    </td>
</tr>

<tr id='ft2.10' class='none'>
    <td class='errorCase'><div class='testcase'>test_get_guest_list_eid_null: eid 参数为空</div></td>
    <td colspan='5' align='center'>

    <!--css div popup start-->
    <a class="popup_link" onfocus='this.blur();' href="javascript:showTestDetail('div_ft2.10')" >
        error</a>

    <div id='div_ft2.10' class="popup_window">
        <div style='text-align: right; color:red;cursor:pointer'>
        <a onfocus='this.blur();' onclick="document.getElementById('div_ft2.10').style.display = 'none' " >
           [x]</a>
        </div>
        <pre>
        
ft2.10: Traceback (most recent call last):
  File "C:\Users\JHMK-ZSS\PycharmProjects\pyrequests\interface\get_guest_list_test.py", line 16, in tearDown
    print(self.result)
AttributeError: 'GetGuestListTest' object has no attribute 'result'


        </pre>
    </div>
    <!--css div popup end-->

    </td>
</tr>

<tr class='passClass'>
    <td>get_hot_list_test.GetHotList</td>
    <td>1</td>
    <td>1</td>
    <td>0</td>
    <td>0</td>
    <td><a href="javascript:showClassDetail('c3',1)">Detail</a></td>
</tr>

<tr id='pt3.1' class='hiddenRow'>
    <td class='none'><div class='testcase'>test_get_hot_list_success</div></td>
    <td colspan='5' align='center'>

    <!--css div popup start-->
    <a class="popup_link" onfocus='this.blur();' href="javascript:showTestDetail('div_pt3.1')" >
        pass</a>

    <div id='div_pt3.1' class="popup_window">
        <div style='text-align: right; color:red;cursor:pointer'>
        <a onfocus='this.blur();' onclick="document.getElementById('div_pt3.1').style.display = 'none' " >
           [x]</a>
        </div>
        <pre>
        
pt3.1: {'code': 200, 'msg': '成功!', 'data': [{'type': 'video', 'text': '原来长发飘飘瓜子脸都是骗人的！', 'username': '葫芦糊涂搞点事儿 [天天发新帖]', 'uid': '19160229', 'header': 'http://wimg.spriteapp.cn/profile/large/2018/01/11/5a5709ca83d49_mini.jpg', 'comment': 326, 'top_commentsVoiceuri': None, 'top_commentsContent': '都是潜力股啊，能瘦下来的话', 'top_commentsHeader': 'http://qzapp.qlogo.cn/qzapp/100336987/930C24273646E0E4586F7A032CC5AD61/100', 'top_commentsName': 'Dauntless1', 'passtime': '2018-04-27\xa008:25:02', 'soureid': 27742161, 'up': 950, 'down': 41, 'forward': 154, 'image': None, 'gif': None, 'thumbnail': 'http://wimg.spriteapp.cn/picture/2018/0426/27742161_407.jpg', 'video': 'http://wvideo.spriteapp.cn/video/2018/0426/5ae0d46bc1314_wpd.mp4'}, {'type': 'video', 'text': '“爸爸，你带妈妈去上学的时候怎么不带我去学，为什么？”', 'username': '共醉江湖 [快乐驿站]', 'uid': '15262111', 'header': 'http://wimg.spriteapp.cn/profile/large/2016/09/20/57e0cd620e99f_mini.jpg', 'comment': 43, 'top_commentsVoiceuri': None, 'top_commentsContent': '那时候王叔叔还没搬过来', 'top_commentsHeader': 'http://wimg.spriteapp.cn/profile', 'top_commentsName': '北极冰火', 'passtime': '2018-10-04\xa016:41:01', 'soureid': 28672360, 'up': 613, 'down': 26, 'forward': 8, 'image': None, 'gif': None, 'thumbnail': 'http://wimg.spriteapp.cn/picture/2018/1003/5bb3b38f525de__b.jpg', 'video': 'http://wvideo.spriteapp.cn/video/2018/1003/5bb3b38f6107d_wpd.mp4'}, {'type': 'video', 'text': '想害朕，门儿都么有！', 'username': '坏男孩4EL', 'uid': '22658470', 'header': 'http://qzapp.qlogo.cn/qzapp/100336987/CE9C943BEEAEA5331579A87B784D1FBA/100', 'comment': 53, 'top_commentsVoiceuri': None, 'top_commentsContent': '梦琪出暴击装', 'top_commentsHeader': 'http://thirdwx.qlogo.cn/mmopen/vi_32/VgZdBQZtwdGzeJWKIMNG1bl20v2FMnO4J0IVIjQRuTWO8OfXPf1VPmh2hJH6IgNu8t10ATkylQkl8H4YkDg5Hg/132', 'top_commentsName': '向上5pv', 'passtime': '2018-05-15\xa015:58:02', 'soureid': 27919433, 'up': 357, 'down': 8, 'forward': 34, 'image': None, 'gif': None, 'thumbnail': 'http://wimg.spriteapp.cn/picture/2018/0515/c3e82d4c-57de-11e8-adae-1866daeb0df1_wpd.jpg', 'video': 'http://wvideo.spriteapp.cn/video/2018/0515/c3e82d4c-57de-11e8-adae-1866daeb0df1_wpd.mp4'}, {'type': 'text', 'text': '小时候和人打架输了，被揍了一顿，不服气，和他约架在村外，我牵着我家和我叔家统共三条狼狗去的。我以为我这次赢定了，谁知道对方就牵来一只狗，母的。然后我方四个，一个挨顿揍，三个被俘虏，牵都牵不回去，麻麻滴，多年后想起来也生气，乡野孩子约个小架，用得着使这么高端离间计吗！', 'username': '赵碧虹 [为爱逆战]', 'uid': '22188795', 'header': 'http://wimg.spriteapp.cn/profile/large/2018/04/16/5ad4a9a3cfb8e_mini.jpg', 'comment': 155, 'top_commentsVoiceuri': None, 'top_commentsContent': '一位不愿意透露姓名的赵碧虹女士', 'top_commentsHeader': 'http://wimg.spriteapp.cn/profile/large/2018/04/16/5ad483efabbec_mini.jpg', 'top_commentsName': '段子护法长老', 'passtime': '2018-04-20\xa020:56:02', 'soureid': 27657298, 'up': 1316, 'down': 55, 'forward': 5, 'image': None, 'gif': None, 'thumbnail': None, 'video': None}, {'type': 'video', 'text': '确认过眼神，是斗不过的牛……', 'username': '动物嗨翻天', 'uid': '22930386', 'header': 'http://wimg.spriteapp.cn/profile/20180907130721805755.jpg', 'comment': 15, 'top_commentsVoiceuri': None, 'top_commentsContent': None, 'top_commentsHeader': None, 'top_commentsName': None, 'passtime': '2018-10-13\xa022:02:02', 'soureid': 28702825, 'up': 168, 'down': 8, 'forward': 6, 'image': None, 'gif': None, 'thumbnail': 'http://wimg.spriteapp.cn/picture/2018/1010/21d05688cc9b11e8a180842b2b4c75ab_wpd.jpg', 'video': 'http://tvideo.spriteapp.cn/video/2018/1010/21d05688cc9b11e8a180842b2b4c75ab_wpd.mp4'}, {'type': 'image', 'text': '有个“奇葩”姓氏，是什么样的体验！', 'username': '神马情况这是 [有容乃悦]', 'uid': '17588230', 'header': 'http://wimg.spriteapp.cn/profile/large/2018/03/21/5ab21157ebeaa_mini.jpg', 'comment': 1568, 'top_commentsVoiceuri': None, 'top_commentsContent': '我矿上有个同事叫毕泰贵，我们给他起的外号叫“日不起”，真事。', 'top_commentsHeader': 'http://qzapp.qlogo.cn/qzapp/100336987/DAAF163E21FD81E49FC80CAA959A5BAB/100', 'top_commentsName': 'Teamo123', 'passtime': '2017-10-04\xa009:07:54', 'soureid': 26503625, 'up': 906, 'down': 123, 'forward': 21, 'image': 'http://wimg.spriteapp.cn/ugc/2017/10/03/59d35caaa23b3_1.jpg', 'gif': None, 'thumbnail': 'http://wimg.spriteapp.cn/ugc/2017/10/03/59d35caaa23b3_1.jpg', 'video': None}, {'type': 'video', 'text': '许多时候女人的爆发并不是因为一件小事而已，是容忍过度，失望透顶…', 'username': '搞笑连连看', 'uid': '22904199', 'header': 'http://wimg.spriteapp.cn/profile/20180809175718586900.png', 'comment': 141, 'top_commentsVoiceuri': None, 'top_commentsContent': '买的要清洗麻烦  塑料瓶装满直接丢', 'top_commentsHeader': 'http://wx.qlogo.cn/mmopen/ZeuSZYeUCFKAAcsDnp7NtTsUbuicicWgnF10MlhXmwAj7aVzgrNuqNvwF1Nic5FykHA8zib2qFn2XPJeyLJI6diaLeLGP0INhAMtm/0', 'top_commentsName': '金泊利感应洁具', 'passtime': '2018-09-15\xa021:50:01', 'soureid': 28602224, 'up': 726, 'down': 37, 'forward': 55, 'image': None, 'gif': None, 'thumbnail': 'http://wimg.spriteapp.cn/picture/2018/0913/f4e2f21eb76611e89df5842b2b4c75ab_wpd.jpg', 'video': 'http://tvideo.spriteapp.cn/video/2018/0913/f4e2f21eb76611e89df5842b2b4c75ab_wpd.mp4'}, {'type': 'image', 'text': '好想谈恋爱，又怕挨日，姐夫们可不可以用男朋友的语气对我说一句话？', 'username': '风雨O7K [风雨同舟]', 'uid': '16672078', 'header': 'http://wimg.spriteapp.cn/profile/large/2017/12/14/5a3243aa2a150_mini.jpg', 'comment': 659, 'top_commentsVoiceuri': None, 'top_commentsContent': '做行政的，武夷山有外公，还想炒茶', 'top_commentsHeader': 'http://wimg.spriteapp.cn/profile/large/2016/05/01/5725e4a67fd53_mini.jpg', 'top_commentsName': '房地产开发商', 'passtime': '2018-01-29\xa006:38:01', 'soureid': 27179081, 'up': 661, 'down': 172, 'forward': 7, 'image': 'http://wimg.spriteapp.cn/ugc/2018/01/28/5a6d27777abc0_1.jpg', 'gif': None, 'thumbnail': 'http://wimg.spriteapp.cn/ugc/2018/01/28/5a6d27777abc0_1.jpg', 'video': None}, {'type': 'image', 'text': '从网上叫饭，点了根墨鱼肠…现在……', 'username': '雁回西楼', 'uid': '17246660', 'header': 'http://wimg.spriteapp.cn/profile/large/2017/06/02/5930c53896e3b_mini.jpg', 'comment': 214, 'top_commentsVoiceuri': None, 'top_commentsContent': '像老子便秘时拉的一样', 'top_commentsHeader': 'http://wx.qlogo.cn/mmopen/vi_32/Q0j4TwGTfTIwZLMettqia5ba8D72WHqlBjWgFTu6LZgrT0iclMJsO2oIK5WyouIFlvK4ZBCgAdC2nxya8kVRIF3g/0', 'top_commentsName': '再见那些年fvb', 'passtime': '2017-11-25\xa017:46:01', 'soureid': 26886943, 'up': 1745, 'down': 134, 'forward': 296, 'image': 'http://wimg.spriteapp.cn/ugc/2017/11/24/5a17a8f116355_1.jpg', 'gif': None, 'thumbnail': 'http://wimg.spriteapp.cn/ugc/2017/11/24/5a17a8f116355_1.jpg', 'video': None}, {'type': 'video', 'text': '大哥我是蛇！！有毒的那种！！可不可以给点面子啊！！！', 'username': '冀绪宠物狗', 'uid': '21499746', 'header': 'http://wimg.spriteapp.cn/profile/large/2018/04/17/5ad5c47ab9032_mini.jpg', 'comment': 175, 'top_commentsVoiceuri': None, 'top_commentsContent': '蛇：给个面子行不？我是蛇！是蛇！有毒的那种！！！', 'top_commentsHeader': 'http://wimg.spriteapp.cn/profile/large/2018/10/04/5bb506bf21810_mini.jpg', 'top_commentsName': '起个名字真麻烦', 'passtime': '2018-10-04\xa002:14:01', 'soureid': 28666735, 'up': 990, 'down': 27, 'forward': 42, 'image': None, 'gif': None, 'thumbnail': 'http://wimg.spriteapp.cn/picture/2018/1001/5bb1138b3255b__b.jpg', 'video': 'http://wvideo.spriteapp.cn/video/2018/1001/5bb1138b3ce85_wpd.mp4'}, {'type': 'video', 'text': '我秋名山车神绝非浪得虚名', 'username': '阿布路人甲', 'uid': '20398088', 'header': 'http://wimg.spriteapp.cn/profile/large/2018/03/08/5aa0ad7524e20_mini.jpg', 'comment': 14, 'top_commentsVoiceuri': None, 'top_commentsContent': None, 'top_commentsHeader': None, 'top_commentsName': None, 'passtime': '2018-05-15\xa021:25:02', 'soureid': 27917546, 'up': 142, 'down': 10, 'forward': 12, 'image': None, 'gif': None, 'thumbnail': 'http://wimg.spriteapp.cn/picture/2018/0514/5af9a9b3bd325cutblack_wpd.jpg', 'video': 'http://dvideo.spriteapp.cn/video/2018/0514/5af9a9b3bd325cutblack_wpd.mp4'}, {'type': 'image', 'text': '把权力的游戏翻译成“郭冬临之陷落”…这些神翻译承包你全年笑点', 'username': '这又神马情况 [有容乃悦]', 'uid': '19794323', 'header': 'http://wimg.spriteapp.cn/profile/large/2017/11/23/5a16a76c2ceeb_mini.jpg', 'comment': 44, 'top_commentsVoiceuri': None, 'top_commentsContent': None, 'top_commentsHeader': None, 'top_commentsName': None, 'passtime': '2018-04-24\xa011:00:01', 'soureid': 27715507, 'up': 409, 'down': 50, 'forward': 43, 'image': 'http://wimg.spriteapp.cn/ugc/2018/04/24/5ade8b9adb6e7_1.jpg', 'gif': None, 'thumbnail': 'http://wimg.spriteapp.cn/ugc/2018/04/24/5ade8b9adb6e7_1.jpg', 'video': None}, {'type': 'video', 'text': '我的A面是焦虑，B面是努力，为了生活，不断前行！', 'username': '开心菻花', 'uid': '22912414', 'header': 'http://wimg.spriteapp.cn/profile/large/2018/09/23/5ba7a9b61a52f_mini.jpg', 'comment': 66, 'top_commentsVoiceuri': None, 'top_commentsContent': '我看您们一个个是蕉绿吧？', 'top_commentsHeader': 'http://wimg.spriteapp.cn/profile/large/2018/05/20/5b00572c0176c_mini.jpg', 'top_commentsName': '昵称审核未通过', 'passtime': '2018-09-30\xa023:19:02', 'soureid': 28660247, 'up': 536, 'down': 31, 'forward': 70, 'image': None, 'gif': None, 'thumbnail': 'http://wimg.spriteapp.cn/picture/2018/0929/5baec01ccb90b__b.jpg', 'video': 'http://wvideo.spriteapp.cn/video/2018/0929/5baec01d0a82b_wpd.mp4'}, {'type': 'image', 'text': '十二星座的缺点？简直准到哭！', 'username': '喒你家玻璃 [砸你家玻璃]', 'uid': '18809558', 'header': 'http://wimg.spriteapp.cn/profile/large/2016/09/29/57ec70bf1adcb_mini.jpg', 'comment': 71, 'top_commentsVoiceuri': None, 'top_commentsContent': None, 'top_commentsHeader': None, 'top_commentsName': None, 'passtime': '2018-04-30\xa023:14:02', 'soureid': 27793649, 'up': 279, 'down': 36, 'forward': 40, 'image': 'http://wimg.spriteapp.cn/ugc/2018/04/30/5ae6f8db1d207_1.jpg', 'gif': None, 'thumbnail': 'http://wimg.spriteapp.cn/ugc/2018/04/30/5ae6f8db1d207_1.jpg', 'video': None}, {'type': 'video', 'text': '蘑菇头搞笑版《童年》，唱出了现实呀！', 'username': '刀郎情怀 [家天下]', 'uid': '21729132', 'header': 'http://wx.qlogo.cn/mmopen/vi_32/g5aApaCqmw4EvN5xib0zK51wpU0iagdh1DwjibUAMGVH6nicK5IGMaRbQoXCTULKrX7XYZtRXicNiaypzib3whJicV9BgA/132', 'comment': 28, 'top_commentsVoiceuri': None, 'top_commentsContent': '没有蘑菇头 改不了的歌！！！', 'top_commentsHeader': 'http://wimg.spriteapp.cn/profile/large/2018/05/01/5ae838807bbfe_mini.jpg', 'top_commentsName': '昵称审核未通过', 'passtime': '2018-05-06\xa008:17:02', 'soureid': 27809728, 'up': 167, 'down': 10, 'forward': 23, 'image': None, 'gif': None, 'thumbnail': 'http://wimg.spriteapp.cn/picture/2018/0502/5ae9488308413cut_wpd.jpg', 'video': 'http://wvideo.spriteapp.cn/video/2018/0502/5ae9488308413cut_wpd.mp4'}, {'type': 'video', 'text': '个人觉得小姐姐各方面还不错😁', 'username': '全球领先在线视频 [OMEGA帮派]', 'uid': '19634336', 'header': 'http://wimg.spriteapp.cn/profile/large/2018/08/06/5b6742613dbe7_mini.jpg', 'comment': 402, 'top_commentsVoiceuri': None, 'top_commentsContent': '这屁股扭得就是欠草呀', 'top_commentsHeader': 'http://thirdwx.qlogo.cn/mmopen/vi_32/Q0j4TwGTfTKXgcsLsqQU2ZXb073qMEibXV1CT9Dev4fQic5xm2RmAYAXnHdHH26LDz0bO0Cqbbyia19APp9CzA3Hg/132', 'top_commentsName': '灰火电', 'passtime': '2018-07-16\xa002:14:02', 'soureid': 28310937, 'up': 783, 'down': 134, 'forward': 64, 'image': None, 'gif': None, 'thumbnail': 'http://wimg.spriteapp.cn/picture/2018/0714/3e8096ce871011e89c87842b2b4c75ab_wpd.jpg', 'video': 'http://tvideo.spriteapp.cn/video/2018/0714/3e8096ce871011e89c87842b2b4c75ab_wpd.mp4'}, {'type': 'image', 'text': '穿汉服上街是种怎样的体验？美的不要不要的！', 'username': '我有了一个男朋友 [下一个天亮]', 'uid': '5348609', 'header': 'http://wimg.spriteapp.cn/profile/large/2016/07/26/57974925b34a6_mini.jpg', 'comment': 285, 'top_commentsVoiceuri': None, 'top_commentsContent': '关键还是看脸！脸！脸！，跟我念，乐一安，脸！', 'top_commentsHeader': 'http://qzapp.qlogo.cn/qzapp/100336987/AC1642588341331DA3497B247FC4D328/100', 'top_commentsName': 'FSS', 'passtime': '2017-10-19\xa016:54:02', 'soureid': 26626183, 'up': 1122, 'down': 101, 'forward': 45, 'image': 'http://wimg.spriteapp.cn/ugc/2017/10/18/59e75c43964fc_1.jpg', 'gif': None, 'thumbnail': 'http://wimg.spriteapp.cn/ugc/2017/10/18/59e75c43964fc_1.jpg', 'video': None}, {'type': 'image', 'text': '日本人的相亲，可简单粗暴多了', 'username': '喒你家玻璃 [砸你家玻璃]', 'uid': '18809558', 'header': 'http://wimg.spriteapp.cn/profile/large/2016/09/29/57ec70bf1adcb_mini.jpg', 'comment': 50, 'top_commentsVoiceuri': None, 'top_commentsContent': None, 'top_commentsHeader': None, 'top_commentsName': None, 'passtime': '2018-05-08\xa018:44:02', 'soureid': 27864268, 'up': 125, 'down': 16, 'forward': 2, 'image': 'http://wimg.spriteapp.cn/ugc/2018/05/08/5af1212d1d807_1.jpg', 'gif': None, 'thumbnail': 'http://wimg.spriteapp.cn/ugc/2018/05/08/5af1212d1d807_1.jpg', 'video': None}, {'type': 'video', 'text': '这一定是某位道友御风飞行开启了先天肛气', 'username': '切_格瓦拉', 'uid': '10060960', 'header': 'http://wimg.spriteapp.cn/profile/large/2014/12/08/5485a11fe0942_mini.jpg', 'comment': 463, 'top_commentsVoiceuri': None, 'top_commentsContent': None, 'top_commentsHeader': None, 'top_commentsName': None, 'passtime': '2017-12-26\xa006:50:02', 'soureid': 27035910, 'up': 1383, 'down': 92, 'forward': 161, 'image': None, 'gif': None, 'thumbnail': 'http://wimg.spriteapp.cn/picture/2017/1223/5a3e6d8709416__b.jpg', 'video': 'http://wvideo.spriteapp.cn/video/2017/1223/5a3e6d8717a26_wpd.mp4'}, {'type': 'gif', 'text': '偷拍时被空姐发现了，她竟然对我笑了，我该怎么办？小孩名字要不要先想好？', 'username': '搞笑强仔 [A号家族]', 'uid': '20986392', 'header': 'http://wimg.spriteapp.cn/profile/large/2018/02/07/5a7b0cbe0fe95_mini.jpg', 'comment': 232, 'top_commentsVoiceuri': None, 'top_commentsContent': '点赞的姐夫会长5cm，就算不缺5cm也可以赞', 'top_commentsHeader': 'http://wimg.spriteapp.cn/profile', 'top_commentsName': '同城专业接单', 'passtime': '2018-02-22\xa009:20:02', 'soureid': 27253589, 'up': 1913, 'down': 68, 'forward': 7, 'image': None, 'gif': 'http://wimg.spriteapp.cn/ugc/2018/02/21/5a8d8a6e2ad9d.gif', 'thumbnail': 'http://wimg.spriteapp.cn/ugc/2018/02/21/5a8d8a6e2ad9d_a_1.jpg', 'video': None}]}


        </pre>
    </div>
    <!--css div popup end-->

    </td>
</tr>

<tr class='failClass'>
    <td>get_kuaidi_test.Kuaiditest</td>
    <td>4</td>
    <td>2</td>
    <td>2</td>
    <td>0</td>
    <td><a href="javascript:showClassDetail('c4',4)">Detail</a></td>
</tr>

<tr id='ft4.1' class='none'>
    <td class='failCase'><div class='testcase'>test_kuaidi_postid_error: 快递单号不存在</div></td>
    <td colspan='5' align='center'>

    <!--css div popup start-->
    <a class="popup_link" onfocus='this.blur();' href="javascript:showTestDetail('div_ft4.1')" >
        fail</a>

    <div id='div_ft4.1' class="popup_window">
        <div style='text-align: right; color:red;cursor:pointer'>
        <a onfocus='this.blur();' onclick="document.getElementById('div_ft4.1').style.display = 'none' " >
           [x]</a>
        </div>
        <pre>
        
ft4.1: {'message': 'ok', 'nu': '111000000000000000', 'ischeck': '1', 'condition': 'F00', 'com': 'yuantong', 'status': '200', 'state': '3', 'data': [{'time': '2019-06-12 18:08:48', 'ftime': '2019-06-12 18:08:48', 'context': '【防城港市】 快件已送达【快递超市的中通快递01】, 如有问题请电联（13627700972 / 13627700972）, 感谢使用中通快递, 期待再次为您服务!', 'location': ''}, {'time': '2019-06-12 17:00:24', 'ftime': '2019-06-12 17:00:24', 'context': '【防城港市】 【防城港】 的公车镇分部（13627700972） 正在第1次派件, 请保持电话畅通,并耐心等待（95720为中通快递员外呼专属号码，请放心接听）', 'location': ''}, {'time': '2019-06-12 14:59:22', 'ftime': '2019-06-12 14:59:22', 'context': '【防城港市】 快件已经到达 【防城港】', 'location': ''}, {'time': '2019-06-12 04:25:44', 'ftime': '2019-06-12 04:25:44', 'context': '【南宁市】 快件离开 【南宁中转】 已发往 【防城港】', 'location': ''}, {'time': '2019-06-12 02:13:37', 'ftime': '2019-06-12 02:13:37', 'context': '【南宁市】 快件已经到达 【南宁中转】', 'location': ''}, {'time': '2019-06-10 21:43:54', 'ftime': '2019-06-10 21:43:54', 'context': '【金华市】 快件离开 【金华中转部】 已发往 【南宁中转】', 'location': ''}, {'time': '2019-06-10 21:28:36', 'ftime': '2019-06-10 21:28:36', 'context': '【金华市】 快件已经到达 【金华中转部】', 'location': ''}, {'time': '2019-06-10 16:25:30', 'ftime': '2019-06-10 16:25:30', 'context': '【衢州市】 快件离开 【衢州】 已发往 【南宁中转】', 'location': ''}, {'time': '2019-06-10 12:55:37', 'ftime': '2019-06-10 12:55:37', 'context': '【衢州市】 【衢州】（0570-3863255、0570-8880833） 的 瑜伽垫（15868182555） 已揽收', 'location': ''}]}
Traceback (most recent call last):
  File "C:\Users\JHMK-ZSS\PycharmProjects\pyrequests\interface\get_kuaidi_test.py", line 30, in test_kuaidi_postid_error
    self.assertEqual(self.result['data'][0]['context'],'查无结果')
AssertionError: '【防城港市】 快件已送达【快递超市的中通快递01】, 如有问题请电联（136277[37 chars]您服务!' != '查无结果'
- 【防城港市】 快件已送达【快递超市的中通快递01】, 如有问题请电联（13627700972 / 13627700972）, 感谢使用中通快递, 期待再次为您服务!
+ 查无结果



        </pre>
    </div>
    <!--css div popup end-->

    </td>
</tr>

<tr id='pt4.2' class='hiddenRow'>
    <td class='none'><div class='testcase'>test_kuaidi_postid_null: 快递单号为空</div></td>
    <td colspan='5' align='center'>

    <!--css div popup start-->
    <a class="popup_link" onfocus='this.blur();' href="javascript:showTestDetail('div_pt4.2')" >
        pass</a>

    <div id='div_pt4.2' class="popup_window">
        <div style='text-align: right; color:red;cursor:pointer'>
        <a onfocus='this.blur();' onclick="document.getElementById('div_pt4.2').style.display = 'none' " >
           [x]</a>
        </div>
        <pre>
        
pt4.2: {'message': '参数错误', 'nu': '', 'ischeck': '0', 'condition': '', 'com': '', 'status': '400', 'state': '0', 'data': []}


        </pre>
    </div>
    <!--css div popup end-->

    </td>
</tr>

<tr id='ft4.3' class='none'>
    <td class='failCase'><div class='testcase'>test_kuaidi_success: 查询成功</div></td>
    <td colspan='5' align='center'>

    <!--css div popup start-->
    <a class="popup_link" onfocus='this.blur();' href="javascript:showTestDetail('div_ft4.3')" >
        fail</a>

    <div id='div_ft4.3' class="popup_window">
        <div style='text-align: right; color:red;cursor:pointer'>
        <a onfocus='this.blur();' onclick="document.getElementById('div_ft4.3').style.display = 'none' " >
           [x]</a>
        </div>
        <pre>
        
ft4.3: {'message': '参数错误', 'nu': '', 'ischeck': '0', 'condition': '', 'com': '', 'status': '400', 'state': '0', 'data': []}
Traceback (most recent call last):
  File "C:\Users\JHMK-ZSS\PycharmProjects\pyrequests\interface\get_kuaidi_test.py", line 36, in test_kuaidi_success
    self.assertEqual(self.result['status'],'200')
AssertionError: '400' != '200'
- 400
? ^
+ 200
? ^



        </pre>
    </div>
    <!--css div popup end-->

    </td>
</tr>

<tr id='pt4.4' class='hiddenRow'>
    <td class='none'><div class='testcase'>test_kuaidi_type_null: 快递公司为空</div></td>
    <td colspan='5' align='center'>

    <!--css div popup start-->
    <a class="popup_link" onfocus='this.blur();' href="javascript:showTestDetail('div_pt4.4')" >
        pass</a>

    <div id='div_pt4.4' class="popup_window">
        <div style='text-align: right; color:red;cursor:pointer'>
        <a onfocus='this.blur();' onclick="document.getElementById('div_pt4.4').style.display = 'none' " >
           [x]</a>
        </div>
        <pre>
        
pt4.4: {'message': '参数错误', 'nu': '', 'ischeck': '0', 'condition': '', 'com': '', 'status': '400', 'state': '0', 'data': []}


        </pre>
    </div>
    <!--css div popup end-->

    </td>
</tr>

<tr id='total_row'>
    <td>Total</td>
    <td>23</td>
    <td>3</td>
    <td>2</td>
    <td>18</td>
    <td>&nbsp;</td>
</tr>
</table>

<div id='ending'>&nbsp;</div>

</body>
</html>
