<?xml version="1.0" encoding="UTF-8"?>
<!DOCTYPE html PUBLIC "-//W3C//DTD XHTML 1.0 Strict//EN" "http://www.w3.org/TR/xhtml1/DTD/xhtml1-strict.dtd">
<html xmlns="http://www.w3.org/1999/xhtml">
<head>
    <title>123</title>
    <meta name="generator" content="HTMLTestRunner 0.8.2"/>
    <meta http-equiv="Content-Type" content="text/html; charset=UTF-8"/>
    
<style type="text/css" media="screen">
body        { font-family: verdana, arial, helvetica, sans-serif; font-size: 80%; }
table       { font-size: 100%; }
pre         { }

/* -- heading ---------------------------------------------------------------------- */
h1 {
	font-size: 16pt;
	color: gray;
}
.heading {
    margin-top: 0ex;
    margin-bottom: 1ex;
}

.heading .attribute {
    margin-top: 1ex;
    margin-bottom: 0;
}

.heading .description {
    margin-top: 4ex;
    margin-bottom: 6ex;
}

/* -- css div popup ------------------------------------------------------------------------ */
a.popup_link {
}

a.popup_link:hover {
    color: red;
}

.popup_window {
    display: none;
    position: relative;
    left: 0px;
    top: 0px;
    /*border: solid #627173 1px; */
    padding: 10px;
    background-color: #E6E6D6;
    font-family: "Lucida Console", "Courier New", Courier, monospace;
    text-align: left;
    font-size: 8pt;
    width: 500px;
}

}
/* -- report ------------------------------------------------------------------------ */
#show_detail_line {
    margin-top: 3ex;
    margin-bottom: 1ex;
}
#result_table {
    width: 80%;
    border-collapse: collapse;
    border: 1px solid #777;
}
#header_row {
    font-weight: bold;
    color: white;
    background-color: #777;
}
#result_table td {
    border: 1px solid #777;
    padding: 2px;
}
#total_row  { font-weight: bold; }
.passClass  { background-color: #6c6; }
.failClass  { background-color: #c60; }
.errorClass { background-color: #c00; }
.passCase   { color: #6c6; }
.failCase   { color: #c60; font-weight: bold; }
.errorCase  { color: #c00; font-weight: bold; }
.hiddenRow  { display: none; }
.testcase   { margin-left: 2em; }


/* -- ending ---------------------------------------------------------------------- */
#ending {
}

</style>

</head>
<body>
<script language="javascript" type="text/javascript"><!--
output_list = Array();

/* level - 0:Summary; 1:Failed; 2:All */
function showCase(level) {
    trs = document.getElementsByTagName("tr");
    for (var i = 0; i < trs.length; i++) {
        tr = trs[i];
        id = tr.id;
        if (id.substr(0,2) == 'ft') {
            if (level < 1) {
                tr.className = 'hiddenRow';
            }
            else {
                tr.className = '';
            }
        }
        if (id.substr(0,2) == 'pt') {
            if (level > 1) {
                tr.className = '';
            }
            else {
                tr.className = 'hiddenRow';
            }
        }
    }
}


function showClassDetail(cid, count) {
    var id_list = Array(count);
    var toHide = 1;
    for (var i = 0; i < count; i++) {
        tid0 = 't' + cid.substr(1) + '.' + (i+1);
        tid = 'f' + tid0;
        tr = document.getElementById(tid);
        if (!tr) {
            tid = 'p' + tid0;
            tr = document.getElementById(tid);
        }
        id_list[i] = tid;
        if (tr.className) {
            toHide = 0;
        }
    }
    for (var i = 0; i < count; i++) {
        tid = id_list[i];
        if (toHide) {
            document.getElementById('div_'+tid).style.display = 'none'
            document.getElementById(tid).className = 'hiddenRow';
        }
        else {
            document.getElementById(tid).className = '';
        }
    }
}


function showTestDetail(div_id){
    var details_div = document.getElementById(div_id)
    var displayState = details_div.style.display
    // alert(displayState)
    if (displayState != 'block' ) {
        displayState = 'block'
        details_div.style.display = 'block'
    }
    else {
        details_div.style.display = 'none'
    }
}


function html_escape(s) {
    s = s.replace(/&/g,'&amp;');
    s = s.replace(/</g,'&lt;');
    s = s.replace(/>/g,'&gt;');
    return s;
}

/* obsoleted by detail in <div>
function showOutput(id, name) {
    var w = window.open("", //url
                    name,
                    "resizable,scrollbars,status,width=800,height=450");
    d = w.document;
    d.write("<pre>");
    d.write(html_escape(output_list[id]));
    d.write("\n");
    d.write("<a href='javascript:window.close()'>close</a>\n");
    d.write("</pre>\n");
    d.close();
}
*/
--></script>

<div class='heading'>
<h1>123</h1>
<p class='attribute'><strong>Start Time:</strong> 2019-06-17 14:44:02</p>
<p class='attribute'><strong>Duration:</strong> 0:00:10.529443</p>
<p class='attribute'><strong>Status:</strong> Pass 5 Failure 1 Error 21</p>

<p class='description'>456</p>
</div>



<p id='show_detail_line'>Show
<a href='javascript:showCase(0)'>Summary</a>
<a href='javascript:showCase(1)'>Failed</a>
<a href='javascript:showCase(2)'>All</a>
</p>
<table id='result_table'>
<colgroup>
<col align='left' />
<col align='right' />
<col align='right' />
<col align='right' />
<col align='right' />
<col align='right' />
</colgroup>
<tr id='header_row'>
    <td>Test Group/Test case</td>
    <td>Count</td>
    <td>Pass</td>
    <td>Fail</td>
    <td>Error</td>
    <td>View</td>
</tr>

<tr class='errorClass'>
    <td>get_event_list_test.GetEventListTest:  获得发布会列表 </td>
    <td>8</td>
    <td>0</td>
    <td>0</td>
    <td>8</td>
    <td><a href="javascript:showClassDetail('c1',8)">Detail</a></td>
</tr>

<tr id='ft1.1' class='none'>
    <td class='errorCase'><div class='testcase'>test_get_event_list_eid_error: eid=901 查询结果为空</div></td>
    <td colspan='5' align='center'>

    <!--css div popup start-->
    <a class="popup_link" onfocus='this.blur();' href="javascript:showTestDetail('div_ft1.1')" >
        error</a>

    <div id='div_ft1.1' class="popup_window">
        <div style='text-align: right; color:red;cursor:pointer'>
        <a onfocus='this.blur();' onclick="document.getElementById('div_ft1.1').style.display = 'none' " >
           [x]</a>
        </div>
        <pre>
        
ft1.1: Traceback (most recent call last):
  File "C:\Users\JHMK-ZSS\PycharmProjects\pyrequests\venv\lib\site-packages\urllib3\connection.py", line 160, in _new_conn
    (self._dns_host, self.port), self.timeout, **extra_kw)
  File "C:\Users\JHMK-ZSS\PycharmProjects\pyrequests\venv\lib\site-packages\urllib3\util\connection.py", line 80, in create_connection
    raise err
  File "C:\Users\JHMK-ZSS\PycharmProjects\pyrequests\venv\lib\site-packages\urllib3\util\connection.py", line 70, in create_connection
    sock.connect(sa)
ConnectionRefusedError: [WinError 10061] 由于目标计算机积极拒绝，无法连接。

During handling of the above exception, another exception occurred:

Traceback (most recent call last):
  File "C:\Users\JHMK-ZSS\PycharmProjects\pyrequests\venv\lib\site-packages\urllib3\connectionpool.py", line 603, in urlopen
    chunked=chunked)
  File "C:\Users\JHMK-ZSS\PycharmProjects\pyrequests\venv\lib\site-packages\urllib3\connectionpool.py", line 355, in _make_request
    conn.request(method, url, **httplib_request_kw)
  File "C:\Users\JHMK-ZSS\AppData\Local\Programs\Python\Python37\lib\http\client.py", line 1229, in request
    self._send_request(method, url, body, headers, encode_chunked)
  File "C:\Users\JHMK-ZSS\AppData\Local\Programs\Python\Python37\lib\http\client.py", line 1275, in _send_request
    self.endheaders(body, encode_chunked=encode_chunked)
  File "C:\Users\JHMK-ZSS\AppData\Local\Programs\Python\Python37\lib\http\client.py", line 1224, in endheaders
    self._send_output(message_body, encode_chunked=encode_chunked)
  File "C:\Users\JHMK-ZSS\AppData\Local\Programs\Python\Python37\lib\http\client.py", line 1016, in _send_output
    self.send(msg)
  File "C:\Users\JHMK-ZSS\AppData\Local\Programs\Python\Python37\lib\http\client.py", line 956, in send
    self.connect()
  File "C:\Users\JHMK-ZSS\PycharmProjects\pyrequests\venv\lib\site-packages\urllib3\connection.py", line 183, in connect
    conn = self._new_conn()
  File "C:\Users\JHMK-ZSS\PycharmProjects\pyrequests\venv\lib\site-packages\urllib3\connection.py", line 169, in _new_conn
    self, "Failed to establish a new connection: %s" % e)
urllib3.exceptions.NewConnectionError: &lt;urllib3.connection.HTTPConnection object at 0x000001F0784FF9E8&gt;: Failed to establish a new connection: [WinError 10061] 由于目标计算机积极拒绝，无法连接。

During handling of the above exception, another exception occurred:

Traceback (most recent call last):
  File "C:\Users\JHMK-ZSS\PycharmProjects\pyrequests\venv\lib\site-packages\requests\adapters.py", line 449, in send
    timeout=timeout
  File "C:\Users\JHMK-ZSS\PycharmProjects\pyrequests\venv\lib\site-packages\urllib3\connectionpool.py", line 641, in urlopen
    _stacktrace=sys.exc_info()[2])
  File "C:\Users\JHMK-ZSS\PycharmProjects\pyrequests\venv\lib\site-packages\urllib3\util\retry.py", line 399, in increment
    raise MaxRetryError(_pool, url, error or ResponseError(cause))
urllib3.exceptions.MaxRetryError: HTTPConnectionPool(host='127.0.0.1', port=8000): Max retries exceeded with url: /api/get_event_list/?eid=901 (Caused by NewConnectionError('&lt;urllib3.connection.HTTPConnection object at 0x000001F0784FF9E8&gt;: Failed to establish a new connection: [WinError 10061] 由于目标计算机积极拒绝，无法连接。'))

During handling of the above exception, another exception occurred:

Traceback (most recent call last):
  File "C:\Users\JHMK-ZSS\PycharmProjects\pyrequests\interface\get_event_list_test.py", line 21, in test_get_event_list_eid_error
    r = requests.get(self.base_url, params={'eid':901})
  File "C:\Users\JHMK-ZSS\PycharmProjects\pyrequests\venv\lib\site-packages\requests\api.py", line 75, in get
    return request('get', url, params=params, **kwargs)
  File "C:\Users\JHMK-ZSS\PycharmProjects\pyrequests\venv\lib\site-packages\requests\api.py", line 60, in request
    return session.request(method=method, url=url, **kwargs)
  File "C:\Users\JHMK-ZSS\PycharmProjects\pyrequests\venv\lib\site-packages\requests\sessions.py", line 533, in request
    resp = self.send(prep, **send_kwargs)
  File "C:\Users\JHMK-ZSS\PycharmProjects\pyrequests\venv\lib\site-packages\requests\sessions.py", line 646, in send
    r = adapter.send(request, **kwargs)
  File "C:\Users\JHMK-ZSS\PycharmProjects\pyrequests\venv\lib\site-packages\requests\adapters.py", line 516, in send
    raise ConnectionError(e, request=request)
requests.exceptions.ConnectionError: HTTPConnectionPool(host='127.0.0.1', port=8000): Max retries exceeded with url: /api/get_event_list/?eid=901 (Caused by NewConnectionError('&lt;urllib3.connection.HTTPConnection object at 0x000001F0784FF9E8&gt;: Failed to establish a new connection: [WinError 10061] 由于目标计算机积极拒绝，无法连接。'))


        </pre>
    </div>
    <!--css div popup end-->

    </td>
</tr>

<tr id='ft1.2' class='none'>
    <td class='errorCase'><div class='testcase'>test_get_event_list_eid_error: eid=901 查询结果为空</div></td>
    <td colspan='5' align='center'>

    <!--css div popup start-->
    <a class="popup_link" onfocus='this.blur();' href="javascript:showTestDetail('div_ft1.2')" >
        error</a>

    <div id='div_ft1.2' class="popup_window">
        <div style='text-align: right; color:red;cursor:pointer'>
        <a onfocus='this.blur();' onclick="document.getElementById('div_ft1.2').style.display = 'none' " >
           [x]</a>
        </div>
        <pre>
        
ft1.2: Traceback (most recent call last):
  File "C:\Users\JHMK-ZSS\PycharmProjects\pyrequests\interface\get_event_list_test.py", line 17, in tearDown
    print(self.result)
AttributeError: 'GetEventListTest' object has no attribute 'result'


        </pre>
    </div>
    <!--css div popup end-->

    </td>
</tr>

<tr id='ft1.3' class='none'>
    <td class='errorCase'><div class='testcase'>test_get_event_list_eid_success: 根据 eid 查询结果成功</div></td>
    <td colspan='5' align='center'>

    <!--css div popup start-->
    <a class="popup_link" onfocus='this.blur();' href="javascript:showTestDetail('div_ft1.3')" >
        error</a>

    <div id='div_ft1.3' class="popup_window">
        <div style='text-align: right; color:red;cursor:pointer'>
        <a onfocus='this.blur();' onclick="document.getElementById('div_ft1.3').style.display = 'none' " >
           [x]</a>
        </div>
        <pre>
        
ft1.3: Traceback (most recent call last):
  File "C:\Users\JHMK-ZSS\PycharmProjects\pyrequests\venv\lib\site-packages\urllib3\connection.py", line 160, in _new_conn
    (self._dns_host, self.port), self.timeout, **extra_kw)
  File "C:\Users\JHMK-ZSS\PycharmProjects\pyrequests\venv\lib\site-packages\urllib3\util\connection.py", line 80, in create_connection
    raise err
  File "C:\Users\JHMK-ZSS\PycharmProjects\pyrequests\venv\lib\site-packages\urllib3\util\connection.py", line 70, in create_connection
    sock.connect(sa)
ConnectionRefusedError: [WinError 10061] 由于目标计算机积极拒绝，无法连接。

During handling of the above exception, another exception occurred:

Traceback (most recent call last):
  File "C:\Users\JHMK-ZSS\PycharmProjects\pyrequests\venv\lib\site-packages\urllib3\connectionpool.py", line 603, in urlopen
    chunked=chunked)
  File "C:\Users\JHMK-ZSS\PycharmProjects\pyrequests\venv\lib\site-packages\urllib3\connectionpool.py", line 355, in _make_request
    conn.request(method, url, **httplib_request_kw)
  File "C:\Users\JHMK-ZSS\AppData\Local\Programs\Python\Python37\lib\http\client.py", line 1229, in request
    self._send_request(method, url, body, headers, encode_chunked)
  File "C:\Users\JHMK-ZSS\AppData\Local\Programs\Python\Python37\lib\http\client.py", line 1275, in _send_request
    self.endheaders(body, encode_chunked=encode_chunked)
  File "C:\Users\JHMK-ZSS\AppData\Local\Programs\Python\Python37\lib\http\client.py", line 1224, in endheaders
    self._send_output(message_body, encode_chunked=encode_chunked)
  File "C:\Users\JHMK-ZSS\AppData\Local\Programs\Python\Python37\lib\http\client.py", line 1016, in _send_output
    self.send(msg)
  File "C:\Users\JHMK-ZSS\AppData\Local\Programs\Python\Python37\lib\http\client.py", line 956, in send
    self.connect()
  File "C:\Users\JHMK-ZSS\PycharmProjects\pyrequests\venv\lib\site-packages\urllib3\connection.py", line 183, in connect
    conn = self._new_conn()
  File "C:\Users\JHMK-ZSS\PycharmProjects\pyrequests\venv\lib\site-packages\urllib3\connection.py", line 169, in _new_conn
    self, "Failed to establish a new connection: %s" % e)
urllib3.exceptions.NewConnectionError: &lt;urllib3.connection.HTTPConnection object at 0x000001F078548A58&gt;: Failed to establish a new connection: [WinError 10061] 由于目标计算机积极拒绝，无法连接。

During handling of the above exception, another exception occurred:

Traceback (most recent call last):
  File "C:\Users\JHMK-ZSS\PycharmProjects\pyrequests\venv\lib\site-packages\requests\adapters.py", line 449, in send
    timeout=timeout
  File "C:\Users\JHMK-ZSS\PycharmProjects\pyrequests\venv\lib\site-packages\urllib3\connectionpool.py", line 641, in urlopen
    _stacktrace=sys.exc_info()[2])
  File "C:\Users\JHMK-ZSS\PycharmProjects\pyrequests\venv\lib\site-packages\urllib3\util\retry.py", line 399, in increment
    raise MaxRetryError(_pool, url, error or ResponseError(cause))
urllib3.exceptions.MaxRetryError: HTTPConnectionPool(host='127.0.0.1', port=8000): Max retries exceeded with url: /api/get_event_list/?eid=1 (Caused by NewConnectionError('&lt;urllib3.connection.HTTPConnection object at 0x000001F078548A58&gt;: Failed to establish a new connection: [WinError 10061] 由于目标计算机积极拒绝，无法连接。'))

During handling of the above exception, another exception occurred:

Traceback (most recent call last):
  File "C:\Users\JHMK-ZSS\PycharmProjects\pyrequests\interface\get_event_list_test.py", line 28, in test_get_event_list_eid_success
    r = requests.get(self.base_url, params={'eid':1})
  File "C:\Users\JHMK-ZSS\PycharmProjects\pyrequests\venv\lib\site-packages\requests\api.py", line 75, in get
    return request('get', url, params=params, **kwargs)
  File "C:\Users\JHMK-ZSS\PycharmProjects\pyrequests\venv\lib\site-packages\requests\api.py", line 60, in request
    return session.request(method=method, url=url, **kwargs)
  File "C:\Users\JHMK-ZSS\PycharmProjects\pyrequests\venv\lib\site-packages\requests\sessions.py", line 533, in request
    resp = self.send(prep, **send_kwargs)
  File "C:\Users\JHMK-ZSS\PycharmProjects\pyrequests\venv\lib\site-packages\requests\sessions.py", line 646, in send
    r = adapter.send(request, **kwargs)
  File "C:\Users\JHMK-ZSS\PycharmProjects\pyrequests\venv\lib\site-packages\requests\adapters.py", line 516, in send
    raise ConnectionError(e, request=request)
requests.exceptions.ConnectionError: HTTPConnectionPool(host='127.0.0.1', port=8000): Max retries exceeded with url: /api/get_event_list/?eid=1 (Caused by NewConnectionError('&lt;urllib3.connection.HTTPConnection object at 0x000001F078548A58&gt;: Failed to establish a new connection: [WinError 10061] 由于目标计算机积极拒绝，无法连接。'))


        </pre>
    </div>
    <!--css div popup end-->

    </td>
</tr>

<tr id='ft1.4' class='none'>
    <td class='errorCase'><div class='testcase'>test_get_event_list_eid_success: 根据 eid 查询结果成功</div></td>
    <td colspan='5' align='center'>

    <!--css div popup start-->
    <a class="popup_link" onfocus='this.blur();' href="javascript:showTestDetail('div_ft1.4')" >
        error</a>

    <div id='div_ft1.4' class="popup_window">
        <div style='text-align: right; color:red;cursor:pointer'>
        <a onfocus='this.blur();' onclick="document.getElementById('div_ft1.4').style.display = 'none' " >
           [x]</a>
        </div>
        <pre>
        
ft1.4: Traceback (most recent call last):
  File "C:\Users\JHMK-ZSS\PycharmProjects\pyrequests\interface\get_event_list_test.py", line 17, in tearDown
    print(self.result)
AttributeError: 'GetEventListTest' object has no attribute 'result'


        </pre>
    </div>
    <!--css div popup end-->

    </td>
</tr>

<tr id='ft1.5' class='none'>
    <td class='errorCase'><div class='testcase'>test_get_event_list_nam_result_null: 关键字‘abc’查询</div></td>
    <td colspan='5' align='center'>

    <!--css div popup start-->
    <a class="popup_link" onfocus='this.blur();' href="javascript:showTestDetail('div_ft1.5')" >
        error</a>

    <div id='div_ft1.5' class="popup_window">
        <div style='text-align: right; color:red;cursor:pointer'>
        <a onfocus='this.blur();' onclick="document.getElementById('div_ft1.5').style.display = 'none' " >
           [x]</a>
        </div>
        <pre>
        
ft1.5: Traceback (most recent call last):
  File "C:\Users\JHMK-ZSS\PycharmProjects\pyrequests\venv\lib\site-packages\urllib3\connection.py", line 160, in _new_conn
    (self._dns_host, self.port), self.timeout, **extra_kw)
  File "C:\Users\JHMK-ZSS\PycharmProjects\pyrequests\venv\lib\site-packages\urllib3\util\connection.py", line 80, in create_connection
    raise err
  File "C:\Users\JHMK-ZSS\PycharmProjects\pyrequests\venv\lib\site-packages\urllib3\util\connection.py", line 70, in create_connection
    sock.connect(sa)
ConnectionRefusedError: [WinError 10061] 由于目标计算机积极拒绝，无法连接。

During handling of the above exception, another exception occurred:

Traceback (most recent call last):
  File "C:\Users\JHMK-ZSS\PycharmProjects\pyrequests\venv\lib\site-packages\urllib3\connectionpool.py", line 603, in urlopen
    chunked=chunked)
  File "C:\Users\JHMK-ZSS\PycharmProjects\pyrequests\venv\lib\site-packages\urllib3\connectionpool.py", line 355, in _make_request
    conn.request(method, url, **httplib_request_kw)
  File "C:\Users\JHMK-ZSS\AppData\Local\Programs\Python\Python37\lib\http\client.py", line 1229, in request
    self._send_request(method, url, body, headers, encode_chunked)
  File "C:\Users\JHMK-ZSS\AppData\Local\Programs\Python\Python37\lib\http\client.py", line 1275, in _send_request
    self.endheaders(body, encode_chunked=encode_chunked)
  File "C:\Users\JHMK-ZSS\AppData\Local\Programs\Python\Python37\lib\http\client.py", line 1224, in endheaders
    self._send_output(message_body, encode_chunked=encode_chunked)
  File "C:\Users\JHMK-ZSS\AppData\Local\Programs\Python\Python37\lib\http\client.py", line 1016, in _send_output
    self.send(msg)
  File "C:\Users\JHMK-ZSS\AppData\Local\Programs\Python\Python37\lib\http\client.py", line 956, in send
    self.connect()
  File "C:\Users\JHMK-ZSS\PycharmProjects\pyrequests\venv\lib\site-packages\urllib3\connection.py", line 183, in connect
    conn = self._new_conn()
  File "C:\Users\JHMK-ZSS\PycharmProjects\pyrequests\venv\lib\site-packages\urllib3\connection.py", line 169, in _new_conn
    self, "Failed to establish a new connection: %s" % e)
urllib3.exceptions.NewConnectionError: &lt;urllib3.connection.HTTPConnection object at 0x000001F0785B2160&gt;: Failed to establish a new connection: [WinError 10061] 由于目标计算机积极拒绝，无法连接。

During handling of the above exception, another exception occurred:

Traceback (most recent call last):
  File "C:\Users\JHMK-ZSS\PycharmProjects\pyrequests\venv\lib\site-packages\requests\adapters.py", line 449, in send
    timeout=timeout
  File "C:\Users\JHMK-ZSS\PycharmProjects\pyrequests\venv\lib\site-packages\urllib3\connectionpool.py", line 641, in urlopen
    _stacktrace=sys.exc_info()[2])
  File "C:\Users\JHMK-ZSS\PycharmProjects\pyrequests\venv\lib\site-packages\urllib3\util\retry.py", line 399, in increment
    raise MaxRetryError(_pool, url, error or ResponseError(cause))
urllib3.exceptions.MaxRetryError: HTTPConnectionPool(host='127.0.0.1', port=8000): Max retries exceeded with url: /api/get_event_list/?name=abc (Caused by NewConnectionError('&lt;urllib3.connection.HTTPConnection object at 0x000001F0785B2160&gt;: Failed to establish a new connection: [WinError 10061] 由于目标计算机积极拒绝，无法连接。'))

During handling of the above exception, another exception occurred:

Traceback (most recent call last):
  File "C:\Users\JHMK-ZSS\PycharmProjects\pyrequests\interface\get_event_list_test.py", line 37, in test_get_event_list_nam_result_null
    r = requests.get(self.base_url, params={'name':'abc'})
  File "C:\Users\JHMK-ZSS\PycharmProjects\pyrequests\venv\lib\site-packages\requests\api.py", line 75, in get
    return request('get', url, params=params, **kwargs)
  File "C:\Users\JHMK-ZSS\PycharmProjects\pyrequests\venv\lib\site-packages\requests\api.py", line 60, in request
    return session.request(method=method, url=url, **kwargs)
  File "C:\Users\JHMK-ZSS\PycharmProjects\pyrequests\venv\lib\site-packages\requests\sessions.py", line 533, in request
    resp = self.send(prep, **send_kwargs)
  File "C:\Users\JHMK-ZSS\PycharmProjects\pyrequests\venv\lib\site-packages\requests\sessions.py", line 646, in send
    r = adapter.send(request, **kwargs)
  File "C:\Users\JHMK-ZSS\PycharmProjects\pyrequests\venv\lib\site-packages\requests\adapters.py", line 516, in send
    raise ConnectionError(e, request=request)
requests.exceptions.ConnectionError: HTTPConnectionPool(host='127.0.0.1', port=8000): Max retries exceeded with url: /api/get_event_list/?name=abc (Caused by NewConnectionError('&lt;urllib3.connection.HTTPConnection object at 0x000001F0785B2160&gt;: Failed to establish a new connection: [WinError 10061] 由于目标计算机积极拒绝，无法连接。'))


        </pre>
    </div>
    <!--css div popup end-->

    </td>
</tr>

<tr id='ft1.6' class='none'>
    <td class='errorCase'><div class='testcase'>test_get_event_list_nam_result_null: 关键字‘abc’查询</div></td>
    <td colspan='5' align='center'>

    <!--css div popup start-->
    <a class="popup_link" onfocus='this.blur();' href="javascript:showTestDetail('div_ft1.6')" >
        error</a>

    <div id='div_ft1.6' class="popup_window">
        <div style='text-align: right; color:red;cursor:pointer'>
        <a onfocus='this.blur();' onclick="document.getElementById('div_ft1.6').style.display = 'none' " >
           [x]</a>
        </div>
        <pre>
        
ft1.6: Traceback (most recent call last):
  File "C:\Users\JHMK-ZSS\PycharmProjects\pyrequests\interface\get_event_list_test.py", line 17, in tearDown
    print(self.result)
AttributeError: 'GetEventListTest' object has no attribute 'result'


        </pre>
    </div>
    <!--css div popup end-->

    </td>
</tr>

<tr id='ft1.7' class='none'>
    <td class='errorCase'><div class='testcase'>test_get_event_list_name_find: 关键字‘发布会’模糊查询</div></td>
    <td colspan='5' align='center'>

    <!--css div popup start-->
    <a class="popup_link" onfocus='this.blur();' href="javascript:showTestDetail('div_ft1.7')" >
        error</a>

    <div id='div_ft1.7' class="popup_window">
        <div style='text-align: right; color:red;cursor:pointer'>
        <a onfocus='this.blur();' onclick="document.getElementById('div_ft1.7').style.display = 'none' " >
           [x]</a>
        </div>
        <pre>
        
ft1.7: Traceback (most recent call last):
  File "C:\Users\JHMK-ZSS\PycharmProjects\pyrequests\venv\lib\site-packages\urllib3\connection.py", line 160, in _new_conn
    (self._dns_host, self.port), self.timeout, **extra_kw)
  File "C:\Users\JHMK-ZSS\PycharmProjects\pyrequests\venv\lib\site-packages\urllib3\util\connection.py", line 80, in create_connection
    raise err
  File "C:\Users\JHMK-ZSS\PycharmProjects\pyrequests\venv\lib\site-packages\urllib3\util\connection.py", line 70, in create_connection
    sock.connect(sa)
ConnectionRefusedError: [WinError 10061] 由于目标计算机积极拒绝，无法连接。

During handling of the above exception, another exception occurred:

Traceback (most recent call last):
  File "C:\Users\JHMK-ZSS\PycharmProjects\pyrequests\venv\lib\site-packages\urllib3\connectionpool.py", line 603, in urlopen
    chunked=chunked)
  File "C:\Users\JHMK-ZSS\PycharmProjects\pyrequests\venv\lib\site-packages\urllib3\connectionpool.py", line 355, in _make_request
    conn.request(method, url, **httplib_request_kw)
  File "C:\Users\JHMK-ZSS\AppData\Local\Programs\Python\Python37\lib\http\client.py", line 1229, in request
    self._send_request(method, url, body, headers, encode_chunked)
  File "C:\Users\JHMK-ZSS\AppData\Local\Programs\Python\Python37\lib\http\client.py", line 1275, in _send_request
    self.endheaders(body, encode_chunked=encode_chunked)
  File "C:\Users\JHMK-ZSS\AppData\Local\Programs\Python\Python37\lib\http\client.py", line 1224, in endheaders
    self._send_output(message_body, encode_chunked=encode_chunked)
  File "C:\Users\JHMK-ZSS\AppData\Local\Programs\Python\Python37\lib\http\client.py", line 1016, in _send_output
    self.send(msg)
  File "C:\Users\JHMK-ZSS\AppData\Local\Programs\Python\Python37\lib\http\client.py", line 956, in send
    self.connect()
  File "C:\Users\JHMK-ZSS\PycharmProjects\pyrequests\venv\lib\site-packages\urllib3\connection.py", line 183, in connect
    conn = self._new_conn()
  File "C:\Users\JHMK-ZSS\PycharmProjects\pyrequests\venv\lib\site-packages\urllib3\connection.py", line 169, in _new_conn
    self, "Failed to establish a new connection: %s" % e)
urllib3.exceptions.NewConnectionError: &lt;urllib3.connection.HTTPConnection object at 0x000001F0785B2748&gt;: Failed to establish a new connection: [WinError 10061] 由于目标计算机积极拒绝，无法连接。

During handling of the above exception, another exception occurred:

Traceback (most recent call last):
  File "C:\Users\JHMK-ZSS\PycharmProjects\pyrequests\venv\lib\site-packages\requests\adapters.py", line 449, in send
    timeout=timeout
  File "C:\Users\JHMK-ZSS\PycharmProjects\pyrequests\venv\lib\site-packages\urllib3\connectionpool.py", line 641, in urlopen
    _stacktrace=sys.exc_info()[2])
  File "C:\Users\JHMK-ZSS\PycharmProjects\pyrequests\venv\lib\site-packages\urllib3\util\retry.py", line 399, in increment
    raise MaxRetryError(_pool, url, error or ResponseError(cause))
urllib3.exceptions.MaxRetryError: HTTPConnectionPool(host='127.0.0.1', port=8000): Max retries exceeded with url: /api/get_event_list/?name=xiao (Caused by NewConnectionError('&lt;urllib3.connection.HTTPConnection object at 0x000001F0785B2748&gt;: Failed to establish a new connection: [WinError 10061] 由于目标计算机积极拒绝，无法连接。'))

During handling of the above exception, another exception occurred:

Traceback (most recent call last):
  File "C:\Users\JHMK-ZSS\PycharmProjects\pyrequests\interface\get_event_list_test.py", line 44, in test_get_event_list_name_find
    r = requests.get(self.base_url, params={'name':'xiao'})
  File "C:\Users\JHMK-ZSS\PycharmProjects\pyrequests\venv\lib\site-packages\requests\api.py", line 75, in get
    return request('get', url, params=params, **kwargs)
  File "C:\Users\JHMK-ZSS\PycharmProjects\pyrequests\venv\lib\site-packages\requests\api.py", line 60, in request
    return session.request(method=method, url=url, **kwargs)
  File "C:\Users\JHMK-ZSS\PycharmProjects\pyrequests\venv\lib\site-packages\requests\sessions.py", line 533, in request
    resp = self.send(prep, **send_kwargs)
  File "C:\Users\JHMK-ZSS\PycharmProjects\pyrequests\venv\lib\site-packages\requests\sessions.py", line 646, in send
    r = adapter.send(request, **kwargs)
  File "C:\Users\JHMK-ZSS\PycharmProjects\pyrequests\venv\lib\site-packages\requests\adapters.py", line 516, in send
    raise ConnectionError(e, request=request)
requests.exceptions.ConnectionError: HTTPConnectionPool(host='127.0.0.1', port=8000): Max retries exceeded with url: /api/get_event_list/?name=xiao (Caused by NewConnectionError('&lt;urllib3.connection.HTTPConnection object at 0x000001F0785B2748&gt;: Failed to establish a new connection: [WinError 10061] 由于目标计算机积极拒绝，无法连接。'))


        </pre>
    </div>
    <!--css div popup end-->

    </td>
</tr>

<tr id='ft1.8' class='none'>
    <td class='errorCase'><div class='testcase'>test_get_event_list_name_find: 关键字‘发布会’模糊查询</div></td>
    <td colspan='5' align='center'>

    <!--css div popup start-->
    <a class="popup_link" onfocus='this.blur();' href="javascript:showTestDetail('div_ft1.8')" >
        error</a>

    <div id='div_ft1.8' class="popup_window">
        <div style='text-align: right; color:red;cursor:pointer'>
        <a onfocus='this.blur();' onclick="document.getElementById('div_ft1.8').style.display = 'none' " >
           [x]</a>
        </div>
        <pre>
        
ft1.8: Traceback (most recent call last):
  File "C:\Users\JHMK-ZSS\PycharmProjects\pyrequests\interface\get_event_list_test.py", line 17, in tearDown
    print(self.result)
AttributeError: 'GetEventListTest' object has no attribute 'result'


        </pre>
    </div>
    <!--css div popup end-->

    </td>
</tr>

<tr class='errorClass'>
    <td>get_guest_list_test.GetGuestListTest:  获得嘉宾列表 </td>
    <td>10</td>
    <td>0</td>
    <td>0</td>
    <td>10</td>
    <td><a href="javascript:showClassDetail('c2',10)">Detail</a></td>
</tr>

<tr id='ft2.1' class='none'>
    <td class='errorCase'><div class='testcase'>test_get_event_list_eid_error: 根据 eid 查询结果为空</div></td>
    <td colspan='5' align='center'>

    <!--css div popup start-->
    <a class="popup_link" onfocus='this.blur();' href="javascript:showTestDetail('div_ft2.1')" >
        error</a>

    <div id='div_ft2.1' class="popup_window">
        <div style='text-align: right; color:red;cursor:pointer'>
        <a onfocus='this.blur();' onclick="document.getElementById('div_ft2.1').style.display = 'none' " >
           [x]</a>
        </div>
        <pre>
        
ft2.1: Traceback (most recent call last):
  File "C:\Users\JHMK-ZSS\PycharmProjects\pyrequests\venv\lib\site-packages\urllib3\connection.py", line 160, in _new_conn
    (self._dns_host, self.port), self.timeout, **extra_kw)
  File "C:\Users\JHMK-ZSS\PycharmProjects\pyrequests\venv\lib\site-packages\urllib3\util\connection.py", line 80, in create_connection
    raise err
  File "C:\Users\JHMK-ZSS\PycharmProjects\pyrequests\venv\lib\site-packages\urllib3\util\connection.py", line 70, in create_connection
    sock.connect(sa)
ConnectionRefusedError: [WinError 10061] 由于目标计算机积极拒绝，无法连接。

During handling of the above exception, another exception occurred:

Traceback (most recent call last):
  File "C:\Users\JHMK-ZSS\PycharmProjects\pyrequests\venv\lib\site-packages\urllib3\connectionpool.py", line 603, in urlopen
    chunked=chunked)
  File "C:\Users\JHMK-ZSS\PycharmProjects\pyrequests\venv\lib\site-packages\urllib3\connectionpool.py", line 355, in _make_request
    conn.request(method, url, **httplib_request_kw)
  File "C:\Users\JHMK-ZSS\AppData\Local\Programs\Python\Python37\lib\http\client.py", line 1229, in request
    self._send_request(method, url, body, headers, encode_chunked)
  File "C:\Users\JHMK-ZSS\AppData\Local\Programs\Python\Python37\lib\http\client.py", line 1275, in _send_request
    self.endheaders(body, encode_chunked=encode_chunked)
  File "C:\Users\JHMK-ZSS\AppData\Local\Programs\Python\Python37\lib\http\client.py", line 1224, in endheaders
    self._send_output(message_body, encode_chunked=encode_chunked)
  File "C:\Users\JHMK-ZSS\AppData\Local\Programs\Python\Python37\lib\http\client.py", line 1016, in _send_output
    self.send(msg)
  File "C:\Users\JHMK-ZSS\AppData\Local\Programs\Python\Python37\lib\http\client.py", line 956, in send
    self.connect()
  File "C:\Users\JHMK-ZSS\PycharmProjects\pyrequests\venv\lib\site-packages\urllib3\connection.py", line 183, in connect
    conn = self._new_conn()
  File "C:\Users\JHMK-ZSS\PycharmProjects\pyrequests\venv\lib\site-packages\urllib3\connection.py", line 169, in _new_conn
    self, "Failed to establish a new connection: %s" % e)
urllib3.exceptions.NewConnectionError: &lt;urllib3.connection.HTTPConnection object at 0x000001F078548AC8&gt;: Failed to establish a new connection: [WinError 10061] 由于目标计算机积极拒绝，无法连接。

During handling of the above exception, another exception occurred:

Traceback (most recent call last):
  File "C:\Users\JHMK-ZSS\PycharmProjects\pyrequests\venv\lib\site-packages\requests\adapters.py", line 449, in send
    timeout=timeout
  File "C:\Users\JHMK-ZSS\PycharmProjects\pyrequests\venv\lib\site-packages\urllib3\connectionpool.py", line 641, in urlopen
    _stacktrace=sys.exc_info()[2])
  File "C:\Users\JHMK-ZSS\PycharmProjects\pyrequests\venv\lib\site-packages\urllib3\util\retry.py", line 399, in increment
    raise MaxRetryError(_pool, url, error or ResponseError(cause))
urllib3.exceptions.MaxRetryError: HTTPConnectionPool(host='127.0.0.1', port=8000): Max retries exceeded with url: /api/get_guest_list/?eid=901 (Caused by NewConnectionError('&lt;urllib3.connection.HTTPConnection object at 0x000001F078548AC8&gt;: Failed to establish a new connection: [WinError 10061] 由于目标计算机积极拒绝，无法连接。'))

During handling of the above exception, another exception occurred:

Traceback (most recent call last):
  File "C:\Users\JHMK-ZSS\PycharmProjects\pyrequests\interface\get_guest_list_test.py", line 27, in test_get_event_list_eid_error
    r = requests.get(self.base_url, params={'eid':901})
  File "C:\Users\JHMK-ZSS\PycharmProjects\pyrequests\venv\lib\site-packages\requests\api.py", line 75, in get
    return request('get', url, params=params, **kwargs)
  File "C:\Users\JHMK-ZSS\PycharmProjects\pyrequests\venv\lib\site-packages\requests\api.py", line 60, in request
    return session.request(method=method, url=url, **kwargs)
  File "C:\Users\JHMK-ZSS\PycharmProjects\pyrequests\venv\lib\site-packages\requests\sessions.py", line 533, in request
    resp = self.send(prep, **send_kwargs)
  File "C:\Users\JHMK-ZSS\PycharmProjects\pyrequests\venv\lib\site-packages\requests\sessions.py", line 646, in send
    r = adapter.send(request, **kwargs)
  File "C:\Users\JHMK-ZSS\PycharmProjects\pyrequests\venv\lib\site-packages\requests\adapters.py", line 516, in send
    raise ConnectionError(e, request=request)
requests.exceptions.ConnectionError: HTTPConnectionPool(host='127.0.0.1', port=8000): Max retries exceeded with url: /api/get_guest_list/?eid=901 (Caused by NewConnectionError('&lt;urllib3.connection.HTTPConnection object at 0x000001F078548AC8&gt;: Failed to establish a new connection: [WinError 10061] 由于目标计算机积极拒绝，无法连接。'))


        </pre>
    </div>
    <!--css div popup end-->

    </td>
</tr>

<tr id='ft2.2' class='none'>
    <td class='errorCase'><div class='testcase'>test_get_event_list_eid_error: 根据 eid 查询结果为空</div></td>
    <td colspan='5' align='center'>

    <!--css div popup start-->
    <a class="popup_link" onfocus='this.blur();' href="javascript:showTestDetail('div_ft2.2')" >
        error</a>

    <div id='div_ft2.2' class="popup_window">
        <div style='text-align: right; color:red;cursor:pointer'>
        <a onfocus='this.blur();' onclick="document.getElementById('div_ft2.2').style.display = 'none' " >
           [x]</a>
        </div>
        <pre>
        
ft2.2: Traceback (most recent call last):
  File "C:\Users\JHMK-ZSS\PycharmProjects\pyrequests\interface\get_guest_list_test.py", line 16, in tearDown
    print(self.result)
AttributeError: 'GetGuestListTest' object has no attribute 'result'


        </pre>
    </div>
    <!--css div popup end-->

    </td>
</tr>

<tr id='ft2.3' class='none'>
    <td class='errorCase'><div class='testcase'>test_get_event_list_eid_phone_null: 根据 eid 和phone 查询结果为空</div></td>
    <td colspan='5' align='center'>

    <!--css div popup start-->
    <a class="popup_link" onfocus='this.blur();' href="javascript:showTestDetail('div_ft2.3')" >
        error</a>

    <div id='div_ft2.3' class="popup_window">
        <div style='text-align: right; color:red;cursor:pointer'>
        <a onfocus='this.blur();' onclick="document.getElementById('div_ft2.3').style.display = 'none' " >
           [x]</a>
        </div>
        <pre>
        
ft2.3: Traceback (most recent call last):
  File "C:\Users\JHMK-ZSS\PycharmProjects\pyrequests\venv\lib\site-packages\urllib3\connection.py", line 160, in _new_conn
    (self._dns_host, self.port), self.timeout, **extra_kw)
  File "C:\Users\JHMK-ZSS\PycharmProjects\pyrequests\venv\lib\site-packages\urllib3\util\connection.py", line 80, in create_connection
    raise err
  File "C:\Users\JHMK-ZSS\PycharmProjects\pyrequests\venv\lib\site-packages\urllib3\util\connection.py", line 70, in create_connection
    sock.connect(sa)
ConnectionRefusedError: [WinError 10061] 由于目标计算机积极拒绝，无法连接。

During handling of the above exception, another exception occurred:

Traceback (most recent call last):
  File "C:\Users\JHMK-ZSS\PycharmProjects\pyrequests\venv\lib\site-packages\urllib3\connectionpool.py", line 603, in urlopen
    chunked=chunked)
  File "C:\Users\JHMK-ZSS\PycharmProjects\pyrequests\venv\lib\site-packages\urllib3\connectionpool.py", line 355, in _make_request
    conn.request(method, url, **httplib_request_kw)
  File "C:\Users\JHMK-ZSS\AppData\Local\Programs\Python\Python37\lib\http\client.py", line 1229, in request
    self._send_request(method, url, body, headers, encode_chunked)
  File "C:\Users\JHMK-ZSS\AppData\Local\Programs\Python\Python37\lib\http\client.py", line 1275, in _send_request
    self.endheaders(body, encode_chunked=encode_chunked)
  File "C:\Users\JHMK-ZSS\AppData\Local\Programs\Python\Python37\lib\http\client.py", line 1224, in endheaders
    self._send_output(message_body, encode_chunked=encode_chunked)
  File "C:\Users\JHMK-ZSS\AppData\Local\Programs\Python\Python37\lib\http\client.py", line 1016, in _send_output
    self.send(msg)
  File "C:\Users\JHMK-ZSS\AppData\Local\Programs\Python\Python37\lib\http\client.py", line 956, in send
    self.connect()
  File "C:\Users\JHMK-ZSS\PycharmProjects\pyrequests\venv\lib\site-packages\urllib3\connection.py", line 183, in connect
    conn = self._new_conn()
  File "C:\Users\JHMK-ZSS\PycharmProjects\pyrequests\venv\lib\site-packages\urllib3\connection.py", line 169, in _new_conn
    self, "Failed to establish a new connection: %s" % e)
urllib3.exceptions.NewConnectionError: &lt;urllib3.connection.HTTPConnection object at 0x000001F0784F2710&gt;: Failed to establish a new connection: [WinError 10061] 由于目标计算机积极拒绝，无法连接。

During handling of the above exception, another exception occurred:

Traceback (most recent call last):
  File "C:\Users\JHMK-ZSS\PycharmProjects\pyrequests\venv\lib\site-packages\requests\adapters.py", line 449, in send
    timeout=timeout
  File "C:\Users\JHMK-ZSS\PycharmProjects\pyrequests\venv\lib\site-packages\urllib3\connectionpool.py", line 641, in urlopen
    _stacktrace=sys.exc_info()[2])
  File "C:\Users\JHMK-ZSS\PycharmProjects\pyrequests\venv\lib\site-packages\urllib3\util\retry.py", line 399, in increment
    raise MaxRetryError(_pool, url, error or ResponseError(cause))
urllib3.exceptions.MaxRetryError: HTTPConnectionPool(host='127.0.0.1', port=8000): Max retries exceeded with url: /api/get_guest_list/?eid=901&amp;phone=10000000000 (Caused by NewConnectionError('&lt;urllib3.connection.HTTPConnection object at 0x000001F0784F2710&gt;: Failed to establish a new connection: [WinError 10061] 由于目标计算机积极拒绝，无法连接。'))

During handling of the above exception, another exception occurred:

Traceback (most recent call last):
  File "C:\Users\JHMK-ZSS\PycharmProjects\pyrequests\interface\get_guest_list_test.py", line 43, in test_get_event_list_eid_phone_null
    r = requests.get(self.base_url, params={'eid':901,'phone':'10000000000'})
  File "C:\Users\JHMK-ZSS\PycharmProjects\pyrequests\venv\lib\site-packages\requests\api.py", line 75, in get
    return request('get', url, params=params, **kwargs)
  File "C:\Users\JHMK-ZSS\PycharmProjects\pyrequests\venv\lib\site-packages\requests\api.py", line 60, in request
    return session.request(method=method, url=url, **kwargs)
  File "C:\Users\JHMK-ZSS\PycharmProjects\pyrequests\venv\lib\site-packages\requests\sessions.py", line 533, in request
    resp = self.send(prep, **send_kwargs)
  File "C:\Users\JHMK-ZSS\PycharmProjects\pyrequests\venv\lib\site-packages\requests\sessions.py", line 646, in send
    r = adapter.send(request, **kwargs)
  File "C:\Users\JHMK-ZSS\PycharmProjects\pyrequests\venv\lib\site-packages\requests\adapters.py", line 516, in send
    raise ConnectionError(e, request=request)
requests.exceptions.ConnectionError: HTTPConnectionPool(host='127.0.0.1', port=8000): Max retries exceeded with url: /api/get_guest_list/?eid=901&amp;phone=10000000000 (Caused by NewConnectionError('&lt;urllib3.connection.HTTPConnection object at 0x000001F0784F2710&gt;: Failed to establish a new connection: [WinError 10061] 由于目标计算机积极拒绝，无法连接。'))


        </pre>
    </div>
    <!--css div popup end-->

    </td>
</tr>

<tr id='ft2.4' class='none'>
    <td class='errorCase'><div class='testcase'>test_get_event_list_eid_phone_null: 根据 eid 和phone 查询结果为空</div></td>
    <td colspan='5' align='center'>

    <!--css div popup start-->
    <a class="popup_link" onfocus='this.blur();' href="javascript:showTestDetail('div_ft2.4')" >
        error</a>

    <div id='div_ft2.4' class="popup_window">
        <div style='text-align: right; color:red;cursor:pointer'>
        <a onfocus='this.blur();' onclick="document.getElementById('div_ft2.4').style.display = 'none' " >
           [x]</a>
        </div>
        <pre>
        
ft2.4: Traceback (most recent call last):
  File "C:\Users\JHMK-ZSS\PycharmProjects\pyrequests\interface\get_guest_list_test.py", line 16, in tearDown
    print(self.result)
AttributeError: 'GetGuestListTest' object has no attribute 'result'


        </pre>
    </div>
    <!--css div popup end-->

    </td>
</tr>

<tr id='ft2.5' class='none'>
    <td class='errorCase'><div class='testcase'>test_get_event_list_eid_phone_success: 根据 eid 和phone 查询结果成功</div></td>
    <td colspan='5' align='center'>

    <!--css div popup start-->
    <a class="popup_link" onfocus='this.blur();' href="javascript:showTestDetail('div_ft2.5')" >
        error</a>

    <div id='div_ft2.5' class="popup_window">
        <div style='text-align: right; color:red;cursor:pointer'>
        <a onfocus='this.blur();' onclick="document.getElementById('div_ft2.5').style.display = 'none' " >
           [x]</a>
        </div>
        <pre>
        
ft2.5: Traceback (most recent call last):
  File "C:\Users\JHMK-ZSS\PycharmProjects\pyrequests\venv\lib\site-packages\urllib3\connection.py", line 160, in _new_conn
    (self._dns_host, self.port), self.timeout, **extra_kw)
  File "C:\Users\JHMK-ZSS\PycharmProjects\pyrequests\venv\lib\site-packages\urllib3\util\connection.py", line 80, in create_connection
    raise err
  File "C:\Users\JHMK-ZSS\PycharmProjects\pyrequests\venv\lib\site-packages\urllib3\util\connection.py", line 70, in create_connection
    sock.connect(sa)
ConnectionRefusedError: [WinError 10061] 由于目标计算机积极拒绝，无法连接。

During handling of the above exception, another exception occurred:

Traceback (most recent call last):
  File "C:\Users\JHMK-ZSS\PycharmProjects\pyrequests\venv\lib\site-packages\urllib3\connectionpool.py", line 603, in urlopen
    chunked=chunked)
  File "C:\Users\JHMK-ZSS\PycharmProjects\pyrequests\venv\lib\site-packages\urllib3\connectionpool.py", line 355, in _make_request
    conn.request(method, url, **httplib_request_kw)
  File "C:\Users\JHMK-ZSS\AppData\Local\Programs\Python\Python37\lib\http\client.py", line 1229, in request
    self._send_request(method, url, body, headers, encode_chunked)
  File "C:\Users\JHMK-ZSS\AppData\Local\Programs\Python\Python37\lib\http\client.py", line 1275, in _send_request
    self.endheaders(body, encode_chunked=encode_chunked)
  File "C:\Users\JHMK-ZSS\AppData\Local\Programs\Python\Python37\lib\http\client.py", line 1224, in endheaders
    self._send_output(message_body, encode_chunked=encode_chunked)
  File "C:\Users\JHMK-ZSS\AppData\Local\Programs\Python\Python37\lib\http\client.py", line 1016, in _send_output
    self.send(msg)
  File "C:\Users\JHMK-ZSS\AppData\Local\Programs\Python\Python37\lib\http\client.py", line 956, in send
    self.connect()
  File "C:\Users\JHMK-ZSS\PycharmProjects\pyrequests\venv\lib\site-packages\urllib3\connection.py", line 183, in connect
    conn = self._new_conn()
  File "C:\Users\JHMK-ZSS\PycharmProjects\pyrequests\venv\lib\site-packages\urllib3\connection.py", line 169, in _new_conn
    self, "Failed to establish a new connection: %s" % e)
urllib3.exceptions.NewConnectionError: &lt;urllib3.connection.HTTPConnection object at 0x000001F0785B2710&gt;: Failed to establish a new connection: [WinError 10061] 由于目标计算机积极拒绝，无法连接。

During handling of the above exception, another exception occurred:

Traceback (most recent call last):
  File "C:\Users\JHMK-ZSS\PycharmProjects\pyrequests\venv\lib\site-packages\requests\adapters.py", line 449, in send
    timeout=timeout
  File "C:\Users\JHMK-ZSS\PycharmProjects\pyrequests\venv\lib\site-packages\urllib3\connectionpool.py", line 641, in urlopen
    _stacktrace=sys.exc_info()[2])
  File "C:\Users\JHMK-ZSS\PycharmProjects\pyrequests\venv\lib\site-packages\urllib3\util\retry.py", line 399, in increment
    raise MaxRetryError(_pool, url, error or ResponseError(cause))
urllib3.exceptions.MaxRetryError: HTTPConnectionPool(host='127.0.0.1', port=8000): Max retries exceeded with url: /api/get_guest_list/?eid=1&amp;phone=15945393949 (Caused by NewConnectionError('&lt;urllib3.connection.HTTPConnection object at 0x000001F0785B2710&gt;: Failed to establish a new connection: [WinError 10061] 由于目标计算机积极拒绝，无法连接。'))

During handling of the above exception, another exception occurred:

Traceback (most recent call last):
  File "C:\Users\JHMK-ZSS\PycharmProjects\pyrequests\interface\get_guest_list_test.py", line 50, in test_get_event_list_eid_phone_success
    r = requests.get(self.base_url, params={'eid':1,'phone':'15945393949'})
  File "C:\Users\JHMK-ZSS\PycharmProjects\pyrequests\venv\lib\site-packages\requests\api.py", line 75, in get
    return request('get', url, params=params, **kwargs)
  File "C:\Users\JHMK-ZSS\PycharmProjects\pyrequests\venv\lib\site-packages\requests\api.py", line 60, in request
    return session.request(method=method, url=url, **kwargs)
  File "C:\Users\JHMK-ZSS\PycharmProjects\pyrequests\venv\lib\site-packages\requests\sessions.py", line 533, in request
    resp = self.send(prep, **send_kwargs)
  File "C:\Users\JHMK-ZSS\PycharmProjects\pyrequests\venv\lib\site-packages\requests\sessions.py", line 646, in send
    r = adapter.send(request, **kwargs)
  File "C:\Users\JHMK-ZSS\PycharmProjects\pyrequests\venv\lib\site-packages\requests\adapters.py", line 516, in send
    raise ConnectionError(e, request=request)
requests.exceptions.ConnectionError: HTTPConnectionPool(host='127.0.0.1', port=8000): Max retries exceeded with url: /api/get_guest_list/?eid=1&amp;phone=15945393949 (Caused by NewConnectionError('&lt;urllib3.connection.HTTPConnection object at 0x000001F0785B2710&gt;: Failed to establish a new connection: [WinError 10061] 由于目标计算机积极拒绝，无法连接。'))


        </pre>
    </div>
    <!--css div popup end-->

    </td>
</tr>

<tr id='ft2.6' class='none'>
    <td class='errorCase'><div class='testcase'>test_get_event_list_eid_phone_success: 根据 eid 和phone 查询结果成功</div></td>
    <td colspan='5' align='center'>

    <!--css div popup start-->
    <a class="popup_link" onfocus='this.blur();' href="javascript:showTestDetail('div_ft2.6')" >
        error</a>

    <div id='div_ft2.6' class="popup_window">
        <div style='text-align: right; color:red;cursor:pointer'>
        <a onfocus='this.blur();' onclick="document.getElementById('div_ft2.6').style.display = 'none' " >
           [x]</a>
        </div>
        <pre>
        
ft2.6: Traceback (most recent call last):
  File "C:\Users\JHMK-ZSS\PycharmProjects\pyrequests\interface\get_guest_list_test.py", line 16, in tearDown
    print(self.result)
AttributeError: 'GetGuestListTest' object has no attribute 'result'


        </pre>
    </div>
    <!--css div popup end-->

    </td>
</tr>

<tr id='ft2.7' class='none'>
    <td class='errorCase'><div class='testcase'>test_get_event_list_eid_success: 根据 eid 查询结果成功</div></td>
    <td colspan='5' align='center'>

    <!--css div popup start-->
    <a class="popup_link" onfocus='this.blur();' href="javascript:showTestDetail('div_ft2.7')" >
        error</a>

    <div id='div_ft2.7' class="popup_window">
        <div style='text-align: right; color:red;cursor:pointer'>
        <a onfocus='this.blur();' onclick="document.getElementById('div_ft2.7').style.display = 'none' " >
           [x]</a>
        </div>
        <pre>
        
ft2.7: Traceback (most recent call last):
  File "C:\Users\JHMK-ZSS\PycharmProjects\pyrequests\venv\lib\site-packages\urllib3\connection.py", line 160, in _new_conn
    (self._dns_host, self.port), self.timeout, **extra_kw)
  File "C:\Users\JHMK-ZSS\PycharmProjects\pyrequests\venv\lib\site-packages\urllib3\util\connection.py", line 80, in create_connection
    raise err
  File "C:\Users\JHMK-ZSS\PycharmProjects\pyrequests\venv\lib\site-packages\urllib3\util\connection.py", line 70, in create_connection
    sock.connect(sa)
ConnectionRefusedError: [WinError 10061] 由于目标计算机积极拒绝，无法连接。

During handling of the above exception, another exception occurred:

Traceback (most recent call last):
  File "C:\Users\JHMK-ZSS\PycharmProjects\pyrequests\venv\lib\site-packages\urllib3\connectionpool.py", line 603, in urlopen
    chunked=chunked)
  File "C:\Users\JHMK-ZSS\PycharmProjects\pyrequests\venv\lib\site-packages\urllib3\connectionpool.py", line 355, in _make_request
    conn.request(method, url, **httplib_request_kw)
  File "C:\Users\JHMK-ZSS\AppData\Local\Programs\Python\Python37\lib\http\client.py", line 1229, in request
    self._send_request(method, url, body, headers, encode_chunked)
  File "C:\Users\JHMK-ZSS\AppData\Local\Programs\Python\Python37\lib\http\client.py", line 1275, in _send_request
    self.endheaders(body, encode_chunked=encode_chunked)
  File "C:\Users\JHMK-ZSS\AppData\Local\Programs\Python\Python37\lib\http\client.py", line 1224, in endheaders
    self._send_output(message_body, encode_chunked=encode_chunked)
  File "C:\Users\JHMK-ZSS\AppData\Local\Programs\Python\Python37\lib\http\client.py", line 1016, in _send_output
    self.send(msg)
  File "C:\Users\JHMK-ZSS\AppData\Local\Programs\Python\Python37\lib\http\client.py", line 956, in send
    self.connect()
  File "C:\Users\JHMK-ZSS\PycharmProjects\pyrequests\venv\lib\site-packages\urllib3\connection.py", line 183, in connect
    conn = self._new_conn()
  File "C:\Users\JHMK-ZSS\PycharmProjects\pyrequests\venv\lib\site-packages\urllib3\connection.py", line 169, in _new_conn
    self, "Failed to establish a new connection: %s" % e)
urllib3.exceptions.NewConnectionError: &lt;urllib3.connection.HTTPConnection object at 0x000001F0785B2F60&gt;: Failed to establish a new connection: [WinError 10061] 由于目标计算机积极拒绝，无法连接。

During handling of the above exception, another exception occurred:

Traceback (most recent call last):
  File "C:\Users\JHMK-ZSS\PycharmProjects\pyrequests\venv\lib\site-packages\requests\adapters.py", line 449, in send
    timeout=timeout
  File "C:\Users\JHMK-ZSS\PycharmProjects\pyrequests\venv\lib\site-packages\urllib3\connectionpool.py", line 641, in urlopen
    _stacktrace=sys.exc_info()[2])
  File "C:\Users\JHMK-ZSS\PycharmProjects\pyrequests\venv\lib\site-packages\urllib3\util\retry.py", line 399, in increment
    raise MaxRetryError(_pool, url, error or ResponseError(cause))
urllib3.exceptions.MaxRetryError: HTTPConnectionPool(host='127.0.0.1', port=8000): Max retries exceeded with url: /api/get_guest_list/?eid=1 (Caused by NewConnectionError('&lt;urllib3.connection.HTTPConnection object at 0x000001F0785B2F60&gt;: Failed to establish a new connection: [WinError 10061] 由于目标计算机积极拒绝，无法连接。'))

During handling of the above exception, another exception occurred:

Traceback (most recent call last):
  File "C:\Users\JHMK-ZSS\PycharmProjects\pyrequests\interface\get_guest_list_test.py", line 34, in test_get_event_list_eid_success
    r = requests.get(self.base_url, params={'eid':1})
  File "C:\Users\JHMK-ZSS\PycharmProjects\pyrequests\venv\lib\site-packages\requests\api.py", line 75, in get
    return request('get', url, params=params, **kwargs)
  File "C:\Users\JHMK-ZSS\PycharmProjects\pyrequests\venv\lib\site-packages\requests\api.py", line 60, in request
    return session.request(method=method, url=url, **kwargs)
  File "C:\Users\JHMK-ZSS\PycharmProjects\pyrequests\venv\lib\site-packages\requests\sessions.py", line 533, in request
    resp = self.send(prep, **send_kwargs)
  File "C:\Users\JHMK-ZSS\PycharmProjects\pyrequests\venv\lib\site-packages\requests\sessions.py", line 646, in send
    r = adapter.send(request, **kwargs)
  File "C:\Users\JHMK-ZSS\PycharmProjects\pyrequests\venv\lib\site-packages\requests\adapters.py", line 516, in send
    raise ConnectionError(e, request=request)
requests.exceptions.ConnectionError: HTTPConnectionPool(host='127.0.0.1', port=8000): Max retries exceeded with url: /api/get_guest_list/?eid=1 (Caused by NewConnectionError('&lt;urllib3.connection.HTTPConnection object at 0x000001F0785B2F60&gt;: Failed to establish a new connection: [WinError 10061] 由于目标计算机积极拒绝，无法连接。'))


        </pre>
    </div>
    <!--css div popup end-->

    </td>
</tr>

<tr id='ft2.8' class='none'>
    <td class='errorCase'><div class='testcase'>test_get_event_list_eid_success: 根据 eid 查询结果成功</div></td>
    <td colspan='5' align='center'>

    <!--css div popup start-->
    <a class="popup_link" onfocus='this.blur();' href="javascript:showTestDetail('div_ft2.8')" >
        error</a>

    <div id='div_ft2.8' class="popup_window">
        <div style='text-align: right; color:red;cursor:pointer'>
        <a onfocus='this.blur();' onclick="document.getElementById('div_ft2.8').style.display = 'none' " >
           [x]</a>
        </div>
        <pre>
        
ft2.8: Traceback (most recent call last):
  File "C:\Users\JHMK-ZSS\PycharmProjects\pyrequests\interface\get_guest_list_test.py", line 16, in tearDown
    print(self.result)
AttributeError: 'GetGuestListTest' object has no attribute 'result'


        </pre>
    </div>
    <!--css div popup end-->

    </td>
</tr>

<tr id='ft2.9' class='none'>
    <td class='errorCase'><div class='testcase'>test_get_guest_list_eid_null: eid 参数为空</div></td>
    <td colspan='5' align='center'>

    <!--css div popup start-->
    <a class="popup_link" onfocus='this.blur();' href="javascript:showTestDetail('div_ft2.9')" >
        error</a>

    <div id='div_ft2.9' class="popup_window">
        <div style='text-align: right; color:red;cursor:pointer'>
        <a onfocus='this.blur();' onclick="document.getElementById('div_ft2.9').style.display = 'none' " >
           [x]</a>
        </div>
        <pre>
        
ft2.9: Traceback (most recent call last):
  File "C:\Users\JHMK-ZSS\PycharmProjects\pyrequests\venv\lib\site-packages\urllib3\connection.py", line 160, in _new_conn
    (self._dns_host, self.port), self.timeout, **extra_kw)
  File "C:\Users\JHMK-ZSS\PycharmProjects\pyrequests\venv\lib\site-packages\urllib3\util\connection.py", line 80, in create_connection
    raise err
  File "C:\Users\JHMK-ZSS\PycharmProjects\pyrequests\venv\lib\site-packages\urllib3\util\connection.py", line 70, in create_connection
    sock.connect(sa)
ConnectionRefusedError: [WinError 10061] 由于目标计算机积极拒绝，无法连接。

During handling of the above exception, another exception occurred:

Traceback (most recent call last):
  File "C:\Users\JHMK-ZSS\PycharmProjects\pyrequests\venv\lib\site-packages\urllib3\connectionpool.py", line 603, in urlopen
    chunked=chunked)
  File "C:\Users\JHMK-ZSS\PycharmProjects\pyrequests\venv\lib\site-packages\urllib3\connectionpool.py", line 355, in _make_request
    conn.request(method, url, **httplib_request_kw)
  File "C:\Users\JHMK-ZSS\AppData\Local\Programs\Python\Python37\lib\http\client.py", line 1229, in request
    self._send_request(method, url, body, headers, encode_chunked)
  File "C:\Users\JHMK-ZSS\AppData\Local\Programs\Python\Python37\lib\http\client.py", line 1275, in _send_request
    self.endheaders(body, encode_chunked=encode_chunked)
  File "C:\Users\JHMK-ZSS\AppData\Local\Programs\Python\Python37\lib\http\client.py", line 1224, in endheaders
    self._send_output(message_body, encode_chunked=encode_chunked)
  File "C:\Users\JHMK-ZSS\AppData\Local\Programs\Python\Python37\lib\http\client.py", line 1016, in _send_output
    self.send(msg)
  File "C:\Users\JHMK-ZSS\AppData\Local\Programs\Python\Python37\lib\http\client.py", line 956, in send
    self.connect()
  File "C:\Users\JHMK-ZSS\PycharmProjects\pyrequests\venv\lib\site-packages\urllib3\connection.py", line 183, in connect
    conn = self._new_conn()
  File "C:\Users\JHMK-ZSS\PycharmProjects\pyrequests\venv\lib\site-packages\urllib3\connection.py", line 169, in _new_conn
    self, "Failed to establish a new connection: %s" % e)
urllib3.exceptions.NewConnectionError: &lt;urllib3.connection.HTTPConnection object at 0x000001F0785C26A0&gt;: Failed to establish a new connection: [WinError 10061] 由于目标计算机积极拒绝，无法连接。

During handling of the above exception, another exception occurred:

Traceback (most recent call last):
  File "C:\Users\JHMK-ZSS\PycharmProjects\pyrequests\venv\lib\site-packages\requests\adapters.py", line 449, in send
    timeout=timeout
  File "C:\Users\JHMK-ZSS\PycharmProjects\pyrequests\venv\lib\site-packages\urllib3\connectionpool.py", line 641, in urlopen
    _stacktrace=sys.exc_info()[2])
  File "C:\Users\JHMK-ZSS\PycharmProjects\pyrequests\venv\lib\site-packages\urllib3\util\retry.py", line 399, in increment
    raise MaxRetryError(_pool, url, error or ResponseError(cause))
urllib3.exceptions.MaxRetryError: HTTPConnectionPool(host='127.0.0.1', port=8000): Max retries exceeded with url: /api/get_guest_list/?eid= (Caused by NewConnectionError('&lt;urllib3.connection.HTTPConnection object at 0x000001F0785C26A0&gt;: Failed to establish a new connection: [WinError 10061] 由于目标计算机积极拒绝，无法连接。'))

During handling of the above exception, another exception occurred:

Traceback (most recent call last):
  File "C:\Users\JHMK-ZSS\PycharmProjects\pyrequests\interface\get_guest_list_test.py", line 20, in test_get_guest_list_eid_null
    r = requests.get(self.base_url, params={'eid':''})
  File "C:\Users\JHMK-ZSS\PycharmProjects\pyrequests\venv\lib\site-packages\requests\api.py", line 75, in get
    return request('get', url, params=params, **kwargs)
  File "C:\Users\JHMK-ZSS\PycharmProjects\pyrequests\venv\lib\site-packages\requests\api.py", line 60, in request
    return session.request(method=method, url=url, **kwargs)
  File "C:\Users\JHMK-ZSS\PycharmProjects\pyrequests\venv\lib\site-packages\requests\sessions.py", line 533, in request
    resp = self.send(prep, **send_kwargs)
  File "C:\Users\JHMK-ZSS\PycharmProjects\pyrequests\venv\lib\site-packages\requests\sessions.py", line 646, in send
    r = adapter.send(request, **kwargs)
  File "C:\Users\JHMK-ZSS\PycharmProjects\pyrequests\venv\lib\site-packages\requests\adapters.py", line 516, in send
    raise ConnectionError(e, request=request)
requests.exceptions.ConnectionError: HTTPConnectionPool(host='127.0.0.1', port=8000): Max retries exceeded with url: /api/get_guest_list/?eid= (Caused by NewConnectionError('&lt;urllib3.connection.HTTPConnection object at 0x000001F0785C26A0&gt;: Failed to establish a new connection: [WinError 10061] 由于目标计算机积极拒绝，无法连接。'))


        </pre>
    </div>
    <!--css div popup end-->

    </td>
</tr>

<tr id='ft2.10' class='none'>
    <td class='errorCase'><div class='testcase'>test_get_guest_list_eid_null: eid 参数为空</div></td>
    <td colspan='5' align='center'>

    <!--css div popup start-->
    <a class="popup_link" onfocus='this.blur();' href="javascript:showTestDetail('div_ft2.10')" >
        error</a>

    <div id='div_ft2.10' class="popup_window">
        <div style='text-align: right; color:red;cursor:pointer'>
        <a onfocus='this.blur();' onclick="document.getElementById('div_ft2.10').style.display = 'none' " >
           [x]</a>
        </div>
        <pre>
        
ft2.10: Traceback (most recent call last):
  File "C:\Users\JHMK-ZSS\PycharmProjects\pyrequests\interface\get_guest_list_test.py", line 16, in tearDown
    print(self.result)
AttributeError: 'GetGuestListTest' object has no attribute 'result'


        </pre>
    </div>
    <!--css div popup end-->

    </td>
</tr>

<tr class='passClass'>
    <td>get_hot_list_test.GetHotList</td>
    <td>1</td>
    <td>1</td>
    <td>0</td>
    <td>0</td>
    <td><a href="javascript:showClassDetail('c3',1)">Detail</a></td>
</tr>

<tr id='pt3.1' class='hiddenRow'>
    <td class='none'><div class='testcase'>test_get_hot_list_success</div></td>
    <td colspan='5' align='center'>

    <!--css div popup start-->
    <a class="popup_link" onfocus='this.blur();' href="javascript:showTestDetail('div_pt3.1')" >
        pass</a>

    <div id='div_pt3.1' class="popup_window">
        <div style='text-align: right; color:red;cursor:pointer'>
        <a onfocus='this.blur();' onclick="document.getElementById('div_pt3.1').style.display = 'none' " >
           [x]</a>
        </div>
        <pre>
        
pt3.1: {'code': 200, 'msg': '成功!', 'data': [{'type': 'video', 'text': '小两口要都是这样，这一天天的日子得多开心啊！', 'username': '龘靐龗齾齉爩虌麷灩韊 [一堆字]', 'uid': '13943553', 'header': 'http://wimg.spriteapp.cn/profile/large/2016/10/07/57f7b339ed872_mini.jpg', 'comment': 38, 'top_commentsVoiceuri': None, 'top_commentsContent': '内容引起强烈不适  已举报', 'top_commentsHeader': 'http://thirdwx.qlogo.cn/mmopen/vi_32/Q0j4TwGTfTIv3gkJ4uclR9iaKZjkibibXwnQLcq5P8ibKEfPEURicicPR4qFYr6icrlv3Y126fQSIXlSI4ia6AOhRNVn5g/132', 'top_commentsName': '狗贼i', 'passtime': '2018-05-09\xa001:41:02', 'soureid': 27860496, 'up': 216, 'down': 14, 'forward': 17, 'image': None, 'gif': None, 'thumbnail': 'http://wimg.spriteapp.cn/picture/2018/0507/80208e44-5205-11e8-bcf1-1866daeb0df1_wpd_67.jpg', 'video': 'http://wvideo.spriteapp.cn/video/2018/0507/80208e44-5205-11e8-bcf1-1866daeb0df1_wpd.mp4'}, {'type': 'video', 'text': '这三句话，花多少钱也买不到！送给你了~', 'username': '我是陈苗 [百思ta妹]', 'uid': '17545511', 'header': 'http://wimg.spriteapp.cn/profile/large/2017/08/28/59a3fe4c5e358_mini.jpg', 'comment': 134, 'top_commentsVoiceuri': None, 'top_commentsContent': '说的都简单！能做到的！要么没出息！要么快挂了！', 'top_commentsHeader': 'http://wimg.spriteapp.cn/profile/large/2018/04/15/5ad32c822725e_mini.jpg', 'top_commentsName': '哒哒哒哒高', 'passtime': '2018-04-27\xa012:13:01', 'soureid': 27754697, 'up': 528, 'down': 51, 'forward': 110, 'image': None, 'gif': None, 'thumbnail': 'http://wimg.spriteapp.cn/picture/2018/0427/a89fceec-49a5-11e8-b975-1866daeb0df1_wpd.jpg', 'video': 'http://wvideo.spriteapp.cn/video/2018/0427/a89fceec-49a5-11e8-b975-1866daeb0df1_wpd.mp4'}, {'type': 'video', 'text': '老夫的少女心！指甲上的艺术，有一丢丢可以理解姑娘们为啥都喜欢美甲了', 'username': '83年的雪碧 [艾特子见]', 'uid': '18136453', 'header': 'http://wimg.spriteapp.cn/profile/large/2018/04/28/5ae496eb1ea97_mini.jpg', 'comment': 27, 'top_commentsVoiceuri': None, 'top_commentsContent': '老夫明天一定要去涂个脚', 'top_commentsHeader': 'http://wimg.spriteapp.cn/profile/large/2018/04/20/5ad922dbe7606_mini.jpg', 'top_commentsName': '夜夜飘', 'passtime': '2018-05-08\xa001:42:01', 'soureid': 27858831, 'up': 103, 'down': 10, 'forward': 9, 'image': None, 'gif': None, 'thumbnail': 'http://wimg.spriteapp.cn/picture/2018/0507/5af0461838903__b.jpg', 'video': 'http://wvideo.spriteapp.cn/video/2018/0507/5af0461850869_wpd.mp4'}, {'type': 'video', 'text': '姑娘，穿成这样出来吓人不太好吧！！', 'username': 'Mr13th', 'uid': '22652304', 'header': 'http://wimg.spriteapp.cn/profile/large/2018/09/08/5b93f19230bc9_mini.jpg', 'comment': 314, 'top_commentsVoiceuri': None, 'top_commentsContent': '僵尸里胸最大的', 'top_commentsHeader': 'http://wimg.spriteapp.cn/profile/large/2017/02/17/58a70d6895104_mini.jpg', 'top_commentsName': '弖乊乕帍', 'passtime': '2018-06-13\xa006:11:01', 'soureid': 28112782, 'up': 823, 'down': 63, 'forward': 37, 'image': None, 'gif': None, 'thumbnail': 'http://wimg.spriteapp.cn/picture/2018/0611/44cac1e66d5a11e8ad1f842b2b4c75ab_wpd.jpg', 'video': 'http://tvideo.spriteapp.cn/video/2018/0611/44cac1e66d5a11e8ad1f842b2b4c75ab_wpd.mp4'}, {'type': 'video', 'text': '请珍惜，愿意和你一起吃苦的女人！', 'username': '相思明月楼 [百思跳跳鱼]', 'uid': '10675617', 'header': 'http://wimg.spriteapp.cn/profile/large/2017/07/21/59721d2d246c4_mini.jpg', 'comment': 247, 'top_commentsVoiceuri': None, 'top_commentsContent': None, 'top_commentsHeader': None, 'top_commentsName': None, 'passtime': '2017-10-03\xa017:04:02', 'soureid': 26498879, 'up': 2329, 'down': 125, 'forward': 400, 'image': None, 'gif': None, 'thumbnail': 'http://wimg.spriteapp.cn/picture/2017/1002/2b2041dc-a783-11e7-bbdf-1866daeb0df1_wpd_31.jpg', 'video': 'http://wvideo.spriteapp.cn/video/2017/1002/2b2041dc-a783-11e7-bbdf-1866daeb0df1_wpd.mp4'}, {'type': 'video', 'text': '喵星人：铲屎的可能是个智障，能不能让我消停一会？？？', 'username': '虎猫侠', 'uid': '15694513', 'header': 'http://wimg.spriteapp.cn/profile/large/2015/08/25/55dc2674abcae_mini.jpg', 'comment': 136, 'top_commentsVoiceuri': None, 'top_commentsContent': '这是哪只跳海草走红的猫咪吗？', 'top_commentsHeader': 'http://wimg.spriteapp.cn/profile/large/2018/04/18/5ad61dfc24ec1_mini.jpg', 'top_commentsName': '段仔哥', 'passtime': '2018-04-21\xa021:56:02', 'soureid': 27674880, 'up': 531, 'down': 30, 'forward': 57, 'image': None, 'gif': None, 'thumbnail': 'http://wimg.spriteapp.cn/picture/2018/0421/27674880_259.jpg', 'video': 'http://wvideo.spriteapp.cn/video/2018/0421/5adb03f0111b9_wpd.mp4'}, {'type': 'video', 'text': '女儿五天没有见到爸爸，一觉醒来看到爸爸的第一反应，暖爆了', 'username': '小堃弟弟 [红颜几度扰梦]', 'uid': '16978385', 'header': 'http://wimg.spriteapp.cn/profile/large/2017/11/13/5a09a9597c56b_mini.jpg', 'comment': 237, 'top_commentsVoiceuri': None, 'top_commentsContent': '半年没见到你了……孩子！为了家为了赚钱', 'top_commentsHeader': 'http://wimg.spriteapp.cn/profile/large/2015/06/12/557af90cd1292_mini.jpg', 'top_commentsName': '我是你夏天的风', 'passtime': '2017-10-04\xa004:55:02', 'soureid': 26493034, 'up': 3064, 'down': 82, 'forward': 332, 'image': None, 'gif': None, 'thumbnail': 'http://wimg.spriteapp.cn/picture/2017/1002/26493034_283.jpg', 'video': 'http://wvideo.spriteapp.cn/video/2017/1002/59d1939282459_wpd.mp4'}, {'type': 'video', 'text': '你们说说看，这个牌照怎么办', 'username': '日日曰日 [日日日日]', 'uid': '18895364', 'header': 'http://wimg.spriteapp.cn/profile/large/2017/07/17/596c4c7c2079f_mini.jpg', 'comment': 416, 'top_commentsVoiceuri': None, 'top_commentsContent': '自己选的怨谁？自己250', 'top_commentsHeader': 'http://wimg.spriteapp.cn/profile', 'top_commentsName': '影无双0', 'passtime': '2017-10-12\xa009:57:01', 'soureid': 26550591, 'up': 1668, 'down': 52, 'forward': 238, 'image': None, 'gif': None, 'thumbnail': 'http://wimg.spriteapp.cn/picture/2017/1009/8ded0f54-ace5-11e7-bbdf-1866daeb0df1_wpd.jpg', 'video': 'http://wvideo.spriteapp.cn/video/2017/1009/8ded0f54-ace5-11e7-bbdf-1866daeb0df1_wpd.mp4'}, {'type': 'video', 'text': '夏日男士发型参考！头可断，发型不能乱……', 'username': '日曰日日 [日日日日]', 'uid': '21393596', 'header': 'http://wimg.spriteapp.cn/profile/large/2018/01/13/5a5a0f74c0e14_mini.jpg', 'comment': 124, 'top_commentsVoiceuri': None, 'top_commentsContent': '那个，，，有没有正处级得发型推荐。。。。我替朋友问的！', 'top_commentsHeader': 'http://wimg.spriteapp.cn/profile/large/2018/02/28/5a96c6e26123d_mini.jpg', 'top_commentsName': '阿星5Qs', 'passtime': '2018-05-05\xa011:47:01', 'soureid': 27832508, 'up': 388, 'down': 17, 'forward': 92, 'image': None, 'gif': None, 'thumbnail': 'http://wimg.spriteapp.cn/picture/2018/0504/90229eb4-4fa2-11e8-aab0-1866daeb0df1cutblack_wpd.jpg', 'video': 'http://wvideo.spriteapp.cn/video/2018/0504/90229eb4-4fa2-11e8-aab0-1866daeb0df1cutblack_wpd.mp4'}, {'type': 'gif', 'text': '大师不愧是大师，原谅我不懂艺术', 'username': '镜子里的自己', 'uid': '20143668', 'header': 'http://wx.qlogo.cn/mmopen/qUVQ3tXv99yLicTjxZicdGD4kcHI7HhcmZwvib6hVwjc7ZxficoOQot5VY2z7hkcvdgiae349txicn8vNc6f9DozsQzwwziboQCflAR/0', 'comment': 126, 'top_commentsVoiceuri': None, 'top_commentsContent': '', 'top_commentsHeader': 'http://wimg.spriteapp.cn/profile/large/2018/02/23/5a902e31f3a71_mini.jpg', 'top_commentsName': '花子丶', 'passtime': '2018-05-06\xa018:44:02', 'soureid': 27827949, 'up': 199, 'down': 38, 'forward': 7, 'image': None, 'gif': 'http://wimg.spriteapp.cn/ugc/2018/05/04/5aebe37676b66.gif', 'thumbnail': 'http://wimg.spriteapp.cn/ugc/2018/05/04/5aebe37676b66_a_1.jpg', 'video': None}, {'type': 'video', 'text': '好人一生平安，世界还是很美好的', 'username': '阿强马强赛马强 [OMEGA帮派]', 'uid': '19634336', 'header': 'http://wimg.spriteapp.cn/profile/large/2018/01/16/5a5dce3778d6a_mini.jpg', 'comment': 334, 'top_commentsVoiceuri': None, 'top_commentsContent': '家里大人下来是不是应该磕个头？', 'top_commentsHeader': 'http://wimg.spriteapp.cn/profile/large/2016/02/22/56ca616a1f606_mini.jpg', 'top_commentsName': '尛宇', 'passtime': '2018-02-16\xa009:00:01', 'soureid': 27236505, 'up': 5277, 'down': 49, 'forward': 124, 'image': None, 'gif': None, 'thumbnail': 'http://wimg.spriteapp.cn/picture/2018/0214/5a84216a34992__b.jpg', 'video': 'http://wvideo.spriteapp.cn/video/2018/0214/5a84216a53b5c_wpd.mp4'}, {'type': 'video', 'text': '世界上速度最快的五辆摩托车，光是听这声音都感觉要上天了', 'username': '83年的雪碧 [艾特子见]', 'uid': '18136453', 'header': 'http://wimg.spriteapp.cn/profile/large/2018/04/28/5ae496eb1ea97_mini.jpg', 'comment': 392, 'top_commentsVoiceuri': None, 'top_commentsContent': '我靠，400了，加两个翅膀估计就可以上天堂了', 'top_commentsHeader': 'http://qzapp.qlogo.cn/qzapp/100336987/CFC61E4B74B8233C05BC68B518B1E056/100', 'top_commentsName': '失传已久的侠', 'passtime': '2018-06-25\xa021:50:02', 'soureid': 28196638, 'up': 1006, 'down': 38, 'forward': 123, 'image': None, 'gif': None, 'thumbnail': 'http://wimg.spriteapp.cn/picture/2018/0625/5b30ba3a1b028__b.jpg', 'video': 'http://wvideo.spriteapp.cn/video/2018/0625/5b30ba3a4e1e5_wpd.mp4'}, {'type': 'video', 'text': '15个正确的拍照姿势，教你五一出游轻松拍出最心动的那个她！', 'username': '孤枫逸天', 'uid': '20746668', 'header': 'http://wimg.spriteapp.cn/profile/20170512111714.jpg', 'comment': 188, 'top_commentsVoiceuri': None, 'top_commentsContent': '人好看怎么拍都好看', 'top_commentsHeader': 'http://wx.qlogo.cn/mmopen/vi_32/VGYhtNng7sajWoh07GHutOicETKCdDz9KZObYKtXJib3iah81v2iaMYTiamu9kz5e7Qegel8j4AZkKvw3cPaIdwWkdQ/0', 'top_commentsName': '嘛哩嘛哩轰3pO', 'passtime': '2018-04-28\xa017:58:02', 'soureid': 27768247, 'up': 636, 'down': 38, 'forward': 132, 'image': None, 'gif': None, 'thumbnail': 'http://wimg.spriteapp.cn/picture/2018/0428/27768247_185.jpg', 'video': 'http://wvideo.spriteapp.cn/video/2018/0428/3adae0c04a8d11e8993b842b2b4c75ab_wpd.mp4'}, {'type': 'image', 'text': '你身边发生过怎样的赤裸裸暴露人性的事情？还是要相信人性的光辉 \u200b\u200b\u200b\u200b', 'username': '斜眼看你笑', 'uid': '20746603', 'header': 'http://wimg.spriteapp.cn/profile/20170512104036.jpg', 'comment': 222, 'top_commentsVoiceuri': None, 'top_commentsContent': '眼酸了，啊，不对，鼻子酸了', 'top_commentsHeader': 'http://wx.qlogo.cn/mmopen/2EzJggZltBMKQovGd4IuGRoazZv7fUTde2icb717p4P5lX8tLzuicn058VkPibBzUV4t2qEHfM6cRgTeXnkTMMIGhK4rvfbvicOZ/0', 'top_commentsName': '浅秋hMe', 'passtime': '2018-01-19\xa019:38:01', 'soureid': 27145055, 'up': 2560, 'down': 80, 'forward': 111, 'image': 'http://wimg.spriteapp.cn/ugc/2018/01/19/09bcd1befcc811e7b6b8842b2b4c75ab_1.jpg', 'gif': None, 'thumbnail': 'http://wimg.spriteapp.cn/ugc/2018/01/19/09bcd1befcc811e7b6b8842b2b4c75ab_1.jpg', 'video': None}, {'type': 'video', 'text': '恶农咆哮，好多可爱的小姐姐啊！你喜欢哪一个？', 'username': '全网美女', 'uid': '20746674', 'header': 'http://wimg.spriteapp.cn/profile/20180709110441140936.png', 'comment': 476, 'top_commentsVoiceuri': None, 'top_commentsContent': '难道这我想给她一巴掌？', 'top_commentsHeader': 'http://wimg.spriteapp.cn/profile/large/2017/12/04/5a2461f7bfae6_mini.jpg', 'top_commentsName': '不得姐用户', 'passtime': '2018-08-11\xa007:58:02', 'soureid': 28461719, 'up': 648, 'down': 437, 'forward': 48, 'image': None, 'gif': None, 'thumbnail': 'http://wimg.spriteapp.cn/picture/2018/0809/bd1f6e769bc211e8bafe842b2b4c75ab_wpd.jpg', 'video': 'http://tvideo.spriteapp.cn/video/2018/0809/bd1f6e769bc211e8bafe842b2b4c75ab_wpd.mp4'}, {'type': 'image', 'text': '六耳猕猴为何与孙悟空难辨真假，这其中有着一个令人潸然泪下的故事...', 'username': '漫步风声间', 'uid': '20746588', 'header': 'http://wimg.spriteapp.cn/profile/20170512103141.jpg', 'comment': 182, 'top_commentsVoiceuri': None, 'top_commentsContent': '陈乔恩都看不过去了，', 'top_commentsHeader': 'http://qzapp.qlogo.cn/qzapp/100336987/DBB0E523C07C8775282DAE3E5588C59A/100', 'top_commentsName': '吾乃石家庄赵子龙', 'passtime': '2018-04-30\xa012:46:03', 'soureid': 27772704, 'up': 600, 'down': 74, 'forward': 38, 'image': 'http://wimg.spriteapp.cn/ugc/2018/04/28/8d8e46764aca11e8b14a842b2b4c75ab_1.jpg', 'gif': None, 'thumbnail': 'http://wimg.spriteapp.cn/ugc/2018/04/28/8d8e46764aca11e8b14a842b2b4c75ab_1.jpg', 'video': None}, {'type': 'image', 'text': '不得不佩服马云啊！一个人把学校撑到前三。', 'username': '喒你家玻璃 [砸你家玻璃]', 'uid': '18809558', 'header': 'http://wimg.spriteapp.cn/profile/large/2016/09/29/57ec70bf1adcb_mini.jpg', 'comment': 73, 'top_commentsVoiceuri': None, 'top_commentsContent': None, 'top_commentsHeader': None, 'top_commentsName': None, 'passtime': '2018-05-08\xa008:00:01', 'soureid': 27845907, 'up': 263, 'down': 38, 'forward': 10, 'image': 'http://wimg.spriteapp.cn/ugc/2018/05/06/5aee8956903e6_1.jpg', 'gif': None, 'thumbnail': 'http://wimg.spriteapp.cn/ugc/2018/05/06/5aee8956903e6_1.jpg', 'video': None}, {'type': 'video', 'text': '98K合集来啦！喜欢么？', 'username': '不交作业别想睡了 [老司机休息室]', 'uid': '17932228', 'header': 'http://wimg.spriteapp.cn/profile/large/2017/11/02/59fada75627d6_mini.jpg', 'comment': 116, 'top_commentsVoiceuri': None, 'top_commentsContent': '好看的皮囊三千一晚\n有趣的灵魂要车要房', 'top_commentsHeader': 'http://wimg.spriteapp.cn/profile/large/2018/04/25/5ae07b4e50a79_mini.jpg', 'top_commentsName': '简浅inD', 'passtime': '2018-04-25\xa023:27:01', 'soureid': 27726292, 'up': 253, 'down': 37, 'forward': 6, 'image': None, 'gif': None, 'thumbnail': 'http://wimg.spriteapp.cn/picture/2018/0425/5adf58ba1ee9d_wpd.jpg', 'video': 'http://wvideo.spriteapp.cn/video/2018/0425/5adf58ba1ee9d_wpd.mp4'}, {'type': 'image', 'text': '据说算对的人不足1%。你算出来了吗？', 'username': '为你改变love [为姐改变]', 'uid': '18996959', 'header': 'http://wimg.spriteapp.cn/profile/large/2016/11/15/582b24d33dd0b_mini.jpg', 'comment': 828, 'top_commentsVoiceuri': None, 'top_commentsContent': '10+3×2＝16  刚才忘记看猫脖子上的哨子了', 'top_commentsHeader': 'http://wimg.spriteapp.cn/profile/large/2017/10/19/59e826a4481d2_mini.jpg', 'top_commentsName': '大郎_快_别停_欧耶', 'passtime': '2017-11-24\xa000:48:01', 'soureid': 26880408, 'up': 862, 'down': 236, 'forward': 109, 'image': 'http://wimg.spriteapp.cn/ugc/2017/11/23/5a16530be2ea1_1.jpg', 'gif': None, 'thumbnail': 'http://wimg.spriteapp.cn/ugc/2017/11/23/5a16530be2ea1_1.jpg', 'video': None}, {'type': 'image', 'text': '刚洗澡尬舞结果脚滑了，一不小心大脚趾头踩下水道里了，艹！塞住拔不出来了，很难受！水都下不去了，咋整啊卧槽？姐夫们有啥办法吗？朋友等我出去嗨呢！！！ \u200b', 'username': '蛮夷阿涂 [蛮夷阿涂]', 'uid': '19837434', 'header': 'http://wimg.spriteapp.cn/profile/large/2017/03/10/58c2180891031_mini.jpg', 'comment': 336, 'top_commentsVoiceuri': None, 'top_commentsContent': '抽插，不停的抽插都下水道高潮了就能拔出来了', 'top_commentsHeader': 'http://wimg.spriteapp.cn/profile/large/2015/02/26/54ee92219ac19_mini.jpg', 'top_commentsName': '家里有个小美女', 'passtime': '2017-12-25\xa011:04:01', 'soureid': 27041512, 'up': 992, 'down': 70, 'forward': 73, 'image': 'http://wimg.spriteapp.cn/ugc/2017/12/25/5a4053fb70396_1.jpg', 'gif': None, 'thumbnail': 'http://wimg.spriteapp.cn/ugc/2017/12/25/5a4053fb70396_1.jpg', 'video': None}]}


        </pre>
    </div>
    <!--css div popup end-->

    </td>
</tr>

<tr class='failClass'>
    <td>get_kuaidi_test.Kuaiditest</td>
    <td>4</td>
    <td>3</td>
    <td>1</td>
    <td>0</td>
    <td><a href="javascript:showClassDetail('c4',4)">Detail</a></td>
</tr>

<tr id='pt4.1' class='hiddenRow'>
    <td class='none'><div class='testcase'>test_kuaidi_postid_error: 快递单号不存在</div></td>
    <td colspan='5' align='center'>

    <!--css div popup start-->
    <a class="popup_link" onfocus='this.blur();' href="javascript:showTestDetail('div_pt4.1')" >
        pass</a>

    <div id='div_pt4.1' class="popup_window">
        <div style='text-align: right; color:red;cursor:pointer'>
        <a onfocus='this.blur();' onclick="document.getElementById('div_pt4.1').style.display = 'none' " >
           [x]</a>
        </div>
        <pre>
        
pt4.1: {'message': 'ok', 'nu': '111000000000000000', 'ischeck': '1', 'com': 'yuantong', 'status': '200', 'condition': 'F00', 'state': '3', 'data': [{'time': '2019-06-15', 'context': '查无结果', 'ftime': '2019-06-15'}]}


        </pre>
    </div>
    <!--css div popup end-->

    </td>
</tr>

<tr id='pt4.2' class='hiddenRow'>
    <td class='none'><div class='testcase'>test_kuaidi_postid_null: 快递单号为空</div></td>
    <td colspan='5' align='center'>

    <!--css div popup start-->
    <a class="popup_link" onfocus='this.blur();' href="javascript:showTestDetail('div_pt4.2')" >
        pass</a>

    <div id='div_pt4.2' class="popup_window">
        <div style='text-align: right; color:red;cursor:pointer'>
        <a onfocus='this.blur();' onclick="document.getElementById('div_pt4.2').style.display = 'none' " >
           [x]</a>
        </div>
        <pre>
        
pt4.2: {'message': '参数错误', 'nu': '', 'ischeck': '0', 'condition': '', 'com': '', 'status': '400', 'state': '0', 'data': []}


        </pre>
    </div>
    <!--css div popup end-->

    </td>
</tr>

<tr id='ft4.3' class='none'>
    <td class='failCase'><div class='testcase'>test_kuaidi_success: 查询成功</div></td>
    <td colspan='5' align='center'>

    <!--css div popup start-->
    <a class="popup_link" onfocus='this.blur();' href="javascript:showTestDetail('div_ft4.3')" >
        fail</a>

    <div id='div_ft4.3' class="popup_window">
        <div style='text-align: right; color:red;cursor:pointer'>
        <a onfocus='this.blur();' onclick="document.getElementById('div_ft4.3').style.display = 'none' " >
           [x]</a>
        </div>
        <pre>
        
ft4.3: {'message': '参数错误', 'nu': '', 'ischeck': '0', 'condition': '', 'com': '', 'status': '400', 'state': '0', 'data': []}
Traceback (most recent call last):
  File "C:\Users\JHMK-ZSS\PycharmProjects\pyrequests\interface\get_kuaidi_test.py", line 36, in test_kuaidi_success
    self.assertEqual(self.result['status'],'200')
AssertionError: '400' != '200'
- 400
? ^
+ 200
? ^



        </pre>
    </div>
    <!--css div popup end-->

    </td>
</tr>

<tr id='pt4.4' class='hiddenRow'>
    <td class='none'><div class='testcase'>test_kuaidi_type_null: 快递公司为空</div></td>
    <td colspan='5' align='center'>

    <!--css div popup start-->
    <a class="popup_link" onfocus='this.blur();' href="javascript:showTestDetail('div_pt4.4')" >
        pass</a>

    <div id='div_pt4.4' class="popup_window">
        <div style='text-align: right; color:red;cursor:pointer'>
        <a onfocus='this.blur();' onclick="document.getElementById('div_pt4.4').style.display = 'none' " >
           [x]</a>
        </div>
        <pre>
        
pt4.4: {'message': '参数错误', 'nu': '', 'ischeck': '0', 'condition': '', 'com': '', 'status': '400', 'state': '0', 'data': []}


        </pre>
    </div>
    <!--css div popup end-->

    </td>
</tr>

<tr class='errorClass'>
    <td>get_place_api_test.Placeapi: 地点提示API</td>
    <td>4</td>
    <td>1</td>
    <td>0</td>
    <td>3</td>
    <td><a href="javascript:showClassDetail('c5',4)">Detail</a></td>
</tr>

<tr id='ft5.1' class='none'>
    <td class='errorCase'><div class='testcase'>test_place_api_ak_error: ak错误</div></td>
    <td colspan='5' align='center'>

    <!--css div popup start-->
    <a class="popup_link" onfocus='this.blur();' href="javascript:showTestDetail('div_ft5.1')" >
        error</a>

    <div id='div_ft5.1' class="popup_window">
        <div style='text-align: right; color:red;cursor:pointer'>
        <a onfocus='this.blur();' onclick="document.getElementById('div_ft5.1').style.display = 'none' " >
           [x]</a>
        </div>
        <pre>
        
ft5.1: {'status': 200, 'message': 'APP不存在，AK有误请检查再重试'}
Traceback (most recent call last):
  File "C:\Users\JHMK-ZSS\PycharmProjects\pyrequests\interface\get_place_api_test.py", line 30, in test_place_api_ak_error
    self.assertEqual(self.result['status',200])
KeyError: ('status', 200)


        </pre>
    </div>
    <!--css div popup end-->

    </td>
</tr>

<tr id='pt5.2' class='hiddenRow'>
    <td class='none'><div class='testcase'>test_place_api_ak_null: ak为空</div></td>
    <td colspan='5' align='center'>

    <!--css div popup start-->
    <a class="popup_link" onfocus='this.blur();' href="javascript:showTestDetail('div_pt5.2')" >
        pass</a>

    <div id='div_pt5.2' class="popup_window">
        <div style='text-align: right; color:red;cursor:pointer'>
        <a onfocus='this.blur();' onclick="document.getElementById('div_pt5.2').style.display = 'none' " >
           [x]</a>
        </div>
        <pre>
        
pt5.2: {'status': 101, 'message': 'AK参数不存在'}


        </pre>
    </div>
    <!--css div popup end-->

    </td>
</tr>

<tr id='ft5.3' class='none'>
    <td class='errorCase'><div class='testcase'>test_place_api_success: 查询成功</div></td>
    <td colspan='5' align='center'>

    <!--css div popup start-->
    <a class="popup_link" onfocus='this.blur();' href="javascript:showTestDetail('div_ft5.3')" >
        error</a>

    <div id='div_ft5.3' class="popup_window">
        <div style='text-align: right; color:red;cursor:pointer'>
        <a onfocus='this.blur();' onclick="document.getElementById('div_ft5.3').style.display = 'none' " >
           [x]</a>
        </div>
        <pre>
        
ft5.3: Traceback (most recent call last):
  File "C:\Users\JHMK-ZSS\PycharmProjects\pyrequests\interface\get_place_api_test.py", line 14, in test_place_api_success
    self.result = r.json()
  File "C:\Users\JHMK-ZSS\PycharmProjects\pyrequests\venv\lib\site-packages\requests\models.py", line 897, in json
    return complexjson.loads(self.text, **kwargs)
  File "C:\Users\JHMK-ZSS\AppData\Local\Programs\Python\Python37\lib\json\__init__.py", line 348, in loads
    return _default_decoder.decode(s)
  File "C:\Users\JHMK-ZSS\AppData\Local\Programs\Python\Python37\lib\json\decoder.py", line 337, in decode
    obj, end = self.raw_decode(s, idx=_w(s, 0).end())
  File "C:\Users\JHMK-ZSS\AppData\Local\Programs\Python\Python37\lib\json\decoder.py", line 355, in raw_decode
    raise JSONDecodeError("Expecting value", s, err.value) from None
json.decoder.JSONDecodeError: Expecting value: line 1 column 1 (char 0)


        </pre>
    </div>
    <!--css div popup end-->

    </td>
</tr>

<tr id='ft5.4' class='none'>
    <td class='errorCase'><div class='testcase'>test_place_api_success: 查询成功</div></td>
    <td colspan='5' align='center'>

    <!--css div popup start-->
    <a class="popup_link" onfocus='this.blur();' href="javascript:showTestDetail('div_ft5.4')" >
        error</a>

    <div id='div_ft5.4' class="popup_window">
        <div style='text-align: right; color:red;cursor:pointer'>
        <a onfocus='this.blur();' onclick="document.getElementById('div_ft5.4').style.display = 'none' " >
           [x]</a>
        </div>
        <pre>
        
ft5.4: Traceback (most recent call last):
  File "C:\Users\JHMK-ZSS\PycharmProjects\pyrequests\interface\get_place_api_test.py", line 9, in tearDown
    print(self.result)
AttributeError: 'Placeapi' object has no attribute 'result'


        </pre>
    </div>
    <!--css div popup end-->

    </td>
</tr>

<tr id='total_row'>
    <td>Total</td>
    <td>27</td>
    <td>5</td>
    <td>1</td>
    <td>21</td>
    <td>&nbsp;</td>
</tr>
</table>

<div id='ending'>&nbsp;</div>

</body>
</html>
