<?xml version="1.0" encoding="UTF-8"?>
<!DOCTYPE html PUBLIC "-//W3C//DTD XHTML 1.0 Strict//EN" "http://www.w3.org/TR/xhtml1/DTD/xhtml1-strict.dtd">
<html xmlns="http://www.w3.org/1999/xhtml">
<head>
    <title>123</title>
    <meta name="generator" content="HTMLTestRunner 0.8.2"/>
    <meta http-equiv="Content-Type" content="text/html; charset=UTF-8"/>
    
<style type="text/css" media="screen">
body        { font-family: verdana, arial, helvetica, sans-serif; font-size: 80%; }
table       { font-size: 100%; }
pre         { }

/* -- heading ---------------------------------------------------------------------- */
h1 {
	font-size: 16pt;
	color: gray;
}
.heading {
    margin-top: 0ex;
    margin-bottom: 1ex;
}

.heading .attribute {
    margin-top: 1ex;
    margin-bottom: 0;
}

.heading .description {
    margin-top: 4ex;
    margin-bottom: 6ex;
}

/* -- css div popup ------------------------------------------------------------------------ */
a.popup_link {
}

a.popup_link:hover {
    color: red;
}

.popup_window {
    display: none;
    position: relative;
    left: 0px;
    top: 0px;
    /*border: solid #627173 1px; */
    padding: 10px;
    background-color: #E6E6D6;
    font-family: "Lucida Console", "Courier New", Courier, monospace;
    text-align: left;
    font-size: 8pt;
    width: 500px;
}

}
/* -- report ------------------------------------------------------------------------ */
#show_detail_line {
    margin-top: 3ex;
    margin-bottom: 1ex;
}
#result_table {
    width: 80%;
    border-collapse: collapse;
    border: 1px solid #777;
}
#header_row {
    font-weight: bold;
    color: white;
    background-color: #777;
}
#result_table td {
    border: 1px solid #777;
    padding: 2px;
}
#total_row  { font-weight: bold; }
.passClass  { background-color: #6c6; }
.failClass  { background-color: #c60; }
.errorClass { background-color: #c00; }
.passCase   { color: #6c6; }
.failCase   { color: #c60; font-weight: bold; }
.errorCase  { color: #c00; font-weight: bold; }
.hiddenRow  { display: none; }
.testcase   { margin-left: 2em; }


/* -- ending ---------------------------------------------------------------------- */
#ending {
}

</style>

</head>
<body>
<script language="javascript" type="text/javascript"><!--
output_list = Array();

/* level - 0:Summary; 1:Failed; 2:All */
function showCase(level) {
    trs = document.getElementsByTagName("tr");
    for (var i = 0; i < trs.length; i++) {
        tr = trs[i];
        id = tr.id;
        if (id.substr(0,2) == 'ft') {
            if (level < 1) {
                tr.className = 'hiddenRow';
            }
            else {
                tr.className = '';
            }
        }
        if (id.substr(0,2) == 'pt') {
            if (level > 1) {
                tr.className = '';
            }
            else {
                tr.className = 'hiddenRow';
            }
        }
    }
}


function showClassDetail(cid, count) {
    var id_list = Array(count);
    var toHide = 1;
    for (var i = 0; i < count; i++) {
        tid0 = 't' + cid.substr(1) + '.' + (i+1);
        tid = 'f' + tid0;
        tr = document.getElementById(tid);
        if (!tr) {
            tid = 'p' + tid0;
            tr = document.getElementById(tid);
        }
        id_list[i] = tid;
        if (tr.className) {
            toHide = 0;
        }
    }
    for (var i = 0; i < count; i++) {
        tid = id_list[i];
        if (toHide) {
            document.getElementById('div_'+tid).style.display = 'none'
            document.getElementById(tid).className = 'hiddenRow';
        }
        else {
            document.getElementById(tid).className = '';
        }
    }
}


function showTestDetail(div_id){
    var details_div = document.getElementById(div_id)
    var displayState = details_div.style.display
    // alert(displayState)
    if (displayState != 'block' ) {
        displayState = 'block'
        details_div.style.display = 'block'
    }
    else {
        details_div.style.display = 'none'
    }
}


function html_escape(s) {
    s = s.replace(/&/g,'&amp;');
    s = s.replace(/</g,'&lt;');
    s = s.replace(/>/g,'&gt;');
    return s;
}

/* obsoleted by detail in <div>
function showOutput(id, name) {
    var w = window.open("", //url
                    name,
                    "resizable,scrollbars,status,width=800,height=450");
    d = w.document;
    d.write("<pre>");
    d.write(html_escape(output_list[id]));
    d.write("\n");
    d.write("<a href='javascript:window.close()'>close</a>\n");
    d.write("</pre>\n");
    d.close();
}
*/
--></script>

<div class='heading'>
<h1>123</h1>
<p class='attribute'><strong>Start Time:</strong> 2019-06-17 14:51:50</p>
<p class='attribute'><strong>Duration:</strong> 0:00:10.428500</p>
<p class='attribute'><strong>Status:</strong> Pass 6 Failure 2 Error 18</p>

<p class='description'>456</p>
</div>



<p id='show_detail_line'>Show
<a href='javascript:showCase(0)'>Summary</a>
<a href='javascript:showCase(1)'>Failed</a>
<a href='javascript:showCase(2)'>All</a>
</p>
<table id='result_table'>
<colgroup>
<col align='left' />
<col align='right' />
<col align='right' />
<col align='right' />
<col align='right' />
<col align='right' />
</colgroup>
<tr id='header_row'>
    <td>Test Group/Test case</td>
    <td>Count</td>
    <td>Pass</td>
    <td>Fail</td>
    <td>Error</td>
    <td>View</td>
</tr>

<tr class='errorClass'>
    <td>get_event_list_test.GetEventListTest:  获得发布会列表 </td>
    <td>8</td>
    <td>0</td>
    <td>0</td>
    <td>8</td>
    <td><a href="javascript:showClassDetail('c1',8)">Detail</a></td>
</tr>

<tr id='ft1.1' class='none'>
    <td class='errorCase'><div class='testcase'>test_get_event_list_eid_error: eid=901 查询结果为空</div></td>
    <td colspan='5' align='center'>

    <!--css div popup start-->
    <a class="popup_link" onfocus='this.blur();' href="javascript:showTestDetail('div_ft1.1')" >
        error</a>

    <div id='div_ft1.1' class="popup_window">
        <div style='text-align: right; color:red;cursor:pointer'>
        <a onfocus='this.blur();' onclick="document.getElementById('div_ft1.1').style.display = 'none' " >
           [x]</a>
        </div>
        <pre>
        
ft1.1: Traceback (most recent call last):
  File "C:\Users\JHMK-ZSS\PycharmProjects\pyrequests\venv\lib\site-packages\urllib3\connection.py", line 160, in _new_conn
    (self._dns_host, self.port), self.timeout, **extra_kw)
  File "C:\Users\JHMK-ZSS\PycharmProjects\pyrequests\venv\lib\site-packages\urllib3\util\connection.py", line 80, in create_connection
    raise err
  File "C:\Users\JHMK-ZSS\PycharmProjects\pyrequests\venv\lib\site-packages\urllib3\util\connection.py", line 70, in create_connection
    sock.connect(sa)
ConnectionRefusedError: [WinError 10061] 由于目标计算机积极拒绝，无法连接。

During handling of the above exception, another exception occurred:

Traceback (most recent call last):
  File "C:\Users\JHMK-ZSS\PycharmProjects\pyrequests\venv\lib\site-packages\urllib3\connectionpool.py", line 603, in urlopen
    chunked=chunked)
  File "C:\Users\JHMK-ZSS\PycharmProjects\pyrequests\venv\lib\site-packages\urllib3\connectionpool.py", line 355, in _make_request
    conn.request(method, url, **httplib_request_kw)
  File "C:\Users\JHMK-ZSS\AppData\Local\Programs\Python\Python37\lib\http\client.py", line 1229, in request
    self._send_request(method, url, body, headers, encode_chunked)
  File "C:\Users\JHMK-ZSS\AppData\Local\Programs\Python\Python37\lib\http\client.py", line 1275, in _send_request
    self.endheaders(body, encode_chunked=encode_chunked)
  File "C:\Users\JHMK-ZSS\AppData\Local\Programs\Python\Python37\lib\http\client.py", line 1224, in endheaders
    self._send_output(message_body, encode_chunked=encode_chunked)
  File "C:\Users\JHMK-ZSS\AppData\Local\Programs\Python\Python37\lib\http\client.py", line 1016, in _send_output
    self.send(msg)
  File "C:\Users\JHMK-ZSS\AppData\Local\Programs\Python\Python37\lib\http\client.py", line 956, in send
    self.connect()
  File "C:\Users\JHMK-ZSS\PycharmProjects\pyrequests\venv\lib\site-packages\urllib3\connection.py", line 183, in connect
    conn = self._new_conn()
  File "C:\Users\JHMK-ZSS\PycharmProjects\pyrequests\venv\lib\site-packages\urllib3\connection.py", line 169, in _new_conn
    self, "Failed to establish a new connection: %s" % e)
urllib3.exceptions.NewConnectionError: &lt;urllib3.connection.HTTPConnection object at 0x000002393F8A09B0&gt;: Failed to establish a new connection: [WinError 10061] 由于目标计算机积极拒绝，无法连接。

During handling of the above exception, another exception occurred:

Traceback (most recent call last):
  File "C:\Users\JHMK-ZSS\PycharmProjects\pyrequests\venv\lib\site-packages\requests\adapters.py", line 449, in send
    timeout=timeout
  File "C:\Users\JHMK-ZSS\PycharmProjects\pyrequests\venv\lib\site-packages\urllib3\connectionpool.py", line 641, in urlopen
    _stacktrace=sys.exc_info()[2])
  File "C:\Users\JHMK-ZSS\PycharmProjects\pyrequests\venv\lib\site-packages\urllib3\util\retry.py", line 399, in increment
    raise MaxRetryError(_pool, url, error or ResponseError(cause))
urllib3.exceptions.MaxRetryError: HTTPConnectionPool(host='127.0.0.1', port=8000): Max retries exceeded with url: /api/get_event_list/?eid=901 (Caused by NewConnectionError('&lt;urllib3.connection.HTTPConnection object at 0x000002393F8A09B0&gt;: Failed to establish a new connection: [WinError 10061] 由于目标计算机积极拒绝，无法连接。'))

During handling of the above exception, another exception occurred:

Traceback (most recent call last):
  File "C:\Users\JHMK-ZSS\PycharmProjects\pyrequests\interface\get_event_list_test.py", line 21, in test_get_event_list_eid_error
    r = requests.get(self.base_url, params={'eid':901})
  File "C:\Users\JHMK-ZSS\PycharmProjects\pyrequests\venv\lib\site-packages\requests\api.py", line 75, in get
    return request('get', url, params=params, **kwargs)
  File "C:\Users\JHMK-ZSS\PycharmProjects\pyrequests\venv\lib\site-packages\requests\api.py", line 60, in request
    return session.request(method=method, url=url, **kwargs)
  File "C:\Users\JHMK-ZSS\PycharmProjects\pyrequests\venv\lib\site-packages\requests\sessions.py", line 533, in request
    resp = self.send(prep, **send_kwargs)
  File "C:\Users\JHMK-ZSS\PycharmProjects\pyrequests\venv\lib\site-packages\requests\sessions.py", line 646, in send
    r = adapter.send(request, **kwargs)
  File "C:\Users\JHMK-ZSS\PycharmProjects\pyrequests\venv\lib\site-packages\requests\adapters.py", line 516, in send
    raise ConnectionError(e, request=request)
requests.exceptions.ConnectionError: HTTPConnectionPool(host='127.0.0.1', port=8000): Max retries exceeded with url: /api/get_event_list/?eid=901 (Caused by NewConnectionError('&lt;urllib3.connection.HTTPConnection object at 0x000002393F8A09B0&gt;: Failed to establish a new connection: [WinError 10061] 由于目标计算机积极拒绝，无法连接。'))


        </pre>
    </div>
    <!--css div popup end-->

    </td>
</tr>

<tr id='ft1.2' class='none'>
    <td class='errorCase'><div class='testcase'>test_get_event_list_eid_error: eid=901 查询结果为空</div></td>
    <td colspan='5' align='center'>

    <!--css div popup start-->
    <a class="popup_link" onfocus='this.blur();' href="javascript:showTestDetail('div_ft1.2')" >
        error</a>

    <div id='div_ft1.2' class="popup_window">
        <div style='text-align: right; color:red;cursor:pointer'>
        <a onfocus='this.blur();' onclick="document.getElementById('div_ft1.2').style.display = 'none' " >
           [x]</a>
        </div>
        <pre>
        
ft1.2: Traceback (most recent call last):
  File "C:\Users\JHMK-ZSS\PycharmProjects\pyrequests\interface\get_event_list_test.py", line 17, in tearDown
    print(self.result)
AttributeError: 'GetEventListTest' object has no attribute 'result'


        </pre>
    </div>
    <!--css div popup end-->

    </td>
</tr>

<tr id='ft1.3' class='none'>
    <td class='errorCase'><div class='testcase'>test_get_event_list_eid_success: 根据 eid 查询结果成功</div></td>
    <td colspan='5' align='center'>

    <!--css div popup start-->
    <a class="popup_link" onfocus='this.blur();' href="javascript:showTestDetail('div_ft1.3')" >
        error</a>

    <div id='div_ft1.3' class="popup_window">
        <div style='text-align: right; color:red;cursor:pointer'>
        <a onfocus='this.blur();' onclick="document.getElementById('div_ft1.3').style.display = 'none' " >
           [x]</a>
        </div>
        <pre>
        
ft1.3: Traceback (most recent call last):
  File "C:\Users\JHMK-ZSS\PycharmProjects\pyrequests\venv\lib\site-packages\urllib3\connection.py", line 160, in _new_conn
    (self._dns_host, self.port), self.timeout, **extra_kw)
  File "C:\Users\JHMK-ZSS\PycharmProjects\pyrequests\venv\lib\site-packages\urllib3\util\connection.py", line 80, in create_connection
    raise err
  File "C:\Users\JHMK-ZSS\PycharmProjects\pyrequests\venv\lib\site-packages\urllib3\util\connection.py", line 70, in create_connection
    sock.connect(sa)
ConnectionRefusedError: [WinError 10061] 由于目标计算机积极拒绝，无法连接。

During handling of the above exception, another exception occurred:

Traceback (most recent call last):
  File "C:\Users\JHMK-ZSS\PycharmProjects\pyrequests\venv\lib\site-packages\urllib3\connectionpool.py", line 603, in urlopen
    chunked=chunked)
  File "C:\Users\JHMK-ZSS\PycharmProjects\pyrequests\venv\lib\site-packages\urllib3\connectionpool.py", line 355, in _make_request
    conn.request(method, url, **httplib_request_kw)
  File "C:\Users\JHMK-ZSS\AppData\Local\Programs\Python\Python37\lib\http\client.py", line 1229, in request
    self._send_request(method, url, body, headers, encode_chunked)
  File "C:\Users\JHMK-ZSS\AppData\Local\Programs\Python\Python37\lib\http\client.py", line 1275, in _send_request
    self.endheaders(body, encode_chunked=encode_chunked)
  File "C:\Users\JHMK-ZSS\AppData\Local\Programs\Python\Python37\lib\http\client.py", line 1224, in endheaders
    self._send_output(message_body, encode_chunked=encode_chunked)
  File "C:\Users\JHMK-ZSS\AppData\Local\Programs\Python\Python37\lib\http\client.py", line 1016, in _send_output
    self.send(msg)
  File "C:\Users\JHMK-ZSS\AppData\Local\Programs\Python\Python37\lib\http\client.py", line 956, in send
    self.connect()
  File "C:\Users\JHMK-ZSS\PycharmProjects\pyrequests\venv\lib\site-packages\urllib3\connection.py", line 183, in connect
    conn = self._new_conn()
  File "C:\Users\JHMK-ZSS\PycharmProjects\pyrequests\venv\lib\site-packages\urllib3\connection.py", line 169, in _new_conn
    self, "Failed to establish a new connection: %s" % e)
urllib3.exceptions.NewConnectionError: &lt;urllib3.connection.HTTPConnection object at 0x000002393F8EAA20&gt;: Failed to establish a new connection: [WinError 10061] 由于目标计算机积极拒绝，无法连接。

During handling of the above exception, another exception occurred:

Traceback (most recent call last):
  File "C:\Users\JHMK-ZSS\PycharmProjects\pyrequests\venv\lib\site-packages\requests\adapters.py", line 449, in send
    timeout=timeout
  File "C:\Users\JHMK-ZSS\PycharmProjects\pyrequests\venv\lib\site-packages\urllib3\connectionpool.py", line 641, in urlopen
    _stacktrace=sys.exc_info()[2])
  File "C:\Users\JHMK-ZSS\PycharmProjects\pyrequests\venv\lib\site-packages\urllib3\util\retry.py", line 399, in increment
    raise MaxRetryError(_pool, url, error or ResponseError(cause))
urllib3.exceptions.MaxRetryError: HTTPConnectionPool(host='127.0.0.1', port=8000): Max retries exceeded with url: /api/get_event_list/?eid=1 (Caused by NewConnectionError('&lt;urllib3.connection.HTTPConnection object at 0x000002393F8EAA20&gt;: Failed to establish a new connection: [WinError 10061] 由于目标计算机积极拒绝，无法连接。'))

During handling of the above exception, another exception occurred:

Traceback (most recent call last):
  File "C:\Users\JHMK-ZSS\PycharmProjects\pyrequests\interface\get_event_list_test.py", line 28, in test_get_event_list_eid_success
    r = requests.get(self.base_url, params={'eid':1})
  File "C:\Users\JHMK-ZSS\PycharmProjects\pyrequests\venv\lib\site-packages\requests\api.py", line 75, in get
    return request('get', url, params=params, **kwargs)
  File "C:\Users\JHMK-ZSS\PycharmProjects\pyrequests\venv\lib\site-packages\requests\api.py", line 60, in request
    return session.request(method=method, url=url, **kwargs)
  File "C:\Users\JHMK-ZSS\PycharmProjects\pyrequests\venv\lib\site-packages\requests\sessions.py", line 533, in request
    resp = self.send(prep, **send_kwargs)
  File "C:\Users\JHMK-ZSS\PycharmProjects\pyrequests\venv\lib\site-packages\requests\sessions.py", line 646, in send
    r = adapter.send(request, **kwargs)
  File "C:\Users\JHMK-ZSS\PycharmProjects\pyrequests\venv\lib\site-packages\requests\adapters.py", line 516, in send
    raise ConnectionError(e, request=request)
requests.exceptions.ConnectionError: HTTPConnectionPool(host='127.0.0.1', port=8000): Max retries exceeded with url: /api/get_event_list/?eid=1 (Caused by NewConnectionError('&lt;urllib3.connection.HTTPConnection object at 0x000002393F8EAA20&gt;: Failed to establish a new connection: [WinError 10061] 由于目标计算机积极拒绝，无法连接。'))


        </pre>
    </div>
    <!--css div popup end-->

    </td>
</tr>

<tr id='ft1.4' class='none'>
    <td class='errorCase'><div class='testcase'>test_get_event_list_eid_success: 根据 eid 查询结果成功</div></td>
    <td colspan='5' align='center'>

    <!--css div popup start-->
    <a class="popup_link" onfocus='this.blur();' href="javascript:showTestDetail('div_ft1.4')" >
        error</a>

    <div id='div_ft1.4' class="popup_window">
        <div style='text-align: right; color:red;cursor:pointer'>
        <a onfocus='this.blur();' onclick="document.getElementById('div_ft1.4').style.display = 'none' " >
           [x]</a>
        </div>
        <pre>
        
ft1.4: Traceback (most recent call last):
  File "C:\Users\JHMK-ZSS\PycharmProjects\pyrequests\interface\get_event_list_test.py", line 17, in tearDown
    print(self.result)
AttributeError: 'GetEventListTest' object has no attribute 'result'


        </pre>
    </div>
    <!--css div popup end-->

    </td>
</tr>

<tr id='ft1.5' class='none'>
    <td class='errorCase'><div class='testcase'>test_get_event_list_nam_result_null: 关键字‘abc’查询</div></td>
    <td colspan='5' align='center'>

    <!--css div popup start-->
    <a class="popup_link" onfocus='this.blur();' href="javascript:showTestDetail('div_ft1.5')" >
        error</a>

    <div id='div_ft1.5' class="popup_window">
        <div style='text-align: right; color:red;cursor:pointer'>
        <a onfocus='this.blur();' onclick="document.getElementById('div_ft1.5').style.display = 'none' " >
           [x]</a>
        </div>
        <pre>
        
ft1.5: Traceback (most recent call last):
  File "C:\Users\JHMK-ZSS\PycharmProjects\pyrequests\venv\lib\site-packages\urllib3\connection.py", line 160, in _new_conn
    (self._dns_host, self.port), self.timeout, **extra_kw)
  File "C:\Users\JHMK-ZSS\PycharmProjects\pyrequests\venv\lib\site-packages\urllib3\util\connection.py", line 80, in create_connection
    raise err
  File "C:\Users\JHMK-ZSS\PycharmProjects\pyrequests\venv\lib\site-packages\urllib3\util\connection.py", line 70, in create_connection
    sock.connect(sa)
ConnectionRefusedError: [WinError 10061] 由于目标计算机积极拒绝，无法连接。

During handling of the above exception, another exception occurred:

Traceback (most recent call last):
  File "C:\Users\JHMK-ZSS\PycharmProjects\pyrequests\venv\lib\site-packages\urllib3\connectionpool.py", line 603, in urlopen
    chunked=chunked)
  File "C:\Users\JHMK-ZSS\PycharmProjects\pyrequests\venv\lib\site-packages\urllib3\connectionpool.py", line 355, in _make_request
    conn.request(method, url, **httplib_request_kw)
  File "C:\Users\JHMK-ZSS\AppData\Local\Programs\Python\Python37\lib\http\client.py", line 1229, in request
    self._send_request(method, url, body, headers, encode_chunked)
  File "C:\Users\JHMK-ZSS\AppData\Local\Programs\Python\Python37\lib\http\client.py", line 1275, in _send_request
    self.endheaders(body, encode_chunked=encode_chunked)
  File "C:\Users\JHMK-ZSS\AppData\Local\Programs\Python\Python37\lib\http\client.py", line 1224, in endheaders
    self._send_output(message_body, encode_chunked=encode_chunked)
  File "C:\Users\JHMK-ZSS\AppData\Local\Programs\Python\Python37\lib\http\client.py", line 1016, in _send_output
    self.send(msg)
  File "C:\Users\JHMK-ZSS\AppData\Local\Programs\Python\Python37\lib\http\client.py", line 956, in send
    self.connect()
  File "C:\Users\JHMK-ZSS\PycharmProjects\pyrequests\venv\lib\site-packages\urllib3\connection.py", line 183, in connect
    conn = self._new_conn()
  File "C:\Users\JHMK-ZSS\PycharmProjects\pyrequests\venv\lib\site-packages\urllib3\connection.py", line 169, in _new_conn
    self, "Failed to establish a new connection: %s" % e)
urllib3.exceptions.NewConnectionError: &lt;urllib3.connection.HTTPConnection object at 0x000002393F9530F0&gt;: Failed to establish a new connection: [WinError 10061] 由于目标计算机积极拒绝，无法连接。

During handling of the above exception, another exception occurred:

Traceback (most recent call last):
  File "C:\Users\JHMK-ZSS\PycharmProjects\pyrequests\venv\lib\site-packages\requests\adapters.py", line 449, in send
    timeout=timeout
  File "C:\Users\JHMK-ZSS\PycharmProjects\pyrequests\venv\lib\site-packages\urllib3\connectionpool.py", line 641, in urlopen
    _stacktrace=sys.exc_info()[2])
  File "C:\Users\JHMK-ZSS\PycharmProjects\pyrequests\venv\lib\site-packages\urllib3\util\retry.py", line 399, in increment
    raise MaxRetryError(_pool, url, error or ResponseError(cause))
urllib3.exceptions.MaxRetryError: HTTPConnectionPool(host='127.0.0.1', port=8000): Max retries exceeded with url: /api/get_event_list/?name=abc (Caused by NewConnectionError('&lt;urllib3.connection.HTTPConnection object at 0x000002393F9530F0&gt;: Failed to establish a new connection: [WinError 10061] 由于目标计算机积极拒绝，无法连接。'))

During handling of the above exception, another exception occurred:

Traceback (most recent call last):
  File "C:\Users\JHMK-ZSS\PycharmProjects\pyrequests\interface\get_event_list_test.py", line 37, in test_get_event_list_nam_result_null
    r = requests.get(self.base_url, params={'name':'abc'})
  File "C:\Users\JHMK-ZSS\PycharmProjects\pyrequests\venv\lib\site-packages\requests\api.py", line 75, in get
    return request('get', url, params=params, **kwargs)
  File "C:\Users\JHMK-ZSS\PycharmProjects\pyrequests\venv\lib\site-packages\requests\api.py", line 60, in request
    return session.request(method=method, url=url, **kwargs)
  File "C:\Users\JHMK-ZSS\PycharmProjects\pyrequests\venv\lib\site-packages\requests\sessions.py", line 533, in request
    resp = self.send(prep, **send_kwargs)
  File "C:\Users\JHMK-ZSS\PycharmProjects\pyrequests\venv\lib\site-packages\requests\sessions.py", line 646, in send
    r = adapter.send(request, **kwargs)
  File "C:\Users\JHMK-ZSS\PycharmProjects\pyrequests\venv\lib\site-packages\requests\adapters.py", line 516, in send
    raise ConnectionError(e, request=request)
requests.exceptions.ConnectionError: HTTPConnectionPool(host='127.0.0.1', port=8000): Max retries exceeded with url: /api/get_event_list/?name=abc (Caused by NewConnectionError('&lt;urllib3.connection.HTTPConnection object at 0x000002393F9530F0&gt;: Failed to establish a new connection: [WinError 10061] 由于目标计算机积极拒绝，无法连接。'))


        </pre>
    </div>
    <!--css div popup end-->

    </td>
</tr>

<tr id='ft1.6' class='none'>
    <td class='errorCase'><div class='testcase'>test_get_event_list_nam_result_null: 关键字‘abc’查询</div></td>
    <td colspan='5' align='center'>

    <!--css div popup start-->
    <a class="popup_link" onfocus='this.blur();' href="javascript:showTestDetail('div_ft1.6')" >
        error</a>

    <div id='div_ft1.6' class="popup_window">
        <div style='text-align: right; color:red;cursor:pointer'>
        <a onfocus='this.blur();' onclick="document.getElementById('div_ft1.6').style.display = 'none' " >
           [x]</a>
        </div>
        <pre>
        
ft1.6: Traceback (most recent call last):
  File "C:\Users\JHMK-ZSS\PycharmProjects\pyrequests\interface\get_event_list_test.py", line 17, in tearDown
    print(self.result)
AttributeError: 'GetEventListTest' object has no attribute 'result'


        </pre>
    </div>
    <!--css div popup end-->

    </td>
</tr>

<tr id='ft1.7' class='none'>
    <td class='errorCase'><div class='testcase'>test_get_event_list_name_find: 关键字‘发布会’模糊查询</div></td>
    <td colspan='5' align='center'>

    <!--css div popup start-->
    <a class="popup_link" onfocus='this.blur();' href="javascript:showTestDetail('div_ft1.7')" >
        error</a>

    <div id='div_ft1.7' class="popup_window">
        <div style='text-align: right; color:red;cursor:pointer'>
        <a onfocus='this.blur();' onclick="document.getElementById('div_ft1.7').style.display = 'none' " >
           [x]</a>
        </div>
        <pre>
        
ft1.7: Traceback (most recent call last):
  File "C:\Users\JHMK-ZSS\PycharmProjects\pyrequests\venv\lib\site-packages\urllib3\connection.py", line 160, in _new_conn
    (self._dns_host, self.port), self.timeout, **extra_kw)
  File "C:\Users\JHMK-ZSS\PycharmProjects\pyrequests\venv\lib\site-packages\urllib3\util\connection.py", line 80, in create_connection
    raise err
  File "C:\Users\JHMK-ZSS\PycharmProjects\pyrequests\venv\lib\site-packages\urllib3\util\connection.py", line 70, in create_connection
    sock.connect(sa)
ConnectionRefusedError: [WinError 10061] 由于目标计算机积极拒绝，无法连接。

During handling of the above exception, another exception occurred:

Traceback (most recent call last):
  File "C:\Users\JHMK-ZSS\PycharmProjects\pyrequests\venv\lib\site-packages\urllib3\connectionpool.py", line 603, in urlopen
    chunked=chunked)
  File "C:\Users\JHMK-ZSS\PycharmProjects\pyrequests\venv\lib\site-packages\urllib3\connectionpool.py", line 355, in _make_request
    conn.request(method, url, **httplib_request_kw)
  File "C:\Users\JHMK-ZSS\AppData\Local\Programs\Python\Python37\lib\http\client.py", line 1229, in request
    self._send_request(method, url, body, headers, encode_chunked)
  File "C:\Users\JHMK-ZSS\AppData\Local\Programs\Python\Python37\lib\http\client.py", line 1275, in _send_request
    self.endheaders(body, encode_chunked=encode_chunked)
  File "C:\Users\JHMK-ZSS\AppData\Local\Programs\Python\Python37\lib\http\client.py", line 1224, in endheaders
    self._send_output(message_body, encode_chunked=encode_chunked)
  File "C:\Users\JHMK-ZSS\AppData\Local\Programs\Python\Python37\lib\http\client.py", line 1016, in _send_output
    self.send(msg)
  File "C:\Users\JHMK-ZSS\AppData\Local\Programs\Python\Python37\lib\http\client.py", line 956, in send
    self.connect()
  File "C:\Users\JHMK-ZSS\PycharmProjects\pyrequests\venv\lib\site-packages\urllib3\connection.py", line 183, in connect
    conn = self._new_conn()
  File "C:\Users\JHMK-ZSS\PycharmProjects\pyrequests\venv\lib\site-packages\urllib3\connection.py", line 169, in _new_conn
    self, "Failed to establish a new connection: %s" % e)
urllib3.exceptions.NewConnectionError: &lt;urllib3.connection.HTTPConnection object at 0x000002393F953710&gt;: Failed to establish a new connection: [WinError 10061] 由于目标计算机积极拒绝，无法连接。

During handling of the above exception, another exception occurred:

Traceback (most recent call last):
  File "C:\Users\JHMK-ZSS\PycharmProjects\pyrequests\venv\lib\site-packages\requests\adapters.py", line 449, in send
    timeout=timeout
  File "C:\Users\JHMK-ZSS\PycharmProjects\pyrequests\venv\lib\site-packages\urllib3\connectionpool.py", line 641, in urlopen
    _stacktrace=sys.exc_info()[2])
  File "C:\Users\JHMK-ZSS\PycharmProjects\pyrequests\venv\lib\site-packages\urllib3\util\retry.py", line 399, in increment
    raise MaxRetryError(_pool, url, error or ResponseError(cause))
urllib3.exceptions.MaxRetryError: HTTPConnectionPool(host='127.0.0.1', port=8000): Max retries exceeded with url: /api/get_event_list/?name=xiao (Caused by NewConnectionError('&lt;urllib3.connection.HTTPConnection object at 0x000002393F953710&gt;: Failed to establish a new connection: [WinError 10061] 由于目标计算机积极拒绝，无法连接。'))

During handling of the above exception, another exception occurred:

Traceback (most recent call last):
  File "C:\Users\JHMK-ZSS\PycharmProjects\pyrequests\interface\get_event_list_test.py", line 44, in test_get_event_list_name_find
    r = requests.get(self.base_url, params={'name':'xiao'})
  File "C:\Users\JHMK-ZSS\PycharmProjects\pyrequests\venv\lib\site-packages\requests\api.py", line 75, in get
    return request('get', url, params=params, **kwargs)
  File "C:\Users\JHMK-ZSS\PycharmProjects\pyrequests\venv\lib\site-packages\requests\api.py", line 60, in request
    return session.request(method=method, url=url, **kwargs)
  File "C:\Users\JHMK-ZSS\PycharmProjects\pyrequests\venv\lib\site-packages\requests\sessions.py", line 533, in request
    resp = self.send(prep, **send_kwargs)
  File "C:\Users\JHMK-ZSS\PycharmProjects\pyrequests\venv\lib\site-packages\requests\sessions.py", line 646, in send
    r = adapter.send(request, **kwargs)
  File "C:\Users\JHMK-ZSS\PycharmProjects\pyrequests\venv\lib\site-packages\requests\adapters.py", line 516, in send
    raise ConnectionError(e, request=request)
requests.exceptions.ConnectionError: HTTPConnectionPool(host='127.0.0.1', port=8000): Max retries exceeded with url: /api/get_event_list/?name=xiao (Caused by NewConnectionError('&lt;urllib3.connection.HTTPConnection object at 0x000002393F953710&gt;: Failed to establish a new connection: [WinError 10061] 由于目标计算机积极拒绝，无法连接。'))


        </pre>
    </div>
    <!--css div popup end-->

    </td>
</tr>

<tr id='ft1.8' class='none'>
    <td class='errorCase'><div class='testcase'>test_get_event_list_name_find: 关键字‘发布会’模糊查询</div></td>
    <td colspan='5' align='center'>

    <!--css div popup start-->
    <a class="popup_link" onfocus='this.blur();' href="javascript:showTestDetail('div_ft1.8')" >
        error</a>

    <div id='div_ft1.8' class="popup_window">
        <div style='text-align: right; color:red;cursor:pointer'>
        <a onfocus='this.blur();' onclick="document.getElementById('div_ft1.8').style.display = 'none' " >
           [x]</a>
        </div>
        <pre>
        
ft1.8: Traceback (most recent call last):
  File "C:\Users\JHMK-ZSS\PycharmProjects\pyrequests\interface\get_event_list_test.py", line 17, in tearDown
    print(self.result)
AttributeError: 'GetEventListTest' object has no attribute 'result'


        </pre>
    </div>
    <!--css div popup end-->

    </td>
</tr>

<tr class='errorClass'>
    <td>get_guest_list_test.GetGuestListTest:  获得嘉宾列表 </td>
    <td>10</td>
    <td>0</td>
    <td>0</td>
    <td>10</td>
    <td><a href="javascript:showClassDetail('c2',10)">Detail</a></td>
</tr>

<tr id='ft2.1' class='none'>
    <td class='errorCase'><div class='testcase'>test_get_event_list_eid_error: 根据 eid 查询结果为空</div></td>
    <td colspan='5' align='center'>

    <!--css div popup start-->
    <a class="popup_link" onfocus='this.blur();' href="javascript:showTestDetail('div_ft2.1')" >
        error</a>

    <div id='div_ft2.1' class="popup_window">
        <div style='text-align: right; color:red;cursor:pointer'>
        <a onfocus='this.blur();' onclick="document.getElementById('div_ft2.1').style.display = 'none' " >
           [x]</a>
        </div>
        <pre>
        
ft2.1: Traceback (most recent call last):
  File "C:\Users\JHMK-ZSS\PycharmProjects\pyrequests\venv\lib\site-packages\urllib3\connection.py", line 160, in _new_conn
    (self._dns_host, self.port), self.timeout, **extra_kw)
  File "C:\Users\JHMK-ZSS\PycharmProjects\pyrequests\venv\lib\site-packages\urllib3\util\connection.py", line 80, in create_connection
    raise err
  File "C:\Users\JHMK-ZSS\PycharmProjects\pyrequests\venv\lib\site-packages\urllib3\util\connection.py", line 70, in create_connection
    sock.connect(sa)
ConnectionRefusedError: [WinError 10061] 由于目标计算机积极拒绝，无法连接。

During handling of the above exception, another exception occurred:

Traceback (most recent call last):
  File "C:\Users\JHMK-ZSS\PycharmProjects\pyrequests\venv\lib\site-packages\urllib3\connectionpool.py", line 603, in urlopen
    chunked=chunked)
  File "C:\Users\JHMK-ZSS\PycharmProjects\pyrequests\venv\lib\site-packages\urllib3\connectionpool.py", line 355, in _make_request
    conn.request(method, url, **httplib_request_kw)
  File "C:\Users\JHMK-ZSS\AppData\Local\Programs\Python\Python37\lib\http\client.py", line 1229, in request
    self._send_request(method, url, body, headers, encode_chunked)
  File "C:\Users\JHMK-ZSS\AppData\Local\Programs\Python\Python37\lib\http\client.py", line 1275, in _send_request
    self.endheaders(body, encode_chunked=encode_chunked)
  File "C:\Users\JHMK-ZSS\AppData\Local\Programs\Python\Python37\lib\http\client.py", line 1224, in endheaders
    self._send_output(message_body, encode_chunked=encode_chunked)
  File "C:\Users\JHMK-ZSS\AppData\Local\Programs\Python\Python37\lib\http\client.py", line 1016, in _send_output
    self.send(msg)
  File "C:\Users\JHMK-ZSS\AppData\Local\Programs\Python\Python37\lib\http\client.py", line 956, in send
    self.connect()
  File "C:\Users\JHMK-ZSS\PycharmProjects\pyrequests\venv\lib\site-packages\urllib3\connection.py", line 183, in connect
    conn = self._new_conn()
  File "C:\Users\JHMK-ZSS\PycharmProjects\pyrequests\venv\lib\site-packages\urllib3\connection.py", line 169, in _new_conn
    self, "Failed to establish a new connection: %s" % e)
urllib3.exceptions.NewConnectionError: &lt;urllib3.connection.HTTPConnection object at 0x000002393F8EAA20&gt;: Failed to establish a new connection: [WinError 10061] 由于目标计算机积极拒绝，无法连接。

During handling of the above exception, another exception occurred:

Traceback (most recent call last):
  File "C:\Users\JHMK-ZSS\PycharmProjects\pyrequests\venv\lib\site-packages\requests\adapters.py", line 449, in send
    timeout=timeout
  File "C:\Users\JHMK-ZSS\PycharmProjects\pyrequests\venv\lib\site-packages\urllib3\connectionpool.py", line 641, in urlopen
    _stacktrace=sys.exc_info()[2])
  File "C:\Users\JHMK-ZSS\PycharmProjects\pyrequests\venv\lib\site-packages\urllib3\util\retry.py", line 399, in increment
    raise MaxRetryError(_pool, url, error or ResponseError(cause))
urllib3.exceptions.MaxRetryError: HTTPConnectionPool(host='127.0.0.1', port=8000): Max retries exceeded with url: /api/get_guest_list/?eid=901 (Caused by NewConnectionError('&lt;urllib3.connection.HTTPConnection object at 0x000002393F8EAA20&gt;: Failed to establish a new connection: [WinError 10061] 由于目标计算机积极拒绝，无法连接。'))

During handling of the above exception, another exception occurred:

Traceback (most recent call last):
  File "C:\Users\JHMK-ZSS\PycharmProjects\pyrequests\interface\get_guest_list_test.py", line 27, in test_get_event_list_eid_error
    r = requests.get(self.base_url, params={'eid':901})
  File "C:\Users\JHMK-ZSS\PycharmProjects\pyrequests\venv\lib\site-packages\requests\api.py", line 75, in get
    return request('get', url, params=params, **kwargs)
  File "C:\Users\JHMK-ZSS\PycharmProjects\pyrequests\venv\lib\site-packages\requests\api.py", line 60, in request
    return session.request(method=method, url=url, **kwargs)
  File "C:\Users\JHMK-ZSS\PycharmProjects\pyrequests\venv\lib\site-packages\requests\sessions.py", line 533, in request
    resp = self.send(prep, **send_kwargs)
  File "C:\Users\JHMK-ZSS\PycharmProjects\pyrequests\venv\lib\site-packages\requests\sessions.py", line 646, in send
    r = adapter.send(request, **kwargs)
  File "C:\Users\JHMK-ZSS\PycharmProjects\pyrequests\venv\lib\site-packages\requests\adapters.py", line 516, in send
    raise ConnectionError(e, request=request)
requests.exceptions.ConnectionError: HTTPConnectionPool(host='127.0.0.1', port=8000): Max retries exceeded with url: /api/get_guest_list/?eid=901 (Caused by NewConnectionError('&lt;urllib3.connection.HTTPConnection object at 0x000002393F8EAA20&gt;: Failed to establish a new connection: [WinError 10061] 由于目标计算机积极拒绝，无法连接。'))


        </pre>
    </div>
    <!--css div popup end-->

    </td>
</tr>

<tr id='ft2.2' class='none'>
    <td class='errorCase'><div class='testcase'>test_get_event_list_eid_error: 根据 eid 查询结果为空</div></td>
    <td colspan='5' align='center'>

    <!--css div popup start-->
    <a class="popup_link" onfocus='this.blur();' href="javascript:showTestDetail('div_ft2.2')" >
        error</a>

    <div id='div_ft2.2' class="popup_window">
        <div style='text-align: right; color:red;cursor:pointer'>
        <a onfocus='this.blur();' onclick="document.getElementById('div_ft2.2').style.display = 'none' " >
           [x]</a>
        </div>
        <pre>
        
ft2.2: Traceback (most recent call last):
  File "C:\Users\JHMK-ZSS\PycharmProjects\pyrequests\interface\get_guest_list_test.py", line 16, in tearDown
    print(self.result)
AttributeError: 'GetGuestListTest' object has no attribute 'result'


        </pre>
    </div>
    <!--css div popup end-->

    </td>
</tr>

<tr id='ft2.3' class='none'>
    <td class='errorCase'><div class='testcase'>test_get_event_list_eid_phone_null: 根据 eid 和phone 查询结果为空</div></td>
    <td colspan='5' align='center'>

    <!--css div popup start-->
    <a class="popup_link" onfocus='this.blur();' href="javascript:showTestDetail('div_ft2.3')" >
        error</a>

    <div id='div_ft2.3' class="popup_window">
        <div style='text-align: right; color:red;cursor:pointer'>
        <a onfocus='this.blur();' onclick="document.getElementById('div_ft2.3').style.display = 'none' " >
           [x]</a>
        </div>
        <pre>
        
ft2.3: Traceback (most recent call last):
  File "C:\Users\JHMK-ZSS\PycharmProjects\pyrequests\venv\lib\site-packages\urllib3\connection.py", line 160, in _new_conn
    (self._dns_host, self.port), self.timeout, **extra_kw)
  File "C:\Users\JHMK-ZSS\PycharmProjects\pyrequests\venv\lib\site-packages\urllib3\util\connection.py", line 80, in create_connection
    raise err
  File "C:\Users\JHMK-ZSS\PycharmProjects\pyrequests\venv\lib\site-packages\urllib3\util\connection.py", line 70, in create_connection
    sock.connect(sa)
ConnectionRefusedError: [WinError 10061] 由于目标计算机积极拒绝，无法连接。

During handling of the above exception, another exception occurred:

Traceback (most recent call last):
  File "C:\Users\JHMK-ZSS\PycharmProjects\pyrequests\venv\lib\site-packages\urllib3\connectionpool.py", line 603, in urlopen
    chunked=chunked)
  File "C:\Users\JHMK-ZSS\PycharmProjects\pyrequests\venv\lib\site-packages\urllib3\connectionpool.py", line 355, in _make_request
    conn.request(method, url, **httplib_request_kw)
  File "C:\Users\JHMK-ZSS\AppData\Local\Programs\Python\Python37\lib\http\client.py", line 1229, in request
    self._send_request(method, url, body, headers, encode_chunked)
  File "C:\Users\JHMK-ZSS\AppData\Local\Programs\Python\Python37\lib\http\client.py", line 1275, in _send_request
    self.endheaders(body, encode_chunked=encode_chunked)
  File "C:\Users\JHMK-ZSS\AppData\Local\Programs\Python\Python37\lib\http\client.py", line 1224, in endheaders
    self._send_output(message_body, encode_chunked=encode_chunked)
  File "C:\Users\JHMK-ZSS\AppData\Local\Programs\Python\Python37\lib\http\client.py", line 1016, in _send_output
    self.send(msg)
  File "C:\Users\JHMK-ZSS\AppData\Local\Programs\Python\Python37\lib\http\client.py", line 956, in send
    self.connect()
  File "C:\Users\JHMK-ZSS\PycharmProjects\pyrequests\venv\lib\site-packages\urllib3\connection.py", line 183, in connect
    conn = self._new_conn()
  File "C:\Users\JHMK-ZSS\PycharmProjects\pyrequests\venv\lib\site-packages\urllib3\connection.py", line 169, in _new_conn
    self, "Failed to establish a new connection: %s" % e)
urllib3.exceptions.NewConnectionError: &lt;urllib3.connection.HTTPConnection object at 0x000002393F892860&gt;: Failed to establish a new connection: [WinError 10061] 由于目标计算机积极拒绝，无法连接。

During handling of the above exception, another exception occurred:

Traceback (most recent call last):
  File "C:\Users\JHMK-ZSS\PycharmProjects\pyrequests\venv\lib\site-packages\requests\adapters.py", line 449, in send
    timeout=timeout
  File "C:\Users\JHMK-ZSS\PycharmProjects\pyrequests\venv\lib\site-packages\urllib3\connectionpool.py", line 641, in urlopen
    _stacktrace=sys.exc_info()[2])
  File "C:\Users\JHMK-ZSS\PycharmProjects\pyrequests\venv\lib\site-packages\urllib3\util\retry.py", line 399, in increment
    raise MaxRetryError(_pool, url, error or ResponseError(cause))
urllib3.exceptions.MaxRetryError: HTTPConnectionPool(host='127.0.0.1', port=8000): Max retries exceeded with url: /api/get_guest_list/?eid=901&amp;phone=10000000000 (Caused by NewConnectionError('&lt;urllib3.connection.HTTPConnection object at 0x000002393F892860&gt;: Failed to establish a new connection: [WinError 10061] 由于目标计算机积极拒绝，无法连接。'))

During handling of the above exception, another exception occurred:

Traceback (most recent call last):
  File "C:\Users\JHMK-ZSS\PycharmProjects\pyrequests\interface\get_guest_list_test.py", line 43, in test_get_event_list_eid_phone_null
    r = requests.get(self.base_url, params={'eid':901,'phone':'10000000000'})
  File "C:\Users\JHMK-ZSS\PycharmProjects\pyrequests\venv\lib\site-packages\requests\api.py", line 75, in get
    return request('get', url, params=params, **kwargs)
  File "C:\Users\JHMK-ZSS\PycharmProjects\pyrequests\venv\lib\site-packages\requests\api.py", line 60, in request
    return session.request(method=method, url=url, **kwargs)
  File "C:\Users\JHMK-ZSS\PycharmProjects\pyrequests\venv\lib\site-packages\requests\sessions.py", line 533, in request
    resp = self.send(prep, **send_kwargs)
  File "C:\Users\JHMK-ZSS\PycharmProjects\pyrequests\venv\lib\site-packages\requests\sessions.py", line 646, in send
    r = adapter.send(request, **kwargs)
  File "C:\Users\JHMK-ZSS\PycharmProjects\pyrequests\venv\lib\site-packages\requests\adapters.py", line 516, in send
    raise ConnectionError(e, request=request)
requests.exceptions.ConnectionError: HTTPConnectionPool(host='127.0.0.1', port=8000): Max retries exceeded with url: /api/get_guest_list/?eid=901&amp;phone=10000000000 (Caused by NewConnectionError('&lt;urllib3.connection.HTTPConnection object at 0x000002393F892860&gt;: Failed to establish a new connection: [WinError 10061] 由于目标计算机积极拒绝，无法连接。'))


        </pre>
    </div>
    <!--css div popup end-->

    </td>
</tr>

<tr id='ft2.4' class='none'>
    <td class='errorCase'><div class='testcase'>test_get_event_list_eid_phone_null: 根据 eid 和phone 查询结果为空</div></td>
    <td colspan='5' align='center'>

    <!--css div popup start-->
    <a class="popup_link" onfocus='this.blur();' href="javascript:showTestDetail('div_ft2.4')" >
        error</a>

    <div id='div_ft2.4' class="popup_window">
        <div style='text-align: right; color:red;cursor:pointer'>
        <a onfocus='this.blur();' onclick="document.getElementById('div_ft2.4').style.display = 'none' " >
           [x]</a>
        </div>
        <pre>
        
ft2.4: Traceback (most recent call last):
  File "C:\Users\JHMK-ZSS\PycharmProjects\pyrequests\interface\get_guest_list_test.py", line 16, in tearDown
    print(self.result)
AttributeError: 'GetGuestListTest' object has no attribute 'result'


        </pre>
    </div>
    <!--css div popup end-->

    </td>
</tr>

<tr id='ft2.5' class='none'>
    <td class='errorCase'><div class='testcase'>test_get_event_list_eid_phone_success: 根据 eid 和phone 查询结果成功</div></td>
    <td colspan='5' align='center'>

    <!--css div popup start-->
    <a class="popup_link" onfocus='this.blur();' href="javascript:showTestDetail('div_ft2.5')" >
        error</a>

    <div id='div_ft2.5' class="popup_window">
        <div style='text-align: right; color:red;cursor:pointer'>
        <a onfocus='this.blur();' onclick="document.getElementById('div_ft2.5').style.display = 'none' " >
           [x]</a>
        </div>
        <pre>
        
ft2.5: Traceback (most recent call last):
  File "C:\Users\JHMK-ZSS\PycharmProjects\pyrequests\venv\lib\site-packages\urllib3\connection.py", line 160, in _new_conn
    (self._dns_host, self.port), self.timeout, **extra_kw)
  File "C:\Users\JHMK-ZSS\PycharmProjects\pyrequests\venv\lib\site-packages\urllib3\util\connection.py", line 80, in create_connection
    raise err
  File "C:\Users\JHMK-ZSS\PycharmProjects\pyrequests\venv\lib\site-packages\urllib3\util\connection.py", line 70, in create_connection
    sock.connect(sa)
ConnectionRefusedError: [WinError 10061] 由于目标计算机积极拒绝，无法连接。

During handling of the above exception, another exception occurred:

Traceback (most recent call last):
  File "C:\Users\JHMK-ZSS\PycharmProjects\pyrequests\venv\lib\site-packages\urllib3\connectionpool.py", line 603, in urlopen
    chunked=chunked)
  File "C:\Users\JHMK-ZSS\PycharmProjects\pyrequests\venv\lib\site-packages\urllib3\connectionpool.py", line 355, in _make_request
    conn.request(method, url, **httplib_request_kw)
  File "C:\Users\JHMK-ZSS\AppData\Local\Programs\Python\Python37\lib\http\client.py", line 1229, in request
    self._send_request(method, url, body, headers, encode_chunked)
  File "C:\Users\JHMK-ZSS\AppData\Local\Programs\Python\Python37\lib\http\client.py", line 1275, in _send_request
    self.endheaders(body, encode_chunked=encode_chunked)
  File "C:\Users\JHMK-ZSS\AppData\Local\Programs\Python\Python37\lib\http\client.py", line 1224, in endheaders
    self._send_output(message_body, encode_chunked=encode_chunked)
  File "C:\Users\JHMK-ZSS\AppData\Local\Programs\Python\Python37\lib\http\client.py", line 1016, in _send_output
    self.send(msg)
  File "C:\Users\JHMK-ZSS\AppData\Local\Programs\Python\Python37\lib\http\client.py", line 956, in send
    self.connect()
  File "C:\Users\JHMK-ZSS\PycharmProjects\pyrequests\venv\lib\site-packages\urllib3\connection.py", line 183, in connect
    conn = self._new_conn()
  File "C:\Users\JHMK-ZSS\PycharmProjects\pyrequests\venv\lib\site-packages\urllib3\connection.py", line 169, in _new_conn
    self, "Failed to establish a new connection: %s" % e)
urllib3.exceptions.NewConnectionError: &lt;urllib3.connection.HTTPConnection object at 0x000002393F953630&gt;: Failed to establish a new connection: [WinError 10061] 由于目标计算机积极拒绝，无法连接。

During handling of the above exception, another exception occurred:

Traceback (most recent call last):
  File "C:\Users\JHMK-ZSS\PycharmProjects\pyrequests\venv\lib\site-packages\requests\adapters.py", line 449, in send
    timeout=timeout
  File "C:\Users\JHMK-ZSS\PycharmProjects\pyrequests\venv\lib\site-packages\urllib3\connectionpool.py", line 641, in urlopen
    _stacktrace=sys.exc_info()[2])
  File "C:\Users\JHMK-ZSS\PycharmProjects\pyrequests\venv\lib\site-packages\urllib3\util\retry.py", line 399, in increment
    raise MaxRetryError(_pool, url, error or ResponseError(cause))
urllib3.exceptions.MaxRetryError: HTTPConnectionPool(host='127.0.0.1', port=8000): Max retries exceeded with url: /api/get_guest_list/?eid=1&amp;phone=15945393949 (Caused by NewConnectionError('&lt;urllib3.connection.HTTPConnection object at 0x000002393F953630&gt;: Failed to establish a new connection: [WinError 10061] 由于目标计算机积极拒绝，无法连接。'))

During handling of the above exception, another exception occurred:

Traceback (most recent call last):
  File "C:\Users\JHMK-ZSS\PycharmProjects\pyrequests\interface\get_guest_list_test.py", line 50, in test_get_event_list_eid_phone_success
    r = requests.get(self.base_url, params={'eid':1,'phone':'15945393949'})
  File "C:\Users\JHMK-ZSS\PycharmProjects\pyrequests\venv\lib\site-packages\requests\api.py", line 75, in get
    return request('get', url, params=params, **kwargs)
  File "C:\Users\JHMK-ZSS\PycharmProjects\pyrequests\venv\lib\site-packages\requests\api.py", line 60, in request
    return session.request(method=method, url=url, **kwargs)
  File "C:\Users\JHMK-ZSS\PycharmProjects\pyrequests\venv\lib\site-packages\requests\sessions.py", line 533, in request
    resp = self.send(prep, **send_kwargs)
  File "C:\Users\JHMK-ZSS\PycharmProjects\pyrequests\venv\lib\site-packages\requests\sessions.py", line 646, in send
    r = adapter.send(request, **kwargs)
  File "C:\Users\JHMK-ZSS\PycharmProjects\pyrequests\venv\lib\site-packages\requests\adapters.py", line 516, in send
    raise ConnectionError(e, request=request)
requests.exceptions.ConnectionError: HTTPConnectionPool(host='127.0.0.1', port=8000): Max retries exceeded with url: /api/get_guest_list/?eid=1&amp;phone=15945393949 (Caused by NewConnectionError('&lt;urllib3.connection.HTTPConnection object at 0x000002393F953630&gt;: Failed to establish a new connection: [WinError 10061] 由于目标计算机积极拒绝，无法连接。'))


        </pre>
    </div>
    <!--css div popup end-->

    </td>
</tr>

<tr id='ft2.6' class='none'>
    <td class='errorCase'><div class='testcase'>test_get_event_list_eid_phone_success: 根据 eid 和phone 查询结果成功</div></td>
    <td colspan='5' align='center'>

    <!--css div popup start-->
    <a class="popup_link" onfocus='this.blur();' href="javascript:showTestDetail('div_ft2.6')" >
        error</a>

    <div id='div_ft2.6' class="popup_window">
        <div style='text-align: right; color:red;cursor:pointer'>
        <a onfocus='this.blur();' onclick="document.getElementById('div_ft2.6').style.display = 'none' " >
           [x]</a>
        </div>
        <pre>
        
ft2.6: Traceback (most recent call last):
  File "C:\Users\JHMK-ZSS\PycharmProjects\pyrequests\interface\get_guest_list_test.py", line 16, in tearDown
    print(self.result)
AttributeError: 'GetGuestListTest' object has no attribute 'result'


        </pre>
    </div>
    <!--css div popup end-->

    </td>
</tr>

<tr id='ft2.7' class='none'>
    <td class='errorCase'><div class='testcase'>test_get_event_list_eid_success: 根据 eid 查询结果成功</div></td>
    <td colspan='5' align='center'>

    <!--css div popup start-->
    <a class="popup_link" onfocus='this.blur();' href="javascript:showTestDetail('div_ft2.7')" >
        error</a>

    <div id='div_ft2.7' class="popup_window">
        <div style='text-align: right; color:red;cursor:pointer'>
        <a onfocus='this.blur();' onclick="document.getElementById('div_ft2.7').style.display = 'none' " >
           [x]</a>
        </div>
        <pre>
        
ft2.7: Traceback (most recent call last):
  File "C:\Users\JHMK-ZSS\PycharmProjects\pyrequests\venv\lib\site-packages\urllib3\connection.py", line 160, in _new_conn
    (self._dns_host, self.port), self.timeout, **extra_kw)
  File "C:\Users\JHMK-ZSS\PycharmProjects\pyrequests\venv\lib\site-packages\urllib3\util\connection.py", line 80, in create_connection
    raise err
  File "C:\Users\JHMK-ZSS\PycharmProjects\pyrequests\venv\lib\site-packages\urllib3\util\connection.py", line 70, in create_connection
    sock.connect(sa)
ConnectionRefusedError: [WinError 10061] 由于目标计算机积极拒绝，无法连接。

During handling of the above exception, another exception occurred:

Traceback (most recent call last):
  File "C:\Users\JHMK-ZSS\PycharmProjects\pyrequests\venv\lib\site-packages\urllib3\connectionpool.py", line 603, in urlopen
    chunked=chunked)
  File "C:\Users\JHMK-ZSS\PycharmProjects\pyrequests\venv\lib\site-packages\urllib3\connectionpool.py", line 355, in _make_request
    conn.request(method, url, **httplib_request_kw)
  File "C:\Users\JHMK-ZSS\AppData\Local\Programs\Python\Python37\lib\http\client.py", line 1229, in request
    self._send_request(method, url, body, headers, encode_chunked)
  File "C:\Users\JHMK-ZSS\AppData\Local\Programs\Python\Python37\lib\http\client.py", line 1275, in _send_request
    self.endheaders(body, encode_chunked=encode_chunked)
  File "C:\Users\JHMK-ZSS\AppData\Local\Programs\Python\Python37\lib\http\client.py", line 1224, in endheaders
    self._send_output(message_body, encode_chunked=encode_chunked)
  File "C:\Users\JHMK-ZSS\AppData\Local\Programs\Python\Python37\lib\http\client.py", line 1016, in _send_output
    self.send(msg)
  File "C:\Users\JHMK-ZSS\AppData\Local\Programs\Python\Python37\lib\http\client.py", line 956, in send
    self.connect()
  File "C:\Users\JHMK-ZSS\PycharmProjects\pyrequests\venv\lib\site-packages\urllib3\connection.py", line 183, in connect
    conn = self._new_conn()
  File "C:\Users\JHMK-ZSS\PycharmProjects\pyrequests\venv\lib\site-packages\urllib3\connection.py", line 169, in _new_conn
    self, "Failed to establish a new connection: %s" % e)
urllib3.exceptions.NewConnectionError: &lt;urllib3.connection.HTTPConnection object at 0x000002393F953EF0&gt;: Failed to establish a new connection: [WinError 10061] 由于目标计算机积极拒绝，无法连接。

During handling of the above exception, another exception occurred:

Traceback (most recent call last):
  File "C:\Users\JHMK-ZSS\PycharmProjects\pyrequests\venv\lib\site-packages\requests\adapters.py", line 449, in send
    timeout=timeout
  File "C:\Users\JHMK-ZSS\PycharmProjects\pyrequests\venv\lib\site-packages\urllib3\connectionpool.py", line 641, in urlopen
    _stacktrace=sys.exc_info()[2])
  File "C:\Users\JHMK-ZSS\PycharmProjects\pyrequests\venv\lib\site-packages\urllib3\util\retry.py", line 399, in increment
    raise MaxRetryError(_pool, url, error or ResponseError(cause))
urllib3.exceptions.MaxRetryError: HTTPConnectionPool(host='127.0.0.1', port=8000): Max retries exceeded with url: /api/get_guest_list/?eid=1 (Caused by NewConnectionError('&lt;urllib3.connection.HTTPConnection object at 0x000002393F953EF0&gt;: Failed to establish a new connection: [WinError 10061] 由于目标计算机积极拒绝，无法连接。'))

During handling of the above exception, another exception occurred:

Traceback (most recent call last):
  File "C:\Users\JHMK-ZSS\PycharmProjects\pyrequests\interface\get_guest_list_test.py", line 34, in test_get_event_list_eid_success
    r = requests.get(self.base_url, params={'eid':1})
  File "C:\Users\JHMK-ZSS\PycharmProjects\pyrequests\venv\lib\site-packages\requests\api.py", line 75, in get
    return request('get', url, params=params, **kwargs)
  File "C:\Users\JHMK-ZSS\PycharmProjects\pyrequests\venv\lib\site-packages\requests\api.py", line 60, in request
    return session.request(method=method, url=url, **kwargs)
  File "C:\Users\JHMK-ZSS\PycharmProjects\pyrequests\venv\lib\site-packages\requests\sessions.py", line 533, in request
    resp = self.send(prep, **send_kwargs)
  File "C:\Users\JHMK-ZSS\PycharmProjects\pyrequests\venv\lib\site-packages\requests\sessions.py", line 646, in send
    r = adapter.send(request, **kwargs)
  File "C:\Users\JHMK-ZSS\PycharmProjects\pyrequests\venv\lib\site-packages\requests\adapters.py", line 516, in send
    raise ConnectionError(e, request=request)
requests.exceptions.ConnectionError: HTTPConnectionPool(host='127.0.0.1', port=8000): Max retries exceeded with url: /api/get_guest_list/?eid=1 (Caused by NewConnectionError('&lt;urllib3.connection.HTTPConnection object at 0x000002393F953EF0&gt;: Failed to establish a new connection: [WinError 10061] 由于目标计算机积极拒绝，无法连接。'))


        </pre>
    </div>
    <!--css div popup end-->

    </td>
</tr>

<tr id='ft2.8' class='none'>
    <td class='errorCase'><div class='testcase'>test_get_event_list_eid_success: 根据 eid 查询结果成功</div></td>
    <td colspan='5' align='center'>

    <!--css div popup start-->
    <a class="popup_link" onfocus='this.blur();' href="javascript:showTestDetail('div_ft2.8')" >
        error</a>

    <div id='div_ft2.8' class="popup_window">
        <div style='text-align: right; color:red;cursor:pointer'>
        <a onfocus='this.blur();' onclick="document.getElementById('div_ft2.8').style.display = 'none' " >
           [x]</a>
        </div>
        <pre>
        
ft2.8: Traceback (most recent call last):
  File "C:\Users\JHMK-ZSS\PycharmProjects\pyrequests\interface\get_guest_list_test.py", line 16, in tearDown
    print(self.result)
AttributeError: 'GetGuestListTest' object has no attribute 'result'


        </pre>
    </div>
    <!--css div popup end-->

    </td>
</tr>

<tr id='ft2.9' class='none'>
    <td class='errorCase'><div class='testcase'>test_get_guest_list_eid_null: eid 参数为空</div></td>
    <td colspan='5' align='center'>

    <!--css div popup start-->
    <a class="popup_link" onfocus='this.blur();' href="javascript:showTestDetail('div_ft2.9')" >
        error</a>

    <div id='div_ft2.9' class="popup_window">
        <div style='text-align: right; color:red;cursor:pointer'>
        <a onfocus='this.blur();' onclick="document.getElementById('div_ft2.9').style.display = 'none' " >
           [x]</a>
        </div>
        <pre>
        
ft2.9: Traceback (most recent call last):
  File "C:\Users\JHMK-ZSS\PycharmProjects\pyrequests\venv\lib\site-packages\urllib3\connection.py", line 160, in _new_conn
    (self._dns_host, self.port), self.timeout, **extra_kw)
  File "C:\Users\JHMK-ZSS\PycharmProjects\pyrequests\venv\lib\site-packages\urllib3\util\connection.py", line 80, in create_connection
    raise err
  File "C:\Users\JHMK-ZSS\PycharmProjects\pyrequests\venv\lib\site-packages\urllib3\util\connection.py", line 70, in create_connection
    sock.connect(sa)
ConnectionRefusedError: [WinError 10061] 由于目标计算机积极拒绝，无法连接。

During handling of the above exception, another exception occurred:

Traceback (most recent call last):
  File "C:\Users\JHMK-ZSS\PycharmProjects\pyrequests\venv\lib\site-packages\urllib3\connectionpool.py", line 603, in urlopen
    chunked=chunked)
  File "C:\Users\JHMK-ZSS\PycharmProjects\pyrequests\venv\lib\site-packages\urllib3\connectionpool.py", line 355, in _make_request
    conn.request(method, url, **httplib_request_kw)
  File "C:\Users\JHMK-ZSS\AppData\Local\Programs\Python\Python37\lib\http\client.py", line 1229, in request
    self._send_request(method, url, body, headers, encode_chunked)
  File "C:\Users\JHMK-ZSS\AppData\Local\Programs\Python\Python37\lib\http\client.py", line 1275, in _send_request
    self.endheaders(body, encode_chunked=encode_chunked)
  File "C:\Users\JHMK-ZSS\AppData\Local\Programs\Python\Python37\lib\http\client.py", line 1224, in endheaders
    self._send_output(message_body, encode_chunked=encode_chunked)
  File "C:\Users\JHMK-ZSS\AppData\Local\Programs\Python\Python37\lib\http\client.py", line 1016, in _send_output
    self.send(msg)
  File "C:\Users\JHMK-ZSS\AppData\Local\Programs\Python\Python37\lib\http\client.py", line 956, in send
    self.connect()
  File "C:\Users\JHMK-ZSS\PycharmProjects\pyrequests\venv\lib\site-packages\urllib3\connection.py", line 183, in connect
    conn = self._new_conn()
  File "C:\Users\JHMK-ZSS\PycharmProjects\pyrequests\venv\lib\site-packages\urllib3\connection.py", line 169, in _new_conn
    self, "Failed to establish a new connection: %s" % e)
urllib3.exceptions.NewConnectionError: &lt;urllib3.connection.HTTPConnection object at 0x000002393F962630&gt;: Failed to establish a new connection: [WinError 10061] 由于目标计算机积极拒绝，无法连接。

During handling of the above exception, another exception occurred:

Traceback (most recent call last):
  File "C:\Users\JHMK-ZSS\PycharmProjects\pyrequests\venv\lib\site-packages\requests\adapters.py", line 449, in send
    timeout=timeout
  File "C:\Users\JHMK-ZSS\PycharmProjects\pyrequests\venv\lib\site-packages\urllib3\connectionpool.py", line 641, in urlopen
    _stacktrace=sys.exc_info()[2])
  File "C:\Users\JHMK-ZSS\PycharmProjects\pyrequests\venv\lib\site-packages\urllib3\util\retry.py", line 399, in increment
    raise MaxRetryError(_pool, url, error or ResponseError(cause))
urllib3.exceptions.MaxRetryError: HTTPConnectionPool(host='127.0.0.1', port=8000): Max retries exceeded with url: /api/get_guest_list/?eid= (Caused by NewConnectionError('&lt;urllib3.connection.HTTPConnection object at 0x000002393F962630&gt;: Failed to establish a new connection: [WinError 10061] 由于目标计算机积极拒绝，无法连接。'))

During handling of the above exception, another exception occurred:

Traceback (most recent call last):
  File "C:\Users\JHMK-ZSS\PycharmProjects\pyrequests\interface\get_guest_list_test.py", line 20, in test_get_guest_list_eid_null
    r = requests.get(self.base_url, params={'eid':''})
  File "C:\Users\JHMK-ZSS\PycharmProjects\pyrequests\venv\lib\site-packages\requests\api.py", line 75, in get
    return request('get', url, params=params, **kwargs)
  File "C:\Users\JHMK-ZSS\PycharmProjects\pyrequests\venv\lib\site-packages\requests\api.py", line 60, in request
    return session.request(method=method, url=url, **kwargs)
  File "C:\Users\JHMK-ZSS\PycharmProjects\pyrequests\venv\lib\site-packages\requests\sessions.py", line 533, in request
    resp = self.send(prep, **send_kwargs)
  File "C:\Users\JHMK-ZSS\PycharmProjects\pyrequests\venv\lib\site-packages\requests\sessions.py", line 646, in send
    r = adapter.send(request, **kwargs)
  File "C:\Users\JHMK-ZSS\PycharmProjects\pyrequests\venv\lib\site-packages\requests\adapters.py", line 516, in send
    raise ConnectionError(e, request=request)
requests.exceptions.ConnectionError: HTTPConnectionPool(host='127.0.0.1', port=8000): Max retries exceeded with url: /api/get_guest_list/?eid= (Caused by NewConnectionError('&lt;urllib3.connection.HTTPConnection object at 0x000002393F962630&gt;: Failed to establish a new connection: [WinError 10061] 由于目标计算机积极拒绝，无法连接。'))


        </pre>
    </div>
    <!--css div popup end-->

    </td>
</tr>

<tr id='ft2.10' class='none'>
    <td class='errorCase'><div class='testcase'>test_get_guest_list_eid_null: eid 参数为空</div></td>
    <td colspan='5' align='center'>

    <!--css div popup start-->
    <a class="popup_link" onfocus='this.blur();' href="javascript:showTestDetail('div_ft2.10')" >
        error</a>

    <div id='div_ft2.10' class="popup_window">
        <div style='text-align: right; color:red;cursor:pointer'>
        <a onfocus='this.blur();' onclick="document.getElementById('div_ft2.10').style.display = 'none' " >
           [x]</a>
        </div>
        <pre>
        
ft2.10: Traceback (most recent call last):
  File "C:\Users\JHMK-ZSS\PycharmProjects\pyrequests\interface\get_guest_list_test.py", line 16, in tearDown
    print(self.result)
AttributeError: 'GetGuestListTest' object has no attribute 'result'


        </pre>
    </div>
    <!--css div popup end-->

    </td>
</tr>

<tr class='passClass'>
    <td>get_hot_list_test.GetHotList</td>
    <td>1</td>
    <td>1</td>
    <td>0</td>
    <td>0</td>
    <td><a href="javascript:showClassDetail('c3',1)">Detail</a></td>
</tr>

<tr id='pt3.1' class='hiddenRow'>
    <td class='none'><div class='testcase'>test_get_hot_list_success</div></td>
    <td colspan='5' align='center'>

    <!--css div popup start-->
    <a class="popup_link" onfocus='this.blur();' href="javascript:showTestDetail('div_pt3.1')" >
        pass</a>

    <div id='div_pt3.1' class="popup_window">
        <div style='text-align: right; color:red;cursor:pointer'>
        <a onfocus='this.blur();' onclick="document.getElementById('div_pt3.1').style.display = 'none' " >
           [x]</a>
        </div>
        <pre>
        
pt3.1: {'code': 200, 'msg': '成功!', 'data': [{'type': 'gif', 'text': '投票：你是喜欢黑的还是白的？', 'username': '摸咪校尉 [百思正能量]', 'uid': '20385456', 'header': 'http://wimg.spriteapp.cn/profile/large/2017/11/28/5a1cd9941d213_mini.jpg', 'comment': 700, 'top_commentsVoiceuri': None, 'top_commentsContent': '白天用白的，有精神！\n晚上用黑的，睡得香！', 'top_commentsHeader': 'http://wimg.spriteapp.cn/profile/large/2016/09/19/57dec2985dfaa_mini.jpg', 'top_commentsName': '每个男人心中都有一辆jeep', 'passtime': '2017-10-12\xa022:22:01', 'soureid': 26573761, 'up': 1208, 'down': 175, 'forward': 36, 'image': None, 'gif': 'http://wimg.spriteapp.cn/ugc/2017/10/12/59deef8637288.gif', 'thumbnail': 'http://wimg.spriteapp.cn/ugc/2017/10/12/59deef8637288_a_1.jpg', 'video': None}, {'type': 'video', 'text': '原来真有人盘在腰上...我想问 哪里有这种蚊子？', 'username': '步步高升l大哥 [认证]', 'uid': '9045414', 'header': 'http://wimg.spriteapp.cn/profile/large/2017/03/20/58ceaeb8b2d5c_mini.jpg', 'comment': 210, 'top_commentsVoiceuri': None, 'top_commentsContent': '曾经说把jj盘腰上的，就是你吧？', 'top_commentsHeader': 'http://qzapp.qlogo.cn/qzapp/100336987/D4ECFBD3A727441E5840AADD4B22D232/100', 'top_commentsName': '纸飞机XBG', 'passtime': '2017-12-28\xa017:45:01', 'soureid': 27055714, 'up': 1571, 'down': 65, 'forward': 446, 'image': None, 'gif': None, 'thumbnail': 'http://wimg.spriteapp.cn/picture/2017/1228/5a445382a190f__b_14.jpg', 'video': 'http://wvideo.spriteapp.cn/video/2017/1228/5a445382b8f8c_wpd.mp4'}, {'type': 'text', 'text': '正上班呢，被老妈打电话匆忙给叫回家，说家里出大事了！跟上司请假匆忙回家了。\n刚进家门被老妈一把摁住，给我换上连衣裙，梳个特淑女的发型～\n我就这么呆呆的任她摆布，直到老妈接个电话我才明白，这是让我去相亲，说实话真不爱去，奈何老妈有令，不得不去\n到了相亲地点我才发现，对方是我的上司，刚刚跟他请假说我肚子疼去医院……', 'username': '海娃的小老婆', 'uid': '21601008', 'header': 'http://wimg.spriteapp.cn/profile/large/2018/04/21/5adb494e3e18a_mini.jpg', 'comment': 55, 'top_commentsVoiceuri': None, 'top_commentsContent': '小姐姐，你这样就高攀了。', 'top_commentsHeader': 'http://wimg.spriteapp.cn/profile/large/2017/06/19/5946b333df21c_mini.jpg', 'top_commentsName': '一步一阶梯丶', 'passtime': '2018-05-09\xa011:50:02', 'soureid': 27867757, 'up': 1153, 'down': 43, 'forward': 1, 'image': None, 'gif': None, 'thumbnail': None, 'video': None}, {'type': 'video', 'text': '两百斤一箩筐 ，背到山顶才赚10元钱，如果你对生活充满抱怨，可能身上的压力还不够。', 'username': '小小白泥 [公众号]', 'uid': '16425220', 'header': 'http://wimg.spriteapp.cn/profile/large/2016/08/22/57ba3fd7160db_mini.jpg', 'comment': 389, 'top_commentsVoiceuri': None, 'top_commentsContent': '一天最少有五百块不然谁干', 'top_commentsHeader': 'http://wx.qlogo.cn/mmhead/YVYcYPr7PghOoH7tY0zickrflTet1sAZfNyOnXGdr2ag/0', 'top_commentsName': '田坎上的妹', 'passtime': '2018-06-09\xa011:55:01', 'soureid': 28086917, 'up': 1052, 'down': 54, 'forward': 35, 'image': None, 'gif': None, 'thumbnail': 'http://wimg.spriteapp.cn/picture/2018/0607/5b18ec2801e56_wpd.jpg', 'video': 'http://wvideo.spriteapp.cn/video/2018/0607/5b18ec2801e56_wpd.mp4'}, {'type': 'video', 'text': '当动物会说重庆话第六弹，哈哈哈～真是太搞笑了！', 'username': '瀚尧 [艾特子见]', 'uid': '15731740', 'header': 'http://wimg.spriteapp.cn/profile/large/2018/04/17/5ad580d81b321_mini.jpg', 'comment': 139, 'top_commentsVoiceuri': None, 'top_commentsContent': '给个机会上二级。嗷呜呜呜', 'top_commentsHeader': 'http://wimg.spriteapp.cn/profile', 'top_commentsName': '段-友你在哪', 'passtime': '2018-04-22\xa016:16:01', 'soureid': 27677047, 'up': 1522, 'down': 61, 'forward': 272, 'image': None, 'gif': None, 'thumbnail': 'http://wimg.spriteapp.cn/picture/2018/0421/211fedf8-4559-11e8-a662-1866daeb0df1_wpd.jpg', 'video': 'http://wvideo.spriteapp.cn/video/2018/0421/211fedf8-4559-11e8-a662-1866daeb0df1_wpd.mp4'}, {'type': 'video', 'text': '这个巴掌打的娇柔不做作！', 'username': '我是云飞扬 [百思葫芦娃]', 'uid': '17642987', 'header': 'http://wimg.spriteapp.cn/profile/large/2017/02/10/589dd39f8a9ee_mini.jpg', 'comment': 439, 'top_commentsVoiceuri': None, 'top_commentsContent': '满满的都是回忆', 'top_commentsHeader': 'http://wimg.spriteapp.cn/profile/large/2018/04/15/5ad2f3d56aea4_mini.jpg', 'top_commentsName': '会奔跑的段子', 'passtime': '2018-04-15\xa014:40:02', 'soureid': 27513865, 'up': 968, 'down': 38, 'forward': 82, 'image': None, 'gif': None, 'thumbnail': 'http://wimg.spriteapp.cn/picture/2018/0412/dfb715b8-3e1d-11e8-b880-1866daeb0df1_wpd.jpg', 'video': 'http://wvideo.spriteapp.cn/video/2018/0412/dfb715b8-3e1d-11e8-b880-1866daeb0df1_wpd.mp4'}, {'type': 'video', 'text': '新买的鞋子！大家看看是不是正品', 'username': '阿布路人甲', 'uid': '20398088', 'header': 'http://wimg.spriteapp.cn/profile/large/2018/03/08/5aa0ad7524e20_mini.jpg', 'comment': 131, 'top_commentsVoiceuri': None, 'top_commentsContent': '罗圈腿私人定制', 'top_commentsHeader': 'http://wimg.spriteapp.cn/profile/large/2016/04/07/57067c1f8d98a_mini.jpg', 'top_commentsName': 'uchcycycyviv', 'passtime': '2018-10-11\xa019:46:01', 'soureid': 28704785, 'up': 587, 'down': 52, 'forward': 55, 'image': None, 'gif': None, 'thumbnail': 'http://wimg.spriteapp.cn/picture/2018/1011/5bbec966e80b8__b.jpg', 'video': 'http://tvideo.spriteapp.cn/video/2018/1011/5bbec966f2b5a_wpd.mp4'}, {'type': 'gif', 'text': '假期结束后回程的路上，旁边坐着一位老大爷，从半路就开始打盹，现在车都快到站了，该怎么叫醒他才好呢？？', 'username': '搞笑小村 [笑了个爆]', 'uid': '16346788', 'header': 'http://wimg.spriteapp.cn/profile/large/2018/02/07/5a7a903fb7bcc_mini.jpg', 'comment': 211, 'top_commentsVoiceuri': None, 'top_commentsContent': '已鉴定，亲爸●✿∀✿●', 'top_commentsHeader': 'http://wimg.spriteapp.cn/profile/large/2017/11/30/5a202a9aa739f_mini.jpg', 'top_commentsName': '自我修养中的演员', 'passtime': '2017-10-09\xa007:36:01', 'soureid': 26535597, 'up': 1008, 'down': 111, 'forward': 5, 'image': None, 'gif': 'http://wimg.spriteapp.cn/ugc/2017/10/07/59d8f2a1555c4.gif', 'thumbnail': 'http://wimg.spriteapp.cn/ugc/2017/10/07/59d8f2a1555c4_a_1.jpg', 'video': None}, {'type': 'video', 'text': '哈哈哈，我有你女朋友的视频，不信你看！', 'username': '百思搞笑运动员 [百思俱乐部]', 'uid': '20701528', 'header': 'http://wx.qlogo.cn/mmopen/2EzJggZltBMKQovGd4IuGUTbUxCnE6yCanY15vtR21Cyjoy2mI5aRYicwic52mgwbibzBmQT9Sx8o2XlEeoDb6Go8swPabbictpo/0', 'comment': 303, 'top_commentsVoiceuri': None, 'top_commentsContent': '这穿内裤还有必要吗', 'top_commentsHeader': 'http://qzapp.qlogo.cn/qzapp/100336987/887456A6C140AC6CD5AD2DD1C50C354C/100', 'top_commentsName': '边7', 'passtime': '2017-12-24\xa022:31:02', 'soureid': 27038690, 'up': 2333, 'down': 136, 'forward': 825, 'image': None, 'gif': None, 'thumbnail': 'http://wimg.spriteapp.cn/picture/2017/1224/5a3f6a3639d4c__b.jpg', 'video': 'http://wvideo.spriteapp.cn/video/2017/1224/5a3f6a364f017_wpd.mp4'}, {'type': 'video', 'text': '土豪造海上别墅，第一层完全泡在海里，售价2100万！', 'username': '葫芦糊涂搞点事儿 [天天发新帖]', 'uid': '19160229', 'header': 'http://wimg.spriteapp.cn/profile/large/2018/01/11/5a5709ca83d49_mini.jpg', 'comment': 249, 'top_commentsVoiceuri': None, 'top_commentsContent': '真是膨胀了，别墅都敢点开看了', 'top_commentsHeader': 'http://wimg.spriteapp.cn/profile/large/2018/04/05/5ac4f78ab3571_mini.jpg', 'top_commentsName': '荷尔蒙液体', 'passtime': '2018-04-23\xa009:37:02', 'soureid': 27683103, 'up': 790, 'down': 34, 'forward': 90, 'image': None, 'gif': None, 'thumbnail': 'http://wimg.spriteapp.cn/picture/2018/0422/ae2f1d20-4592-11e8-a662-1866daeb0df1_wpd.jpg', 'video': 'http://wvideo.spriteapp.cn/video/2018/0422/ae2f1d20-4592-11e8-a662-1866daeb0df1_wpd.mp4'}, {'type': 'video', 'text': '一首世界名曲，送给青春，祭奠数以亿计的子子孙孙……', 'username': '承诺转身是谎言 [吉祥如意]', 'uid': '19832696', 'header': 'http://wimg.spriteapp.cn/profile/large/2017/09/23/59c61c44e5ae0_mini.jpg', 'comment': 269, 'top_commentsVoiceuri': None, 'top_commentsContent': '东京热给你多少。我们一本道给双倍', 'top_commentsHeader': 'http://wx.qlogo.cn/mmopen/vi_32/Q0j4TwGTfTLzt52HQpV46Exlxd8icJrXfEWJI478UIYZyLpa8Joibumkib3svibGhmzxndWiaVlka3PkRpOrGwX7GhA/0', 'top_commentsName': '凡羽xFo', 'passtime': '2017-11-15\xa017:44:01', 'soureid': 26818819, 'up': 1963, 'down': 63, 'forward': 488, 'image': None, 'gif': None, 'thumbnail': 'http://wimg.spriteapp.cn/picture/2017/1114/5a0a80b6c5576__b.jpg', 'video': 'http://wvideo.spriteapp.cn/video/2017/1114/5a0a80b6d667b_wpd.mp4'}, {'type': 'gif', 'text': '小伙子，你确定你不是对方派来的卧底吗？', 'username': '夏小檬 [大明湖畔]', 'uid': '19268252', 'header': 'http://wimg.spriteapp.cn/profile/large/2017/10/09/59db2392b3321_mini.jpg', 'comment': 116, 'top_commentsVoiceuri': None, 'top_commentsContent': '实不相瞒，我的注意力根本没在小伙子身上', 'top_commentsHeader': 'http://wimg.spriteapp.cn/profile/large/2018/04/14/5ad21289237c7_mini.jpg', 'top_commentsName': '只有靠偷维持生活这样子', 'passtime': '2018-04-28\xa021:22:02', 'soureid': 27757195, 'up': 411, 'down': 26, 'forward': 4, 'image': None, 'gif': 'http://wimg.spriteapp.cn/ugc/2018/04/27/5ae29c292aa18.gif', 'thumbnail': 'http://wimg.spriteapp.cn/ugc/2018/04/27/5ae29c292aa18_a_1.jpg', 'video': None}, {'type': 'video', 'text': '真正的国产良心之作！！ 剧情秒杀一切动漫！！！', 'username': '电影神探', 'uid': '22904219', 'header': 'http://wimg.spriteapp.cn/profile/20180809180841682644.jpg', 'comment': 132, 'top_commentsVoiceuri': None, 'top_commentsContent': '我与作者比命长系列', 'top_commentsHeader': 'http://qzapp.qlogo.cn/qzapp/100336987/3A11672131A4791D778F7C77B4A62A85/100', 'top_commentsName': '不得姐用户', 'passtime': '2018-09-30\xa021:41:02', 'soureid': 28664680, 'up': 940, 'down': 32, 'forward': 62, 'image': None, 'gif': None, 'thumbnail': 'http://wimg.spriteapp.cn/picture/2018/0930/57aa77cac47111e8bb2e842b2b4c75ab_wpd.jpg', 'video': 'http://tvideo.spriteapp.cn/video/2018/0930/57aa77cac47111e8bb2e842b2b4c75ab_wpd.mp4'}, {'type': 'gif', 'text': '娶个贤惠的媳妇有多重要，下班回来饭菜都准备好，碗筷都摆好了！', 'username': '幽默搞笑GIF图 [锤子家族]', 'uid': '15797873', 'header': 'http://wimg.spriteapp.cn/profile/large/2017/03/28/58d9cf7ba2de4_mini.jpg', 'comment': 450, 'top_commentsVoiceuri': None, 'top_commentsContent': 'rng输了，闷', 'top_commentsHeader': 'http://qzapp.qlogo.cn/qzapp/100336987/37398AA724782EE93D43BC80DDEB64C5/100', 'top_commentsName': '丶夜篱', 'passtime': '2017-10-28\xa020:30:02', 'soureid': 26681537, 'up': 1052, 'down': 114, 'forward': 25, 'image': None, 'gif': 'http://wimg.spriteapp.cn/ugc/2017/10/26/59f139de42477.gif', 'thumbnail': 'http://wimg.spriteapp.cn/ugc/2017/10/26/59f139de42477_a_1.jpg', 'video': None}, {'type': 'video', 'text': '妹子的舞姿碉堡了╭(╯ε╰)╮', 'username': 'Fir飘', 'uid': '21421421', 'header': 'http://wimg.spriteapp.cn/profile/large/2017/10/06/59d797b564604_mini.jpg', 'comment': 715, 'top_commentsVoiceuri': None, 'top_commentsContent': None, 'top_commentsHeader': None, 'top_commentsName': None, 'passtime': '2017-10-07\xa015:06:02', 'soureid': 26527331, 'up': 2454, 'down': 212, 'forward': 352, 'image': None, 'gif': None, 'thumbnail': 'http://wimg.spriteapp.cn/picture/2017/1006/59d79982d5c3f__b.jpg', 'video': 'http://wvideo.spriteapp.cn/video/2017/1006/59d799830efd8_wpd.mp4'}, {'type': 'video', 'text': '黄蜂女首次出手，居然还有翅膀，还有镭射枪？', 'username': '百汇电影', 'uid': '17994992', 'header': 'http://wimg.spriteapp.cn/profile/large/2018/09/23/5ba7b00c0fddc_mini.jpg', 'comment': 48, 'top_commentsVoiceuri': None, 'top_commentsContent': '哎，我越来越同情漫威的反派了', 'top_commentsHeader': 'http://wimg.spriteapp.cn/profile/large/2015/10/03/560fde783e327_mini.jpg', 'top_commentsName': '一念千年', 'passtime': '2018-10-03\xa009:19:02', 'soureid': 28671720, 'up': 368, 'down': 37, 'forward': 6, 'image': None, 'gif': None, 'thumbnail': 'http://wimg.spriteapp.cn/picture/2018/1002/5bb37880194f3cut_wpd.jpg', 'video': 'http://tvideo.spriteapp.cn/video/2018/1002/5bb37880194f3cut_wpd.mp4'}, {'type': 'video', 'text': '高手在民间啊，太漂亮了', 'username': '认真笑', 'uid': '21013681', 'header': 'http://wimg.spriteapp.cn/profile/large/2018/05/01/5ae744092fbf8_mini.jpg', 'comment': 175, 'top_commentsVoiceuri': None, 'top_commentsContent': '技术活当赏。', 'top_commentsHeader': 'http://wimg.spriteapp.cn/profile/large/2018/04/30/5ae6b780270bc_mini.jpg', 'top_commentsName': '青青青梅煮酒', 'passtime': '2018-05-06\xa018:21:02', 'soureid': 27845972, 'up': 748, 'down': 12, 'forward': 48, 'image': None, 'gif': None, 'thumbnail': 'http://wimg.spriteapp.cn/picture/2018/0506/5aee8baf46e08__b.jpg', 'video': 'http://wvideo.spriteapp.cn/video/2018/0506/5aee8baf7c7d1_wpd.mp4'}, {'type': 'video', 'text': '欢迎观看你看了你也吃不起系列', 'username': '大厨来了', 'uid': '22905126', 'header': 'http://wimg.spriteapp.cn/profile/20180810140726513883.jpg', 'comment': 372, 'top_commentsVoiceuri': None, 'top_commentsContent': '澳龙一斤200块钱，这只顶多3斤，谁想吃来找我 我请客', 'top_commentsHeader': 'http://wx.qlogo.cn/mmopen/2EzJggZltBO9m2ZboJfcZzGuf8p2icxhPpPw3MoGX4tvalN3lribT7M6GcvyDWZ44DHydUD2wNS7JxXf5BiaY1hq2KlHmBLww4z/0', 'top_commentsName': '银龙-小塞班', 'passtime': '2018-09-14\xa013:46:02', 'soureid': 28600981, 'up': 628, 'down': 75, 'forward': 41, 'image': None, 'gif': None, 'thumbnail': 'http://wimg.spriteapp.cn/picture/2018/0913/27e5fe52b74611e886b1842b2b4c75ab_wpd.jpg', 'video': 'http://tvideo.spriteapp.cn/video/2018/0913/27e5fe52b74611e886b1842b2b4c75ab_wpd.mp4'}, {'type': 'image', 'text': '重庆火锅你敢吃吗？', 'username': '臭宝蛋蛋 [Ms]', 'uid': '19531820', 'header': 'http://tva4.sinaimg.cn/crop.0.0.996.996.50/e7f9e94djw8f6ursgyso3j20ro0rp0wy.jpg', 'comment': 425, 'top_commentsVoiceuri': None, 'top_commentsContent': '山城啤酒，知心朋友！！！有没有人懂', 'top_commentsHeader': 'http://qzapp.qlogo.cn/qzapp/100336987/CB2D6200BFDC46831E5FAB96BCFE3075/100', 'top_commentsName': '人心那么凉', 'passtime': '2017-12-09\xa017:16:42', 'soureid': 26960615, 'up': 1022, 'down': 133, 'forward': 132, 'image': 'http://wimg.spriteapp.cn/ugc/2017/12/08/5a2a0634144c4_1.jpg', 'gif': None, 'thumbnail': 'http://wimg.spriteapp.cn/ugc/2017/12/08/5a2a0634144c4_1.jpg', 'video': None}, {'type': 'video', 'text': '无证未必无效！怼到专家哑口无言', 'username': '鱼丿忆', 'uid': '20730290', 'header': 'http://wimg.spriteapp.cn/profile/20170508160343.jpg', 'comment': 733, 'top_commentsVoiceuri': None, 'top_commentsContent': '给站起来怼的那位点赞', 'top_commentsHeader': 'http://wimg.spriteapp.cn/profile/large/2017/10/22/59ec3f2ccaf0b_mini.jpg', 'top_commentsName': '若尘ZXK', 'passtime': '2018-02-22\xa023:39:02', 'soureid': 27252419, 'up': 2371, 'down': 85, 'forward': 223, 'image': None, 'gif': None, 'thumbnail': 'http://wimg.spriteapp.cn/picture/2018/0221/27252419_338.jpg', 'video': 'http://wvideo.spriteapp.cn/video/2018/0221/c573fa6416d511e88ce9842b2b4c75ab_wpd.mp4'}]}


        </pre>
    </div>
    <!--css div popup end-->

    </td>
</tr>

<tr class='failClass'>
    <td>get_kuaidi_test.Kuaiditest</td>
    <td>4</td>
    <td>2</td>
    <td>2</td>
    <td>0</td>
    <td><a href="javascript:showClassDetail('c4',4)">Detail</a></td>
</tr>

<tr id='ft4.1' class='none'>
    <td class='failCase'><div class='testcase'>test_kuaidi_postid_error: 快递单号不存在</div></td>
    <td colspan='5' align='center'>

    <!--css div popup start-->
    <a class="popup_link" onfocus='this.blur();' href="javascript:showTestDetail('div_ft4.1')" >
        fail</a>

    <div id='div_ft4.1' class="popup_window">
        <div style='text-align: right; color:red;cursor:pointer'>
        <a onfocus='this.blur();' onclick="document.getElementById('div_ft4.1').style.display = 'none' " >
           [x]</a>
        </div>
        <pre>
        
ft4.1: {'message': 'ok', 'nu': '111000000000000000', 'ischeck': '0', 'condition': '00', 'com': 'yuantong', 'status': '200', 'state': '0', 'data': [{'time': '2019-06-17 13:49:42', 'ftime': '2019-06-17 13:49:42', 'context': '【长沙市】 快件离开 【长沙中转部】 已发往 【赣州中转部】', 'location': ''}, {'time': '2019-06-17 13:43:56', 'ftime': '2019-06-17 13:43:56', 'context': '【长沙市】 快件已经到达 【长沙中转部】', 'location': ''}]}
Traceback (most recent call last):
  File "C:\Users\JHMK-ZSS\PycharmProjects\pyrequests\interface\get_kuaidi_test.py", line 30, in test_kuaidi_postid_error
    self.assertEqual(self.result['data'][0]['context'],'查无结果')
AssertionError: '【长沙市】 快件离开 【长沙中转部】 已发往 【赣州中转部】' != '查无结果'
- 【长沙市】 快件离开 【长沙中转部】 已发往 【赣州中转部】
+ 查无结果



        </pre>
    </div>
    <!--css div popup end-->

    </td>
</tr>

<tr id='pt4.2' class='hiddenRow'>
    <td class='none'><div class='testcase'>test_kuaidi_postid_null: 快递单号为空</div></td>
    <td colspan='5' align='center'>

    <!--css div popup start-->
    <a class="popup_link" onfocus='this.blur();' href="javascript:showTestDetail('div_pt4.2')" >
        pass</a>

    <div id='div_pt4.2' class="popup_window">
        <div style='text-align: right; color:red;cursor:pointer'>
        <a onfocus='this.blur();' onclick="document.getElementById('div_pt4.2').style.display = 'none' " >
           [x]</a>
        </div>
        <pre>
        
pt4.2: {'message': '参数错误', 'nu': '', 'ischeck': '0', 'condition': '', 'com': '', 'status': '400', 'state': '0', 'data': []}


        </pre>
    </div>
    <!--css div popup end-->

    </td>
</tr>

<tr id='ft4.3' class='none'>
    <td class='failCase'><div class='testcase'>test_kuaidi_success: 查询成功</div></td>
    <td colspan='5' align='center'>

    <!--css div popup start-->
    <a class="popup_link" onfocus='this.blur();' href="javascript:showTestDetail('div_ft4.3')" >
        fail</a>

    <div id='div_ft4.3' class="popup_window">
        <div style='text-align: right; color:red;cursor:pointer'>
        <a onfocus='this.blur();' onclick="document.getElementById('div_ft4.3').style.display = 'none' " >
           [x]</a>
        </div>
        <pre>
        
ft4.3: {'message': '参数错误', 'nu': '', 'ischeck': '0', 'condition': '', 'com': '', 'status': '400', 'state': '0', 'data': []}
Traceback (most recent call last):
  File "C:\Users\JHMK-ZSS\PycharmProjects\pyrequests\interface\get_kuaidi_test.py", line 36, in test_kuaidi_success
    self.assertEqual(self.result['status'],'200')
AssertionError: '400' != '200'
- 400
? ^
+ 200
? ^



        </pre>
    </div>
    <!--css div popup end-->

    </td>
</tr>

<tr id='pt4.4' class='hiddenRow'>
    <td class='none'><div class='testcase'>test_kuaidi_type_null: 快递公司为空</div></td>
    <td colspan='5' align='center'>

    <!--css div popup start-->
    <a class="popup_link" onfocus='this.blur();' href="javascript:showTestDetail('div_pt4.4')" >
        pass</a>

    <div id='div_pt4.4' class="popup_window">
        <div style='text-align: right; color:red;cursor:pointer'>
        <a onfocus='this.blur();' onclick="document.getElementById('div_pt4.4').style.display = 'none' " >
           [x]</a>
        </div>
        <pre>
        
pt4.4: {'message': '参数错误', 'nu': '', 'ischeck': '0', 'condition': '', 'com': '', 'status': '400', 'state': '0', 'data': []}


        </pre>
    </div>
    <!--css div popup end-->

    </td>
</tr>

<tr class='passClass'>
    <td>get_place_api_test.Placeapi: 地点提示API</td>
    <td>3</td>
    <td>3</td>
    <td>0</td>
    <td>0</td>
    <td><a href="javascript:showClassDetail('c5',3)">Detail</a></td>
</tr>

<tr id='pt5.1' class='hiddenRow'>
    <td class='none'><div class='testcase'>test_place_api_ak_error: ak错误</div></td>
    <td colspan='5' align='center'>

    <!--css div popup start-->
    <a class="popup_link" onfocus='this.blur();' href="javascript:showTestDetail('div_pt5.1')" >
        pass</a>

    <div id='div_pt5.1' class="popup_window">
        <div style='text-align: right; color:red;cursor:pointer'>
        <a onfocus='this.blur();' onclick="document.getElementById('div_pt5.1').style.display = 'none' " >
           [x]</a>
        </div>
        <pre>
        
pt5.1: {'status': 200, 'message': 'APP不存在，AK有误请检查再重试'}


        </pre>
    </div>
    <!--css div popup end-->

    </td>
</tr>

<tr id='pt5.2' class='hiddenRow'>
    <td class='none'><div class='testcase'>test_place_api_ak_null: ak为空</div></td>
    <td colspan='5' align='center'>

    <!--css div popup start-->
    <a class="popup_link" onfocus='this.blur();' href="javascript:showTestDetail('div_pt5.2')" >
        pass</a>

    <div id='div_pt5.2' class="popup_window">
        <div style='text-align: right; color:red;cursor:pointer'>
        <a onfocus='this.blur();' onclick="document.getElementById('div_pt5.2').style.display = 'none' " >
           [x]</a>
        </div>
        <pre>
        
pt5.2: {'status': 101, 'message': 'AK参数不存在'}


        </pre>
    </div>
    <!--css div popup end-->

    </td>
</tr>

<tr id='pt5.3' class='hiddenRow'>
    <td class='none'><div class='testcase'>test_place_api_success: 查询成功</div></td>
    <td colspan='5' align='center'>

    <!--css div popup start-->
    <a class="popup_link" onfocus='this.blur();' href="javascript:showTestDetail('div_pt5.3')" >
        pass</a>

    <div id='div_pt5.3' class="popup_window">
        <div style='text-align: right; color:red;cursor:pointer'>
        <a onfocus='this.blur();' onclick="document.getElementById('div_pt5.3').style.display = 'none' " >
           [x]</a>
        </div>
        <pre>
        
pt5.3: {'status': 0, 'message': 'ok', 'result': [{'name': '天安门', 'location': {'lat': 39.915526, 'lng': 116.403847}, 'uid': '65e1ee886c885190f60e77ff', 'province': '北京市', 'city': '北京市', 'district': '东城区', 'business': '', 'cityid': '131'}, {'name': '天安门广场', 'location': {'lat': 39.909652, 'lng': 116.404177}, 'uid': 'c9b5fb91d49345bc5d0d0262', 'province': '北京市', 'city': '北京市', 'district': '东城区', 'business': '', 'cityid': '131'}, {'name': '天安门东-地铁站', 'location': {'lat': 39.91408, 'lng': 116.407851}, 'uid': '940aeb3c98d5a0218a2fb5de', 'province': '北京市', 'city': '北京市', 'district': '东城区', 'business': '', 'cityid': '131'}, {'name': '天安门广场-国旗', 'location': {'lat': 39.91328, 'lng': 116.403931}, 'uid': '4ae2adcf574bcd2b38221c66', 'province': '北京市', 'city': '北京市', 'district': '东城区', 'business': '', 'cityid': '131'}, {'name': '天安门西-地铁站', 'location': {'lat': 39.913776, 'lng': 116.39805}, 'uid': '002975204d3b1e9b9968b4de', 'province': '北京市', 'city': '北京市', 'district': '西城区', 'business': '', 'cityid': '131'}, {'name': '天安门东-公交车站', 'location': {'lat': 39.914089, 'lng': 116.40802}, 'uid': 'e1ee3a5e7be676c8213bf257', 'province': '北京市', 'city': '北京市', 'district': '东城区', 'business': '', 'cityid': '131'}, {'name': '天安门-华表', 'location': {'lat': 39.91433, 'lng': 116.404413}, 'uid': '3ff8be14bf465f3682288ac1', 'province': '北京市', 'city': '北京市', 'district': '东城区', 'business': '', 'cityid': '131'}, {'name': '天安门西-公交车站', 'location': {'lat': 39.913723, 'lng': 116.398056}, 'uid': 'a8e23c622c11486eae045714', 'province': '北京市', 'city': '北京市', 'district': '西城区', 'business': '', 'cityid': '131'}, {'name': '天安门-出口', 'location': {'lat': 39.91543, 'lng': 116.404241}, 'uid': 'e93b3a20e96f63d55cd4fe95', 'province': '北京市', 'city': '北京市', 'district': '东城区', 'business': '', 'cityid': '131'}, {'name': '保利国际影城(天安门店)', 'location': {'lat': 39.904638, 'lng': 116.403785}, 'uid': '9695ea62990089d42fb17e3a', 'province': '北京市', 'city': '北京市', 'district': '西城区', 'business': '', 'cityid': '131'}]}


        </pre>
    </div>
    <!--css div popup end-->

    </td>
</tr>

<tr id='total_row'>
    <td>Total</td>
    <td>26</td>
    <td>6</td>
    <td>2</td>
    <td>18</td>
    <td>&nbsp;</td>
</tr>
</table>

<div id='ending'>&nbsp;</div>

</body>
</html>
